Workbook
Name AvalDesemp: Cadastros!$R$6:$R$9
Name AvalPrazo: Cadastros!$S$6:$S$8
Name Beneficios: Cadastros!$I$6:$I$12
Name CategoriasImped: Cadastros!$Q$6:$Q$12
Name Complexidades: Cadastros!$G$6:$G$8
Name Departamentos: Cadastros!$C$6:$C$8
Name DeptosCSC: Cadastros!$L$6:$L$17
Name Empresas: Cadastros!$E$6:$E$12
Name EntBI: Cadastros!$AR$6:$AR$9
Name EntGov: Cadastros!$AO$6:$AO$11
Name EntMC: Cadastros!$AP$6:$AP$10
Name EntOper: Cadastros!$AT$6:$AT$12
Name EntPMO: Cadastros!$AS$6:$AS$9
Name EntTD: Cadastros!$AQ$6:$AQ$11
Name EquipePI: Cadastros!$N$6:$N$10
Name EtapasWorkflow: Cadastros!$U$6:$U$14
Name Impactos: Cadastros!$H$6:$H$8
Name Lista_Pilares_E2: Cadastros!$K$6:$K$11
Name MapaEnt: Cadastros!$Y$6:$Z$11
Name MapaPessoas: Cadastros!$AB$6:$AC$17
Name MapaTemas: Cadastros!$V$6:$W$14
Name MotivoStatus: Cadastros!$P$6:$P$15
Name NomeArquivo: 'Leia-me'!$C$90
Name Papeis: Cadastros!$M$6:$M$7
Name Pes01: Cadastros!$AV$6:$AV$16
Name Pes02: Cadastros!$AW$6:$AW$19
Name Pes03: Cadastros!$AX$6:$AX$12
Name Pes04: Cadastros!$AY$6:$AY$26
Name Pes05: Cadastros!$AZ$6:$AZ$10
Name Pes06: Cadastros!$BA$6:$BA$13
Name Pes07: Cadastros!$BB$6:$BB$19
Name Pes08: Cadastros!$BC$6:$BC$16
Name Pes09: Cadastros!$BD$6:$BD$17
Name Pes10: Cadastros!$BE$6:$BE$13
Name Pes11: Cadastros!$BF$6:$BF$9
Name Pes12: Cadastros!$BG$6:$BG$9
Name Pilares: Cadastros!$K$6:$K$11
Name Prefixo: 'Leia-me'!$C$86
Name Prioridades: Cadastros!$F$6:$F$8
Name Projetos: Cadastros!$B$6:$B$14
Name RadarCor: Cadastros!$T$6:$T$8
Name SimNao: Cadastros!$J$6:$J$7
Name StatusCriterio: Cadastros!$BJ$6:$BJ$10
Name StatusEtapa: Cadastros!$BI$6:$BI$13
Name StatusGeralProjeto: Cadastros!$BH$6:$BH$8
Name StatusList: Cadastros!$D$6:$D$11
Name StatusSemana: Cadastros!$O$6:$O$10
Name TemaActio: Cadastros!$AL$6:$AL$11
Name TemaIndMetas: Cadastros!$AM$6:$AM$11
Name TemaInvestidas: Cadastros!$AK$6:$AK$11
Name TemaLumen: Cadastros!$AE$6:$AE$19
Name TemaNewsletter: Cadastros!$AH$6:$AH$23
Name TemaRotinaFC: Cadastros!$AI$6:$AI$16
Name TemaRotinaFin: Cadastros!$AJ$6:$AJ$12
Name TemaSaneamento: Cadastros!$AG$6:$AG$9
Name TemaV360: Cadastros!$AF$6:$AF$8

Sheet Capa
B2: GESTÃO DE ATIVIDADES & WORKFLOW E1–E08
B3: Planilha do Analista — Viviane Lima (VL)
B4: Torre Financeira CSC · Departamento Processos Integrados · Supervisão: Juliana Batista
B7: SOBRE ESTE ARQUIVO
B8: Analista responsável: | C8: Viviane Lima
B9: Prefixo de ID (exclusivo): | C9: =Prefixo&" — Não alterar (garante ID único na consolidação)" -> VL — Não alterar (garante ID único na consolidação)
B10: Departamento: | C10: Processos Integrados
B11: Supervisora: | C11: Juliana Batista
B12: Estrutura: | C12: Torre Financeira — Centro de Serviços Compartilhados (CSC)
B13: Data de referência: | C13: =TODAY() -> 46233
B15: OBJETIVO
B16: Registrar, acompanhar e reportar todas as atividades e entregas do analista em um único controle: cada linha da aba Lançamentos é uma atividade,
B17: que percorre o fluxo de governança E1–E08 (49 critérios de aceite com evidência por etapa), mede ganho de produtividade (h/mês) e alimenta
B18: automaticamente o Acompanhamento Semanal, identificado por período de datas, e o Dashboard — painel executivo único da supervisão.
B20: FLUXO DE GOVERNANÇA — WORKFLOW E1–E08
B21: Etapa | C21: Tipo | D21: O que acontece
B22: E1 — Solicitação | C22: Registro · 8 critérios | D22: Necessidade descrita, origem, impacto e demanda registrada com recebimento confirmado.
B23: E2 — Triagem | C23: Classificação · 8 critérios | D23: Tipo, prioridade, complexidade, categoria, responsável e vínculo com projeto definidos.
B24: E3 — Levantamento | C24: ⚠ GATE · 5 critérios | D24: Requisitos, escopo, riscos e critérios de aceite validados — obrigatório para iniciar a E4.
B25: E4 — Execução | C25: Desenvolvimento · 7 critérios | D25: Execução planejada e realizada, progresso acompanhado e qualidade verificada.
B26: E5 — Validação | C26: ⚠ GATE · 5 critérios | D26: Validação do usuário e aprovação da gestão — homologação formalizada antes da E6.
B27: E6 — Ajustes | C27: Correção · 6 critérios | D27: Achados priorizados, ajustes executados e nova validação (quando aplicável).
B28: E7 — Entrega | C28: 🚀 Go-live · 4 critérios | D28: Solução disponibilizada, comunicada, encerrada no controle e evidências arquivadas.
B29: E08 — Estabilização | C29: Hypercare · 6 critérios | D29: Suporte assistido (padrão 7 dias): encerra estável ou abre nova demanda na E1.
B31: MAPA DE NAVEGAÇÃO — 16 ABAS DO ARQUIVO
B32: Aba | C32: Tipo | D32: Função
B33: Capa | C33: Consulta | D33: Apresentação do arquivo: objetivo, fluxo de governança e mapa das abas.
B34: Dashboard | C34: Automática | D34: Painel executivo único: cartões, velocímetros, funil E1–E8, gráficos e visões por projeto, pilar, departamento e Hypercare.
B35: Leia-me | C35: Consulta | D35: Instruções completas de uso e regras de ouro do preenchimento.
B36: Lançamentos | C36: Preencher | D36: Registro mestre: 1 linha = 1 atividade/entrega, com ID automático (JV-0001...).
B37: Workflow (Tracker) | C37: Automática | D37: Status derivado das etapas E1–E8, etapa atual, % do fluxo, gates e bloqueios — não digitar.
B38: E1 — Solicitação | C38: Preencher | D38: Critérios de aceite da solicitação (⏳/🔄/✔/⛔/N/A) + evidências.
B39: E2 — Triagem | C39: Preencher | D39: Critérios de classificação, prioridade e atribuição de responsável.
B40: E3 — Levantamento | C40: Preencher ⚠ | D40: Gate de escopo: requisitos e critérios de aceite validados.
B41: E4 — Execução | C41: Preencher | D41: Critérios de execução, progresso e preparação da entrega.
B42: E5 — Validação | C42: Preencher ⚠ | D42: Gate de homologação: validação do usuário e aprovação da gestão.
B43: E6 — Ajustes | C43: Preencher | D43: Tratamento dos achados da validação (quando aplicável).
... B48: PROMPT | C48: Referência | D48: Especificação técnica do sistema. Documento de apoio, não operacional.
B50: REGRAS DE OURO
B51: • Nunca digite valores fora das listas suspensas — isso quebra a consolidação automática.
...

Sheet Dashboard
B2: PROCESSOS INTEGRADOS | PORTFÓLIO EXECUTIVO | M2: =$T$44 -> Atualizado em 30/07/2026 | S2: Carteira total | T2: {=SUMPRODUCT(--(Lançamentos!$C$3:$C$1001<>""))} -> 0 | V2: {=IF($T$4=0,"",_xlfn.LET(_xlpm.m,(Lançamentos!$C$3:$C$1001<>"")*(Lançamentos!$AL$3:$AL$1001<>"Encerrado")*(Lançamentos!$AL$3:$AL$1001<>"Cancelado"),_xlpm.ids,_xlfn._xlws.FILTER(Lançamentos!$B$3:$B$1001,_xlpm.m),_xlpm.ativ,_xlfn._xlws.FILTER(Lançamentos!$J$3:$J$1001,_xlpm.m),_xlpm.proj,_xlfn._xlws.FILTER(Lançamentos!$F$3:$F$1001,_xlpm.m),_xlpm.stat,_xlfn._xlws.FILTER(Lançamentos!$AL$3:$AL$1001,_xlpm.m),_xlpm.ini,_xlfn._xlws.FILTER(Lançamentos!$C$3:$C$1001,_xlpm.m),_xlpm.ad,_xlfn._xlws.FILTER(Lançamentos!$AD$3:$AD$1001,_xlpm.m),_xlpm.ae,_xlfn._xlws.FILTER(Lançamentos!$AE$3:$AE$1001,_xlpm.m),_xlpm.af,_xlfn._xlws.FILTER(Lançamentos!$AF$3:$AF$1001,_xlpm.m),_xlpm.ai,_xlfn._xlws.FILTER(Lançamentos!$AI$3:$AI$1001,_xlpm.m),_xlpm.et,_xlfn.XLOOKUP(_xlpm.ids,'Workflow (Tracker)'!$B$26:$B$525,'Workflow (Tracker)'!$M$26:$M$525,""),_xlpm.fluxo,_xlfn.XLOOKUP(_xlpm.ids,'Workflow (Tracker)'!$B$26:$B$525,'Workflow (Tracker)'!$N$26:$N$525,""),_xlpm.bloq,--(_xlfn.XLOOKUP(_xlpm.ids,'Workflow (Tracker)'!$B$26:$B$525,MMULT(--('Workflow (Tracker)'!$E$26:$L$525="Bloqueado"),TRANSPOSE(COLUMN('Workflow (Tracker)'!$E$26:$L$26)^0)),0)>0),_xlpm.dias,TODAY()-_xlpm.ini,_xlpm.atras,--(ISNUMBER(_xlpm.ad)*(1-ISNUMBER(_xlpm.af))*ISNUMBER(_xlpm.ae)*(_xlpm.ae<TODAY())),_xlpm.inc,--ISNUMBER(SEARCH("Incidente Crítico",_xlpm.ai)),_xlpm.sit,IF(_xlpm.inc,"🔴 Incidente crítico",IF(_xlpm.bloq,"🔴 Bloqueada",IF(_xlpm.atras,"🔴 Hypercare atrasado",IF(_xlpm.dias>30,"🔴 Crítico",IF(_xlpm.dias>15,"🟠 Atenção","🟢 Normal"))))),_xlfn.SORTBY(_xlfn.HSTACK(_xlpm.ids,_xlpm.ativ,_xlpm.proj,_xlpm.stat,_xlpm.et,_xlpm.fluxo,_xlpm.dias,_xlpm.sit),_xlpm.ini,1)))} | AE2: {=IF($T$9=0,"",_xlfn.LET(_xlpm.g,Lançamentos!$W$3:$W$1001,_xlpm.m,(Lançamentos!$C$3:$C$1001<>"")*(Lançamentos!$O$3:$O$1001<>"Apoio")*ISNUMBER(_xlpm.g)*(_xlpm.g>0),_xlpm.id,_xlfn._xlws.FILTER(Lançamentos!$B$3:$B$1001,_xlpm.m),_xlpm.ativ,_xlfn._xlws.FILTER(Lançamentos!$J$3:$J$1001,_xlpm.m),_xlpm.proj,_xlfn._xlws.FILTER(Lançamentos!$F$3:$F$1001,_xlpm.m),_xlpm.ganho,_xlfn._xlws.FILTER(_xlpm.g,_xlpm.m),_xlpm.red,_xlfn._xlws.FILTER(Lançamentos!$X$3:$X$1001,_xlpm.m),_xlpm.ord,_xlfn.SORTBY(_xlfn.HSTACK(_xlpm.ativ,_xlpm.proj,_xlpm.ganho,_xlpm.red,_xlpm.id),_xlpm.ganho,-1),_xlpm.top,_xlfn.TAKE(_xlpm.ord,MIN(5,ROWS(_xlpm.ord))),_xlfn.HSTACK(_xlfn.SEQUENCE(ROWS(_xlpm.top)),_xlpm.top)))} | AL2: {=IF($T$2=0,"",_xlfn.LET(_xlpm.dim,CHOOSE(MATCH($E$52,{"Projeto","Pilar","Departamento CSC"},0),Lançamentos!$F$3:$F$1001,Lançamentos!$H$3:$H$1001,Lançamentos!$L$3:$L$1001),_xlpm.valid,Lançamentos!$C$3:$C$1001<>"",_xlpm.u,_xlfn.UNIQUE(_xlfn._xlws.FILTER(_xlpm.dim,_xlpm.valid*(_xlpm.dim<>""))),_xlpm.dem,_xlfn.MAP(_xlpm.u,_xlfn.LAMBDA(_xlpm.x,SUM(--_xlpm.valid*--(_xlpm.dim=_xlpm.x)))),_xlpm.conc,_xlfn.MAP(_xlpm.u,_xlfn.LAMBDA(_xlpm.x,SUM(--_xlpm.valid*--(_xlpm.dim=_xlpm.x)*--(Lançamentos!$AL$3:$AL$1001="Encerrado")))),_xlpm.horas,_xlfn.MAP(_xlpm.u,_xlfn.LAMBDA(_xlpm.x,SUMPRODUCT(--_xlpm.valid,--(_xlpm.dim=_xlpm.x),IFERROR(Lançamentos!$T$3:$T$1001,0)))),_xlpm.ganho,_xlfn.MAP(_xlpm.u,_xlfn.LAMBDA(_xlpm.x,SUMPRODUCT(--_xlpm.valid,--(_xlpm.dim=_xlpm.x),--(Lançamentos!$O$3:$O$1001<>"Apoio"),IFERROR(Lançamentos!$W$3:$W$1001,0)))),_xlpm.pct,IFERROR(_xlpm.ganho/$T$9,0),_xlfn.SORTBY(_xlfn.HSTACK(_xlpm.u,_xlpm.dem,_xlpm.conc,_xlpm.horas,_xlpm.ganho,_xlpm.pct),_xlpm.ganho,-1)))}
B3: Viviane Lima | S3: Concluídas | T3: =COUNTIFS(Lançamentos!$C$3:$C$1001,"<>",Lançamentos!$AL$3:$AL$1001,"Encerrado") -> 0
S4: Em aberto | T4: =COUNTIFS(Lançamentos!$C$3:$C$1001,"<>",Lançamentos!$AL$3:$AL$1001,"<>Encerrado",Lançamentos!$AL$3:$AL$1001,"<>Cancelado") -> 0
B5: BLOCO 1 — SINAL EXECUTIVO | S5: Demandas responsável | T5: {=SUMPRODUCT(--(Lançamentos!$C$3:$C$1001<>""),--(Lançamentos!$O$3:$O$1001<>"Apoio"))} -> 0
B6: ="STATUS DO DASHBOARD"&CHAR(10)&IF($T$34="CRÍTICO","🔴 CRÍTICO",IF($T$34="ACOMPANHAR","🟠 ACOMPANHAR","🟢 ESTÁVEL")) -> STATUS DO DASHBOARD 🟢 ESTÁVEL | G6: =$T$4&" demandas abertas | "&$T$14&" bloqueios | "&IF($T$17=0,"Hypercare no prazo",$T$17&" Hypercare atrasado(s)") -> 0 demandas abertas | 0 bloqueios | Hypercare no prazo | S6: Concluídas responsável | T6: =COUNTIFS(Lançamentos!$C$3:$C$1001,"<>",Lançamentos!$O$3:$O$1001,"<>Apoio",Lançamentos!$AL$3:$AL$1001,"Encerrado") -> 0
G7: ="Maior impacto: "&$T$39&" | "&$T$40&" | +"&TEXT($T$36,"0,0")&" h/mês" -> Maior impacto: | | +0,0 h/mês | S7: Taxa conclusão | T7: =IFERROR(T6/T5,"")
G8: ="Capacidade: "&TEXT($T$9,"#.##0,0")&" h/mês | "&TEXT($T$10,"#.##0,0")&" h/ano | Mais antiga: "&$T$38&" ("&$T$37&" dias) | Críticas: "&$T$33 -> Capacidade: 0,0 h/mês | 0,0 h/ano | Mais antiga: ( dias) | Críticas: 0 | S8: Horas investidas | T8: =SUMIFS(Lançamentos!$T$3:$T$1001,Lançamentos!$C$3:$C$1001,"<>") -> 0
S9: Ganho mensal | T9: =SUMIFS(Lançamentos!$W$3:$W$1001,Lançamentos!$C$3:$C$1001,"<>",Lançamentos!$O$3:$O$1001,"<>Apoio") -> 0
B10: =TEXT($T$7,"0,0%")&" da carteira como responsável está concluída. As 3 iniciativas de maior impacto representam "&TEXT($T$35,"0,0%")&" do ganho mensal. "&IF(AND($T$14=0,$T$17=0,$T$18=0),"Não existem bloqueios, atrasos de Hypercare ou incidentes críticos.","Existem condições críticas que exigem atuação.") -> da carteira como responsável está concluída. As 3 iniciativas de maior impacto representam do ganho mensal. Não existem bloqueios, atrasos de Hypercare ou incidentes críticos. | S10: Ganho anual | T10: =T9*12 -> 0
S11: Lead time médio | T11: =IFERROR(AVERAGEIFS(Lançamentos!$AK$3:$AK$1001,Lançamentos!$AL$3:$AL$1001,"Encerrado",Lançamentos!$AK$3:$AK$1001,">=0"),"")
B12: BLOCO 2 — RESULTADO DO PORTFÓLIO | S12: Eficiência transformação | T12: =IFERROR(T9/T8,"")
B13: CARTEIRA TOTAL | F13: CONCLUÍDAS | J13: EM ABERTO | N13: TAXA DE CONCLUSÃO | S13: Redução média | T13: =IFERROR(AVERAGEIFS(Lançamentos!$X$3:$X$1001,Lançamentos!$C$3:$C$1001,"<>",Lançamentos!$U$3:$U$1001,">0",Lançamentos!$V$3:$V$1001,">=0"),"")
B14: =$T$2 -> 0 | F14: =$T$3 -> 0 | J14: =$T$4 -> 0 | N14: =TEXT($T$7,"0,0%")&CHAR(10)&$T$6&"/"&$T$5&" como responsável" -> 0/0 como responsável | S14: Bloqueadas | T14: {=SUMPRODUCT(--('Workflow (Tracker)'!$B$26:$B$525<>""),--(MMULT(--('Workflow (Tracker)'!$E$26:$L$525="Bloqueado"),TRANSPOSE(COLUMN('Workflow (Tracker)'!$E$26:$L$26)^0))>0))} -> 0
S15: Gate E3 pendente | T15: {=SUMPRODUCT(--('Workflow (Tracker)'!$B$26:$B$525<>""),--('Workflow (Tracker)'!$G$26:$G$525<>"Concluído"),--(_xlfn.XLOOKUP('Workflow (Tracker)'!$B$26:$B$525,Lançamentos!$B$3:$B$1001,Lançamentos!$AL$3:$AL$1001,"")<>"Cancelado"))} -> 0
S16: Gate E5 pendente | T16: {=SUMPRODUCT(--('Workflow (Tracker)'!$B$26:$B$525<>""),--('Workflow (Tracker)'!$I$26:$I$525<>"Concluído"),--(_xlfn.XLOOKUP('Workflow (Tracker)'!$B$26:$B$525,Lançamentos!$B$3:$B$1001,Lançamentos!$AL$3:$AL$1001,"")<>"Cancelado"))} -> 0
B17: HORAS INVESTIDAS | F17: GANHO MENSAL | J17: GANHO ANUALIZADO | N17: LEAD TIME MÉDIO | S17: Hypercare atrasado | T17: =COUNTIFS(Lançamentos!$C$3:$C$1001,"<>",Lançamentos!$AD$3:$AD$1001,"<>",Lançamentos!$AF$3:$AF$1001,"",Lançamentos!$AE$3:$AE$1001,"<"&TODAY()) -> 0
B18: =TEXT($T$8,"#.##0,0")&" h" -> 0,0 h | F18: =TEXT($T$9,"#.##0,0")&" h/mês" -> 0,0 h/mês | J18: =TEXT($T$10,"#.##0,0")&" h/ano" -> 0,0 h/ano | N18: =TEXT($T$11,"0,0")&" dias" -> dias | S18: Incidentes críticos | T18: =COUNTIFS(Lançamentos!$C$3:$C$1001,"<>",Lançamentos!$AI$3:$AI$1001,"*Incidente Crítico*") -> 0
S19: Em estabilização efetiva | T19: {=SUMPRODUCT(--(Lançamentos!$C$3:$C$502<>""),--ISNUMBER(SEARCH("Em Estabilização",Lançamentos!$AI$3:$AI$502)),--((('Workflow (Tracker)'!$K$26:$K$525="Concluído")+ISNUMBER(SEARCH("E08",'Workflow (Tracker)'!$M$26:$M$525)))>0))} -> 0
S20: Encerrados estáveis | T20: =COUNTIFS(Lançamentos!$C$3:$C$1001,"<>",Lançamentos!$AI$3:$AI$1001,"*Estável*Demanda Encerrada*") -> 0
S21: Hypercare no prazo | T21: {=IFERROR(SUMPRODUCT(--(Lançamentos!$C$3:$C$1001<>""),--ISNUMBER(Lançamentos!$AF$3:$AF$1001),--ISNUMBER(Lançamentos!$AE$3:$AE$1001),--(Lançamentos!$AF$3:$AF$1001<=Lançamentos!$AE$3:$AE$1001))/SUMPRODUCT(--(Lançamentos!$C$3:$C$1001<>""),--ISNUMBER(Lançamentos!$AF$3:$AF$1001)),"")}
B22: BLOCO 3 — ATENÇÃO GERENCIAL | S22: Cobertura Hypercare | T22: {=IFERROR(SUMPRODUCT(--(Lançamentos!$C$3:$C$1001<>""),--ISNUMBER(Lançamentos!$AD$3:$AD$1001))/SUMPRODUCT(--(Lançamentos!$C$3:$C$1001<>""),--ISNUMBER(Lançamentos!$D$3:$D$1001)),"")}
B23: =$T$4&" abertas | "&$T$14&" bloqueadas | "&$T$43&" com gate pendente | "&$T$17&" atrasadas | "&$T$18&" incidentes" -> 0 abertas | 0 bloqueadas | 0 com gate pendente | 0 atrasadas | 0 incidentes | S23: Tempo médio Hypercare | T23: {=IFERROR(AVERAGE(_xlfn._xlws.FILTER(Lançamentos!$AG$3:$AG$1001,(Lançamentos!$C$3:$C$1001<>"")*ISNUMBER(Lançamentos!$AF$3:$AF$1001))),"")}
B24: ="Fluxo atual: "&IF($T$42="","sem demandas registradas",$T$42)&" | Gates: E3 "&$T$15&" pendente(s), E5 "&$T$16&" pendente(s) | Exibindo até 5 demandas abertas mais antigas" -> Fluxo atual: sem demandas registradas | Gates: E3 0 pendente(s), E5 0 pendente(s) | Exibindo até 5 demandas abertas mais antigas | S24: Novas demandas Hypercare | T24: {=SUMPRODUCT(--(Lançamentos!$C$3:$C$1001<>""),--(Lançamentos!$AJ$3:$AJ$1001<>""))} -> 0
S25: Horas informadas | T25: {=SUMPRODUCT(--(Lançamentos!$C$3:$C$1001<>""),--ISNUMBER(Lançamentos!$T$3:$T$1001))} -> 0
B26: ID | C26: ATIVIDADE | G26: PROJETO | I26: STATUS | K26: ETAPA ATUAL | M26: % FLUXO | N26: DIAS | O26: SITUAÇÃO | Q26: LINK | S26: Ganho mensurado | T26: {=SUMPRODUCT(--(Lançamentos!$C$3:$C$1001<>""),--ISNUMBER(Lançamentos!$U$3:$U$1001),--(Lançamentos!$U$3:$U$1001>0),--ISNUMBER(Lançamentos!$V$3:$V$1001))} -> 0
B27: =IFERROR(INDEX(_xlfn.ANCHORARRAY($V$2),1,1),"") | C27: =IFERROR(INDEX(_xlfn.ANCHORARRAY($V$2),1,2),"") | G27: =IFERROR(INDEX(_xlfn.ANCHORARRAY($V$2),1,3),"") | I27: =IFERROR(INDEX(_xlfn.ANCHORARRAY($V$2),1,4),"") | K27: =IFERROR(INDEX(_xlfn.ANCHORARRAY($V$2),1,5),"") | M27: =IFERROR(INDEX(_xlfn.ANCHORARRAY($V$2),1,6),"") | N27: =IFERROR(INDEX(_xlfn.ANCHORARRAY($V$2),1,7),"") | O27: =IFERROR(INDEX(_xlfn.ANCHORARRAY($V$2),1,8),"") | Q27: =IF($B27="","",HYPERLINK("#'Lançamentos'!B"&MATCH($B27,Lançamentos!$B:$B,0),"Abrir")) | S27: Projeto classificado | T27: {=SUMPRODUCT(--(Lançamentos!$C$3:$C$1001<>""),--(Lançamentos!$F$3:$F$1001<>""),--ISNUMBER(MATCH(Lançamentos!$F$3:$F$1001,Cadastros!$B$6:$B$48,0)))} -> 0
B28: =IFERROR(INDEX(_xlfn.ANCHORARRAY($V$2),2,1),"") | C28: =IFERROR(INDEX(_xlfn.ANCHORARRAY($V$2),2,2),"") | G28: =IFERROR(INDEX(_xlfn.ANCHORARRAY($V$2),2,3),"") | I28: =IFERROR(INDEX(_xlfn.ANCHORARRAY($V$2),2,4),"") | K28: =IFERROR(INDEX(_xlfn.ANCHORARRAY($V$2),2,5),"") | M28: =IFERROR(INDEX(_xlfn.ANCHORARRAY($V$2),2,6),"") | N28: =IFERROR(INDEX(_xlfn.ANCHORARRAY($V$2),2,7),"") | O28: =IFERROR(INDEX(_xlfn.ANCHORARRAY($V$2),2,8),"") | Q28: =IF($B28="","",HYPERLINK("#'Lançamentos'!B"&MATCH($B28,Lançamentos!$B:$B,0),"Abrir")) | S28: Pilar classificado | T28: {=SUMPRODUCT(--(Lançamentos!$C$3:$C$1001<>""),--(Lançamentos!$H$3:$H$1001<>""),--ISNUMBER(MATCH(Lançamentos!$H$3:$H$1001,Cadastros!$K$6:$K$48,0)))} -> 0
B29: =IFERROR(INDEX(_xlfn.ANCHORARRAY($V$2),3,1),"") | C29: =IFERROR(INDEX(_xlfn.ANCHORARRAY($V$2),3,2),"") | G29: =IFERROR(INDEX(_xlfn.ANCHORARRAY($V$2),3,3),"") | I29: =IFERROR(INDEX(_xlfn.ANCHORARRAY($V$2),3,4),"") | K29: =IFERROR(INDEX(_xlfn.ANCHORARRAY($V$2),3,5),"") | M29: =IFERROR(INDEX(_xlfn.ANCHORARRAY($V$2),3,6),"") | N29: =IFERROR(INDEX(_xlfn.ANCHORARRAY($V$2),3,7),"") | O29: =IFERROR(INDEX(_xlfn.ANCHORARRAY($V$2),3,8),"") | Q29: =IF($B29="","",HYPERLINK("#'Lançamentos'!B"&MATCH($B29,Lançamentos!$B:$B,0),"Abrir")) | S29: Departamento classificado | T29: {=SUMPRODUCT(--(Lançamentos!$C$3:$C$1001<>""),--(Lançamentos!$L$3:$L$1001<>""),--ISNUMBER(MATCH(Lançamentos!$L$3:$L$1001,Cadastros!$L$6:$L$48,0)))} -> 0
B30: =IFERROR(INDEX(_xlfn.ANCHORARRAY($V$2),4,1),"") | C30: =IFERROR(INDEX(_xlfn.ANCHORARRAY($V$2),4,2),"") | G30: =IFERROR(INDEX(_xlfn.ANCHORARRAY($V$2),4,3),"") | I30: =IFERROR(INDEX(_xlfn.ANCHORARRAY($V$2),4,4),"") | K30: =IFERROR(INDEX(_xlfn.ANCHORARRAY($V$2),4,5),"") | M30: =IFERROR(INDEX(_xlfn.ANCHORARRAY($V$2),4,6),"") | N30: =IFERROR(INDEX(_xlfn.ANCHORARRAY($V$2),4,7),"") | O30: =IFERROR(INDEX(_xlfn.ANCHORARRAY($V$2),4,8),"") | Q30: =IF($B30="","",HYPERLINK("#'Lançamentos'!B"&MATCH($B30,Lançamentos!$B:$B,0),"Abrir")) | S30: Inconsistências classificação | T30: {=SUMPRODUCT(--(Lançamentos!$C$3:$C$1001<>""),--(((Lançamentos!$F$3:$F$1001="")+ISNA(MATCH(Lançamentos!$F$3:$F$1001,Cadastros!$B$6:$B$48,0))+(Lançamentos!$H$3:$H$1001="")+ISNA(MATCH(Lançamentos!$H$3:$H$1001,Cadastros!$K$6:$K$48,0))+(Lançamentos!$L$3:$L$1001="")+ISNA(MATCH(Lançamentos!$L$3:$L$1001,Cadastros!$L$6:$L$48,0)))>0))} -> 0
B31: =IFERROR(INDEX(_xlfn.ANCHORARRAY($V$2),5,1),"") | C31: =IFERROR(INDEX(_xlfn.ANCHORARRAY($V$2),5,2),"") | G31: =IFERROR(INDEX(_xlfn.ANCHORARRAY($V$2),5,3),"") | I31: =IFERROR(INDEX(_xlfn.ANCHORARRAY($V$2),5,4),"") | K31: =IFERROR(INDEX(_xlfn.ANCHORARRAY($V$2),5,5),"") | M31: =IFERROR(INDEX(_xlfn.ANCHORARRAY($V$2),5,6),"") | N31: =IFERROR(INDEX(_xlfn.ANCHORARRAY($V$2),5,7),"") | O31: =IFERROR(INDEX(_xlfn.ANCHORARRAY($V$2),5,8),"") | Q31: =IF($B31="","",HYPERLINK("#'Lançamentos'!B"&MATCH($B31,Lançamentos!$B:$B,0),"Abrir")) | S31: IDs duplicados | T31: {=SUMPRODUCT(--(Lançamentos!$C$3:$C$1001<>""),--(COUNTIF(Lançamentos!$B$3:$B$1001,Lançamentos!$B$3:$B$1001)>1))} -> 0
B32: =IFERROR(INDEX(_xlfn.ANCHORARRAY($V$2),6,1),"") | C32: =IFERROR(INDEX(_xlfn.ANCHORARRAY($V$2),6,2),"") | G32: =IFERROR(INDEX(_xlfn.ANCHORARRAY($V$2),6,3),"") | I32: =IFERROR(INDEX(_xlfn.ANCHORARRAY($V$2),6,4),"") | K32: =IFERROR(INDEX(_xlfn.ANCHORARRAY($V$2),6,5),"") | M32: =IFERROR(INDEX(_xlfn.ANCHORARRAY($V$2),6,6),"") | N32: =IFERROR(INDEX(_xlfn.ANCHORARRAY($V$2),6,7),"") | O32: =IFERROR(INDEX(_xlfn.ANCHORARRAY($V$2),6,8),"") | Q32: =IF($B32="","",HYPERLINK("#'Lançamentos'!B"&MATCH($B32,Lançamentos!$B:$B,0),"Abrir")) | S32: Inconsistências Hypercare | T32: {=SUMPRODUCT(--(Lançamentos!$C$3:$C$502<>""),--ISNUMBER(SEARCH("Em Estabilização",Lançamentos!$AI$3:$AI$502)),--('Workflow (Tracker)'!$K$26:$K$525<>"Concluído"),--ISERROR(SEARCH("E08",'Workflow (Tracker)'!$M$26:$M$525)))} -> 0
B33: =IFERROR(INDEX(_xlfn.ANCHORARRAY($V$2),7,1),"") | C33: =IFERROR(INDEX(_xlfn.ANCHORARRAY($V$2),7,2),"") | G33: =IFERROR(INDEX(_xlfn.ANCHORARRAY($V$2),7,3),"") | I33: =IFERROR(INDEX(_xlfn.ANCHORARRAY($V$2),7,4),"") | K33: =IFERROR(INDEX(_xlfn.ANCHORARRAY($V$2),7,5),"") | M33: =IFERROR(INDEX(_xlfn.ANCHORARRAY($V$2),7,6),"") | N33: =IFERROR(INDEX(_xlfn.ANCHORARRAY($V$2),7,7),"") | O33: =IFERROR(INDEX(_xlfn.ANCHORARRAY($V$2),7,8),"") | Q33: =IF($B33="","",HYPERLINK("#'Lançamentos'!B"&MATCH($B33,Lançamentos!$B:$B,0),"Abrir")) | S33: Demandas críticas | T33: {=SUMPRODUCT(--(Lançamentos!$C$3:$C$502<>""),--(((MMULT(--('Workflow (Tracker)'!$E$26:$L$525="Bloqueado"),TRANSPOSE(COLUMN('Workflow (Tracker)'!$E$26:$L$26)^0))>0)+((Lançamentos!$AD$3:$AD$502<>"")*(Lançamentos!$AF$3:$AF$502="")*(Lançamentos!$AE$3:$AE$502<TODAY()))+ISNUMBER(SEARCH("Incidente Crítico",Lançamentos!$AI$3:$AI$502)))>0))} -> 0
B34: =IFERROR(INDEX(_xlfn.ANCHORARRAY($V$2),8,1),"") | C34: =IFERROR(INDEX(_xlfn.ANCHORARRAY($V$2),8,2),"") | G34: =IFERROR(INDEX(_xlfn.ANCHORARRAY($V$2),8,3),"") | I34: =IFERROR(INDEX(_xlfn.ANCHORARRAY($V$2),8,4),"") | K34: =IFERROR(INDEX(_xlfn.ANCHORARRAY($V$2),8,5),"") | M34: =IFERROR(INDEX(_xlfn.ANCHORARRAY($V$2),8,6),"") | N34: =IFERROR(INDEX(_xlfn.ANCHORARRAY($V$2),8,7),"") | O34: =IFERROR(INDEX(_xlfn.ANCHORARRAY($V$2),8,8),"") | Q34: =IF($B34="","",HYPERLINK("#'Lançamentos'!B"&MATCH($B34,Lançamentos!$B:$B,0),"Abrir")) | S34: Status executivo | T34: =IF(T33>0,"CRÍTICO",IF(T4>0,"ACOMPANHAR","ESTÁVEL")) -> ESTÁVEL
B35: =IFERROR(INDEX(_xlfn.ANCHORARRAY($V$2),9,1),"") | C35: =IFERROR(INDEX(_xlfn.ANCHORARRAY($V$2),9,2),"") | G35: =IFERROR(INDEX(_xlfn.ANCHORARRAY($V$2),9,3),"") | I35: =IFERROR(INDEX(_xlfn.ANCHORARRAY($V$2),9,4),"") | K35: =IFERROR(INDEX(_xlfn.ANCHORARRAY($V$2),9,5),"") | M35: =IFERROR(INDEX(_xlfn.ANCHORARRAY($V$2),9,6),"") | N35: =IFERROR(INDEX(_xlfn.ANCHORARRAY($V$2),9,7),"") | O35: =IFERROR(INDEX(_xlfn.ANCHORARRAY($V$2),9,8),"") | Q35: =IF($B35="","",HYPERLINK("#'Lançamentos'!B"&MATCH($B35,Lançamentos!$B:$B,0),"Abrir")) | S35: Concentração Top 3 | T35: {=_xlfn.LET(_xlpm.g,_xlfn._xlws.FILTER(Lançamentos!$W$3:$W$1001,(Lançamentos!$C$3:$C$1001<>"")*(Lançamentos!$O$3:$O$1001<>"Apoio")*(Lançamentos!$W$3:$W$1001>0)),_xlpm.n,MIN(3,ROWS(_xlpm.g)),IFERROR(SUM(LARGE(_xlpm.g,_xlfn.SEQUENCE(_xlpm.n)))/T9,""))}
B36: =IFERROR(INDEX(_xlfn.ANCHORARRAY($V$2),10,1),"") | C36: =IFERROR(INDEX(_xlfn.ANCHORARRAY($V$2),10,2),"") | G36: =IFERROR(INDEX(_xlfn.ANCHORARRAY($V$2),10,3),"") | I36: =IFERROR(INDEX(_xlfn.ANCHORARRAY($V$2),10,4),"") | K36: =IFERROR(INDEX(_xlfn.ANCHORARRAY($V$2),10,5),"") | M36: =IFERROR(INDEX(_xlfn.ANCHORARRAY($V$2),10,6),"") | N36: =IFERROR(INDEX(_xlfn.ANCHORARRAY($V$2),10,7),"") | O36: =IFERROR(INDEX(_xlfn.ANCHORARRAY($V$2),10,8),"") | Q36: =IF($B36="","",HYPERLINK("#'Lançamentos'!B"&MATCH($B36,Lançamentos!$B:$B,0),"Abrir")) | S36: Maior ganho | T36: =IFERROR(_xlfn.MAXIFS(Lançamentos!$W$3:$W$1001,Lançamentos!$C$3:$C$1001,"<>",Lançamentos!$O$3:$O$1001,"<>Apoio"),"") -> 0
S37: Dias demanda mais antiga | T37: {=_xlfn.LET(_xlpm.m,(Lançamentos!$C$3:$C$1001<>"")*(Lançamentos!$AL$3:$AL$1001<>"Encerrado")*(Lançamentos!$AL$3:$AL$1001<>"Cancelado"),_xlpm.d,_xlfn._xlws.FILTER(Lançamentos!$C$3:$C$1001,_xlpm.m),IFERROR(MAX(TODAY()-_xlpm.d),""))}
B38: BLOCO 4 — IMPACTO GERADO | S38: ID demanda mais antiga | T38: {=_xlfn.LET(_xlpm.m,(Lançamentos!$C$3:$C$1001<>"")*(Lançamentos!$AL$3:$AL$1001<>"Encerrado")*(Lançamentos!$AL$3:$AL$1001<>"Cancelado"),_xlpm.d,_xlfn._xlws.FILTER(Lançamentos!$C$3:$C$1001,_xlpm.m),_xlpm.ids,_xlfn._xlws.FILTER(Lançamentos!$B$3:$B$1001,_xlpm.m),IFERROR(_xlfn.XLOOKUP(MIN(_xlpm.d),_xlpm.d,_xlpm.ids),""))}
B39: ="CAPACIDADE MENSAL LIBERADA"&CHAR(10)&TEXT($T$9,"#.##0,0")&" h/mês" -> CAPACIDADE MENSAL LIBERADA 0,0 h/mês | H39: ="CAPACIDADE ANUALIZADA"&CHAR(10)&TEXT($T$10,"#.##0,0")&" h/ano" -> CAPACIDADE ANUALIZADA 0,0 h/ano | N39: ="CONCENTRAÇÃO TOP 3"&CHAR(10)&TEXT($T$35,"0,0%")&" do ganho total" -> CONCENTRAÇÃO TOP 3 do ganho total | S39: Atividade maior ganho | T39: =IF(T36="","",_xlfn.XLOOKUP(T36,Lançamentos!$W$3:$W$1001,Lançamentos!$J$3:$J$1001,""))
S40: Projeto maior ganho | T40: =IF(T36="","",_xlfn.XLOOKUP(T36,Lançamentos!$W$3:$W$1001,Lançamentos!$F$3:$F$1001,""))
S41: IDs inconsistência HC | T41: {=IFERROR(_xlfn.TEXTJOIN(", ",TRUE,_xlfn._xlws.FILTER(Lançamentos!$B$3:$B$502,(Lançamentos!$C$3:$C$502<>"")*ISNUMBER(SEARCH("Em Estabilização",Lançamentos!$AI$3:$AI$502))*('Workflow (Tracker)'!$K$26:$K$525<>"Concluído")*ISERROR(SEARCH("E08",'Workflow (Tracker)'!$M$26:$M$525)))),"")}
...

Sheet Leia-me
B2: LEIA-ME — MANUAL DE USO DA PLANILHA
B3: Gestão de Atividades & Workflow E1–E8 · Analista José Victor (JV)
B4: Torre Financeira CSC · Processos Integrados · Supervisão: Juliana Batista
B7: 1 · COMEÇANDO — O QUE FAZER NA PRIMEIRA VEZ
B8: ="1. Este arquivo é pessoal do analista "&$C$85&" (prefixo "&Prefixo&"), Departamento de Processos Integrados. Salve sempre como "&CHAR(34)&NomeArquivo&CHAR(34)&" e deposite na pasta compartilhada ao fim de cada semana para a consolidação da supervisão." -> 1. Este arquivo é pessoal do analista Viviane Lima (prefixo VL), Departamento de Processos Integrados. Salve sempre como "base-atividades-viviane_lima" e deposite na pasta compartilhada ao fim de cada semana para a consolidação da supervisão.
B9: ="2. Toda atividade nasce na aba Lançamentos: uma linha = uma atividade ou entrega. O ID Único ("&Prefixo&"-0001, "&Prefixo&"-0002…) é gerado automaticamente — nunca digite um ID à mão nem altere o prefixo "&Prefixo&". É ele que impede colisão de registros entre os analistas na consolidação." -> 2. Toda atividade nasce na aba Lançamentos: uma linha = uma atividade ou entrega. O ID Único (VL-0001, VL-0002…) é gerado automaticamente — nunca digite um ID à mão nem altere o prefixo VL. É ele que impede colisão de registros entre os analistas na consolidação.
B10: 3. Com a atividade lançada, percorra o fluxo E1 → E08 marcando os critérios de aceite nas oito abas de etapa. É nessas abas que a governança acontece: cada critério recebe um marcador de status e uma evidência.
B11: 4. Não existe status digitado à mão. As abas Workflow (Tracker), Dashboard e Dashboard derivam etapa atual, % do fluxo, gates, bloqueios e indicadores diretamente dos critérios e dos Lançamentos.
B12: 5. Antes da reunião com a gestora, abra a aba Acompanhamento Semanal e preencha apenas as seções marcadas com ✍️ (leva cerca de 5 minutos). As seções ⚙️ já chegam prontas.
B14: 2 · MAPA DAS ABAS — O QUE É CADA UMA
B15: Aba | C15: Tipo | D15: Função
B16: Capa | C16: Consulta | D16: Apresentação do arquivo: objetivo, fluxo de governança e mapa das abas.
B17: Leia-me | C17: Consulta | D17: Este manual: como preencher, legenda de status, regras de ouro e identificação.
B18: Dashboard | C18: Automática | D18: KPIs consolidados, funil E1–E8 e visões por projeto, pilar, status e Hypercare. | E18: Painel executivo único: cartões, velocímetros, funil E1–E8, gráficos e visões por projeto, pilar, departamento e Hypercare.
B19: Lançamentos | C19: Preencher | D19: Registro mestre: 1 linha = 1 atividade/entrega, 37 colunas, ID gerado automaticamente.
B20: Workflow (Tracker) | C20: Automática | D20: Status derivado das etapas, etapa atual, % do fluxo, gates e bloqueios. Não digite nada aqui.
B21: E1 — Solicitação | C21: Preencher | D21: 8 critérios: necessidade descrita, origem, impacto, evidências e recebimento confirmado.
B22: E2 — Triagem | C22: Preencher | D22: 8 critérios: tipo, área solicitante, prioridade, complexidade, categoria e responsável.
B23: E3 — Levantamento | C23: Preencher ⚠ | D23: 5 critérios: requisitos, escopo, riscos e critérios de aceite. GATE — trava o início da E4.
B24: E4 — Execução | C24: Preencher | D24: 7 critérios: execução planejada e realizada, progresso, qualidade e preparo da entrega.
B25: E5 — Validação | C25: Preencher ⚠ | D25: 5 critérios: validação do usuário e aprovação da gestão. GATE — trava o início da E6.
B26: E6 — Ajustes | C26: Preencher | D26: 6 critérios: achados priorizados, ajustes, pendências e nova validação. Etapa condicional.
B27: E7 — Entrega | C27: Preencher | D27: 4 critérios: solução disponibilizada, comunicada, encerrada no controle e evidências arquivadas.
B28: E08 — Estabilização Hypercare | C28: Preencher | D28: 6 critérios + controle de prazo do Hypercare (padrão 7 dias, ajustável).
B29: Acompanhamento Semanal | C29: Preencher | D29: Report da reunião semanal em 8 seções — 4 delas automáticas.
B30: Cadastros | C30: Consulta | D30: 14 listas mestras das validações (fonte única) — não alterar.
B31: PROMPT | C31: Referência | D31: Especificação técnica do sistema. Documento de apoio, não operacional.
B33: 3 · FLUXO DE GOVERNANÇA E1–E08 — 49 CRITÉRIOS DE ACEITE
B34: Etapa | C34: Critérios | D34: O que precisa estar concluído
B35: E1 — Solicitação | C35: 8 critérios | D35: Necessidade descrita, origem e identificação registradas, cenário e resultado esperado, impacto informado, evidências verificadas e recebimento confirmado.
B36: E2 — Triagem | C36: 8 critérios | D36: Tipo de demanda, área solicitante, prioridade, responsável, complexidade, categoria, vínculo com projeto e Tracker atualizado.
B37: E3 — Levantamento | C37: 5 · ⚠ GATE | D37: Requisitos levantados, escopo definido, riscos e dependências mapeados, critérios de aceite definidos e escopo validado. Sem os 5 concluídos, a E4 não pode iniciar.
B38: E4 — Execução | C38: 7 critérios | D38: Execução planejada e realizada, evolução registrada, progresso acompanhado, qualidade verificada, entrega preparada para validação e Tracker atualizado.
B39: E5 — Validação | C39: 5 · ⚠ GATE | D39: Entrega submetida, validação do usuário realizada, aprovação da gestão registrada, achados registrados e homologação formalizada. Sem os 5 concluídos, a E6 não pode iniciar.
B40: E6 — Ajustes | C40: 6 critérios | D40: Achados priorizados, ajustes executados, solução atualizada, pendências tratadas, nova validação e ajustes aprovados. Sem achados, marque Etapa 06 Aplicável? = Não.
B41: E7 — Entrega | C41: 4 · 🚀 Go-live | D41: Solução disponibilizada, entrega comunicada, projeto encerrado no controle e evidências arquivadas.
B42: E08 — Estabilização | C42: 6 critérios | D42: Suporte inicial prestado, solução monitorada, ocorrências registradas, correções emergenciais concluídas, estabilização confirmada e encerramento — ou novo ciclo na E1. Prazo padrão de 7 dias.
B44: 4 · LEGENDA DOS MARCADORES DE STATUS
B45: Marcador | C45: Usar quando | D45: Efeito no sistema
B46: ⏳ Pendente | C46: Ainda não iniciado | D46: A etapa permanece em aberto e a linha aparece em âmbar claro na aba da etapa.
...

Sheet Lançamentos
B2: ID Único | C2: Data Início | D2: Data Conclusão | E2: Departamento | F2: Projeto | G2: Tema | H2: Pilar Proc. Integrados | I2: Tipo de Demanda | J2: Atividade (título curto) | K2: Descrição | L2: Depto. Envolvido (CSC) | M2: Pessoa Envolvida | N2: Parceria? | O2: Papel na Atividade | P2: Parceiros (equipe PI) | Q2: ID Atividade Principal | R2: Empresa | S2: Status | T2: Horas Gastas | U2: Tempo Antes (h/mês) | V2: Tempo Depois (h/mês) | W2: Ganho (h/mês) | X2: % Redução | Y2: Resultado Alcançado | Z2: Pendência / Próximo Passo | AA2: Observação | AB2: Status E08 | AC2: % E08 | AD2: Início Hypercare | AE2: Encerramento Previsto | AF2: Encerramento Real | AG2: Dias Hypercare | AH2: Situação Prazo E08 | AI2: Resultado Hypercare | AJ2: ID Nova Demanda | AK2: Lead Time Total | AL2: Status Geral Definitivo
B3: =IF($C3="","",Prefixo&"-"&TEXT(ROW()-2,"0000")) | H3: =IF('E2 — Triagem'!D8="","",'E2 — Triagem'!D8) | W3: =IF(OR($U3="",$V3="",$U3<=0),"",$U3-$V3) | X3: =IF(OR($U3="",$V3="",$U3<=0),"",($U3-$V3)/$U3) | AB3: =IF($B3="","",'Workflow (Tracker)'!L26) | AC3: =IF($B3="","",'E08 — Estabilização Hypercare'!K8) | AD3: =IF($B3="","",'E08 — Estabilização Hypercare'!O8) | AE3: =IF($B3="","",'E08 — Estabilização Hypercare'!Q8) | AF3: =IF(OR($B3="",'E08 — Estabilização Hypercare'!R8=""),"",'E08 — Estabilização Hypercare'!R8) | AG3: =IF($B3="","",'E08 — Estabilização Hypercare'!S8) | AH3: =IF($B3="","",'E08 — Estabilização Hypercare'!T8) | AI3: =IF($B3="","",'E08 — Estabilização Hypercare'!N8) | AJ3: =IF(OR($B3="",'E08 — Estabilização Hypercare'!U8=""),"",'E08 — Estabilização Hypercare'!U8) | AK3: =IF(OR($B3="",$AF3="",$C3=""),"",$AF3-$C3) | AL3: =IF($B3="","",IF($AB3="Concluído","Encerrado",IF(AND($S3="Concluído",$AB3<>"Concluído"),"Em Hypercare",$S3)))
B4: =IF($C4="","",Prefixo&"-"&TEXT(ROW()-2,"0000")) | H4: =IF('E2 — Triagem'!D9="","",'E2 — Triagem'!D9) | W4: =IF(OR($U4="",$V4="",$U4<=0),"",$U4-$V4) | X4: =IF(OR($U4="",$V4="",$U4<=0),"",($U4-$V4)/$U4) | AB4: =IF($B4="","",'Workflow (Tracker)'!L27) | AC4: =IF($B4="","",'E08 — Estabilização Hypercare'!K9) | AD4: =IF($B4="","",'E08 — Estabilização Hypercare'!O9) | AE4: =IF($B4="","",'E08 — Estabilização Hypercare'!Q9) | AF4: =IF(OR($B4="",'E08 — Estabilização Hypercare'!R9=""),"",'E08 — Estabilização Hypercare'!R9) | AG4: =IF($B4="","",'E08 — Estabilização Hypercare'!S9) | AH4: =IF($B4="","",'E08 — Estabilização Hypercare'!T9) | AI4: =IF($B4="","",'E08 — Estabilização Hypercare'!N9) | AJ4: =IF(OR($B4="",'E08 — Estabilização Hypercare'!U9=""),"",'E08 — Estabilização Hypercare'!U9) | AK4: =IF(OR($B4="",$AF4="",$C4=""),"",$AF4-$C4) | AL4: =IF($B4="","",IF($AB4="Concluído","Encerrado",IF(AND($S4="Concluído",$AB4<>"Concluído"),"Em Hypercare",$S4)))
B5: =IF($C5="","",Prefixo&"-"&TEXT(ROW()-2,"0000")) | H5: =IF('E2 — Triagem'!D10="","",'E2 — Triagem'!D10) | W5: =IF(OR($U5="",$V5="",$U5<=0),"",$U5-$V5) | X5: =IF(OR($U5="",$V5="",$U5<=0),"",($U5-$V5)/$U5) | AB5: =IF($B5="","",'Workflow (Tracker)'!L28) | AC5: =IF($B5="","",'E08 — Estabilização Hypercare'!K10) | AD5: =IF($B5="","",'E08 — Estabilização Hypercare'!O10) | AE5: =IF($B5="","",'E08 — Estabilização Hypercare'!Q10) | AF5: =IF(OR($B5="",'E08 — Estabilização Hypercare'!R10=""),"",'E08 — Estabilização Hypercare'!R10) | AG5: =IF($B5="","",'E08 — Estabilização Hypercare'!S10) | AH5: =IF($B5="","",'E08 — Estabilização Hypercare'!T10) | AI5: =IF($B5="","",'E08 — Estabilização Hypercare'!N10) | AJ5: =IF(OR($B5="",'E08 — Estabilização Hypercare'!U10=""),"",'E08 — Estabilização Hypercare'!U10) | AK5: =IF(OR($B5="",$AF5="",$C5=""),"",$AF5-$C5) | AL5: =IF($B5="","",IF($AB5="Concluído","Encerrado",IF(AND($S5="Concluído",$AB5<>"Concluído"),"Em Hypercare",$S5)))
B6: =IF($C6="","",Prefixo&"-"&TEXT(ROW()-2,"0000")) | H6: =IF('E2 — Triagem'!D11="","",'E2 — Triagem'!D11) | W6: =IF(OR($U6="",$V6="",$U6<=0),"",$U6-$V6) | X6: =IF(OR($U6="",$V6="",$U6<=0),"",($U6-$V6)/$U6) | AB6: =IF($B6="","",'Workflow (Tracker)'!L29) | AC6: =IF($B6="","",'E08 — Estabilização Hypercare'!K11) | AD6: =IF($B6="","",'E08 — Estabilização Hypercare'!O11) | AE6: =IF($B6="","",'E08 — Estabilização Hypercare'!Q11) | AF6: =IF(OR($B6="",'E08 — Estabilização Hypercare'!R11=""),"",'E08 — Estabilização Hypercare'!R11) | AG6: =IF($B6="","",'E08 — Estabilização Hypercare'!S11) | AH6: =IF($B6="","",'E08 — Estabilização Hypercare'!T11) | AI6: =IF($B6="","",'E08 — Estabilização Hypercare'!N11) | AJ6: =IF(OR($B6="",'E08 — Estabilização Hypercare'!U11=""),"",'E08 — Estabilização Hypercare'!U11) | AK6: =IF(OR($B6="",$AF6="",$C6=""),"",$AF6-$C6) | AL6: =IF($B6="","",IF($AB6="Concluído","Encerrado",IF(AND($S6="Concluído",$AB6<>"Concluído"),"Em Hypercare",$S6)))
B7: =IF($C7="","",Prefixo&"-"&TEXT(ROW()-2,"0000")) | H7: =IF('E2 — Triagem'!D12="","",'E2 — Triagem'!D12) | W7: =IF(OR($U7="",$V7="",$U7<=0),"",$U7-$V7) | X7: =IF(OR($U7="",$V7="",$U7<=0),"",($U7-$V7)/$U7) | AB7: =IF($B7="","",'Workflow (Tracker)'!L30) | AC7: =IF($B7="","",'E08 — Estabilização Hypercare'!K12) | AD7: =IF($B7="","",'E08 — Estabilização Hypercare'!O12) | AE7: =IF($B7="","",'E08 — Estabilização Hypercare'!Q12) | AF7: =IF(OR($B7="",'E08 — Estabilização Hypercare'!R12=""),"",'E08 — Estabilização Hypercare'!R12) | AG7: =IF($B7="","",'E08 — Estabilização Hypercare'!S12) | AH7: =IF($B7="","",'E08 — Estabilização Hypercare'!T12) | AI7: =IF($B7="","",'E08 — Estabilização Hypercare'!N12) | AJ7: =IF(OR($B7="",'E08 — Estabilização Hypercare'!U12=""),"",'E08 — Estabilização Hypercare'!U12) | AK7: =IF(OR($B7="",$AF7="",$C7=""),"",$AF7-$C7) | AL7: =IF($B7="","",IF($AB7="Concluído","Encerrado",IF(AND($S7="Concluído",$AB7<>"Concluído"),"Em Hypercare",$S7)))
B8: =IF($C8="","",Prefixo&"-"&TEXT(ROW()-2,"0000")) | H8: =IF('E2 — Triagem'!D13="","",'E2 — Triagem'!D13) | W8: =IF(OR($U8="",$V8="",$U8<=0),"",$U8-$V8) | X8: =IF(OR($U8="",$V8="",$U8<=0),"",($U8-$V8)/$U8) | AB8: =IF($B8="","",'Workflow (Tracker)'!L31) | AC8: =IF($B8="","",'E08 — Estabilização Hypercare'!K13) | AD8: =IF($B8="","",'E08 — Estabilização Hypercare'!O13) | AE8: =IF($B8="","",'E08 — Estabilização Hypercare'!Q13) | AF8: =IF(OR($B8="",'E08 — Estabilização Hypercare'!R13=""),"",'E08 — Estabilização Hypercare'!R13) | AG8: =IF($B8="","",'E08 — Estabilização Hypercare'!S13) | AH8: =IF($B8="","",'E08 — Estabilização Hypercare'!T13) | AI8: =IF($B8="","",'E08 — Estabilização Hypercare'!N13) | AJ8: =IF(OR($B8="",'E08 — Estabilização Hypercare'!U13=""),"",'E08 — Estabilização Hypercare'!U13) | AK8: =IF(OR($B8="",$AF8="",$C8=""),"",$AF8-$C8) | AL8: =IF($B8="","",IF($AB8="Concluído","Encerrado",IF(AND($S8="Concluído",$AB8<>"Concluído"),"Em Hypercare",$S8)))
B9: =IF($C9="","",Prefixo&"-"&TEXT(ROW()-2,"0000")) | H9: =IF('E2 — Triagem'!D14="","",'E2 — Triagem'!D14) | W9: =IF(OR($U9="",$V9="",$U9<=0),"",$U9-$V9) | X9: =IF(OR($U9="",$V9="",$U9<=0),"",($U9-$V9)/$U9) | AB9: =IF($B9="","",'Workflow (Tracker)'!L32) | AC9: =IF($B9="","",'E08 — Estabilização Hypercare'!K14) | AD9: =IF($B9="","",'E08 — Estabilização Hypercare'!O14) | AE9: =IF($B9="","",'E08 — Estabilização Hypercare'!Q14) | AF9: =IF(OR($B9="",'E08 — Estabilização Hypercare'!R14=""),"",'E08 — Estabilização Hypercare'!R14) | AG9: =IF($B9="","",'E08 — Estabilização Hypercare'!S14) | AH9: =IF($B9="","",'E08 — Estabilização Hypercare'!T14) | AI9: =IF($B9="","",'E08 — Estabilização Hypercare'!N14) | AJ9: =IF(OR($B9="",'E08 — Estabilização Hypercare'!U14=""),"",'E08 — Estabilização Hypercare'!U14) | AK9: =IF(OR($B9="",$AF9="",$C9=""),"",$AF9-$C9) | AL9: =IF($B9="","",IF($AB9="Concluído","Encerrado",IF(AND($S9="Concluído",$AB9<>"Concluído"),"Em Hypercare",$S9)))
B10: =IF($C10="","",Prefixo&"-"&TEXT(ROW()-2,"0000")) | H10: =IF('E2 — Triagem'!D15="","",'E2 — Triagem'!D15) | W10: =IF(OR($U10="",$V10="",$U10<=0),"",$U10-$V10) | X10: =IF(OR($U10="",$V10="",$U10<=0),"",($U10-$V10)/$U10) | AB10: =IF($B10="","",'Workflow (Tracker)'!L33) | AC10: =IF($B10="","",'E08 — Estabilização Hypercare'!K15) | AD10: =IF($B10="","",'E08 — Estabilização Hypercare'!O15) | AE10: =IF($B10="","",'E08 — Estabilização Hypercare'!Q15) | AF10: =IF(OR($B10="",'E08 — Estabilização Hypercare'!R15=""),"",'E08 — Estabilização Hypercare'!R15) | AG10: =IF($B10="","",'E08 — Estabilização Hypercare'!S15) | AH10: =IF($B10="","",'E08 — Estabilização Hypercare'!T15) | AI10: =IF($B10="","",'E08 — Estabilização Hypercare'!N15) | AJ10: =IF(OR($B10="",'E08 — Estabilização Hypercare'!U15=""),"",'E08 — Estabilização Hypercare'!U15) | AK10: =IF(OR($B10="",$AF10="",$C10=""),"",$AF10-$C10) | AL10: =IF($B10="","",IF($AB10="Concluído","Encerrado",IF(AND($S10="Concluído",$AB10<>"Concluído"),"Em Hypercare",$S10)))
B11: =IF($C11="","",Prefixo&"-"&TEXT(ROW()-2,"0000")) | H11: =IF('E2 — Triagem'!D16="","",'E2 — Triagem'!D16) | W11: =IF(OR($U11="",$V11="",$U11<=0),"",$U11-$V11) | X11: =IF(OR($U11="",$V11="",$U11<=0),"",($U11-$V11)/$U11) | AB11: =IF($B11="","",'Workflow (Tracker)'!L34) | AC11: =IF($B11="","",'E08 — Estabilização Hypercare'!K16) | AD11: =IF($B11="","",'E08 — Estabilização Hypercare'!O16) | AE11: =IF($B11="","",'E08 — Estabilização Hypercare'!Q16) | AF11: =IF(OR($B11="",'E08 — Estabilização Hypercare'!R16=""),"",'E08 — Estabilização Hypercare'!R16) | AG11: =IF($B11="","",'E08 — Estabilização Hypercare'!S16) | AH11: =IF($B11="","",'E08 — Estabilização Hypercare'!T16) | AI11: =IF($B11="","",'E08 — Estabilização Hypercare'!N16) | AJ11: =IF(OR($B11="",'E08 — Estabilização Hypercare'!U16=""),"",'E08 — Estabilização Hypercare'!U16) | AK11: =IF(OR($B11="",$AF11="",$C11=""),"",$AF11-$C11) | AL11: =IF($B11="","",IF($AB11="Concluído","Encerrado",IF(AND($S11="Concluído",$AB11<>"Concluído"),"Em Hypercare",$S11)))
B12: =IF($C12="","",Prefixo&"-"&TEXT(ROW()-2,"0000")) | H12: =IF('E2 — Triagem'!D17="","",'E2 — Triagem'!D17) | W12: =IF(OR($U12="",$V12="",$U12<=0),"",$U12-$V12) | X12: =IF(OR($U12="",$V12="",$U12<=0),"",($U12-$V12)/$U12) | AB12: =IF($B12="","",'Workflow (Tracker)'!L35) | AC12: =IF($B12="","",'E08 — Estabilização Hypercare'!K17) | AD12: =IF($B12="","",'E08 — Estabilização Hypercare'!O17) | AE12: =IF($B12="","",'E08 — Estabilização Hypercare'!Q17) | AF12: =IF(OR($B12="",'E08 — Estabilização Hypercare'!R17=""),"",'E08 — Estabilização Hypercare'!R17) | AG12: =IF($B12="","",'E08 — Estabilização Hypercare'!S17) | AH12: =IF($B12="","",'E08 — Estabilização Hypercare'!T17) | AI12: =IF($B12="","",'E08 — Estabilização Hypercare'!N17) | AJ12: =IF(OR($B12="",'E08 — Estabilização Hypercare'!U17=""),"",'E08 — Estabilização Hypercare'!U17) | AK12: =IF(OR($B12="",$AF12="",$C12=""),"",$AF12-$C12) | AL12: =IF($B12="","",IF($AB12="Concluído","Encerrado",IF(AND($S12="Concluído",$AB12<>"Concluído"),"Em Hypercare",$S12)))
B13: =IF($C13="","",Prefixo&"-"&TEXT(ROW()-2,"0000")) | H13: =IF('E2 — Triagem'!D18="","",'E2 — Triagem'!D18) | W13: =IF(OR($U13="",$V13="",$U13<=0),"",$U13-$V13) | X13: =IF(OR($U13="",$V13="",$U13<=0),"",($U13-$V13)/$U13) | AB13: =IF($B13="","",'Workflow (Tracker)'!L36) | AC13: =IF($B13="","",'E08 — Estabilização Hypercare'!K18) | AD13: =IF($B13="","",'E08 — Estabilização Hypercare'!O18) | AE13: =IF($B13="","",'E08 — Estabilização Hypercare'!Q18) | AF13: =IF(OR($B13="",'E08 — Estabilização Hypercare'!R18=""),"",'E08 — Estabilização Hypercare'!R18) | AG13: =IF($B13="","",'E08 — Estabilização Hypercare'!S18) | AH13: =IF($B13="","",'E08 — Estabilização Hypercare'!T18) | AI13: =IF($B13="","",'E08 — Estabilização Hypercare'!N18) | AJ13: =IF(OR($B13="",'E08 — Estabilização Hypercare'!U18=""),"",'E08 — Estabilização Hypercare'!U18) | AK13: =IF(OR($B13="",$AF13="",$C13=""),"",$AF13-$C13) | AL13: =IF($B13="","",IF($AB13="Concluído","Encerrado",IF(AND($S13="Concluído",$AB13<>"Concluído"),"Em Hypercare",$S13)))
B14: =IF($C14="","",Prefixo&"-"&TEXT(ROW()-2,"0000")) | H14: =IF('E2 — Triagem'!D19="","",'E2 — Triagem'!D19) | W14: =IF(OR($U14="",$V14="",$U14<=0),"",$U14-$V14) | X14: =IF(OR($U14="",$V14="",$U14<=0),"",($U14-$V14)/$U14) | AB14: =IF($B14="","",'Workflow (Tracker)'!L37) | AC14: =IF($B14="","",'E08 — Estabilização Hypercare'!K19) | AD14: =IF($B14="","",'E08 — Estabilização Hypercare'!O19) | AE14: =IF($B14="","",'E08 — Estabilização Hypercare'!Q19) | AF14: =IF(OR($B14="",'E08 — Estabilização Hypercare'!R19=""),"",'E08 — Estabilização Hypercare'!R19) | AG14: =IF($B14="","",'E08 — Estabilização Hypercare'!S19) | AH14: =IF($B14="","",'E08 — Estabilização Hypercare'!T19) | AI14: =IF($B14="","",'E08 — Estabilização Hypercare'!N19) | AJ14: =IF(OR($B14="",'E08 — Estabilização Hypercare'!U19=""),"",'E08 — Estabilização Hypercare'!U19) | AK14: =IF(OR($B14="",$AF14="",$C14=""),"",$AF14-$C14) | AL14: =IF($B14="","",IF($AB14="Concluído","Encerrado",IF(AND($S14="Concluído",$AB14<>"Concluído"),"Em Hypercare",$S14)))
... B502: =IF($C502="","",Prefixo&"-"&TEXT(ROW()-2,"0000")) | H502: =IF('E2 — Triagem'!D507="","",'E2 — Triagem'!D507) | W502: =IF(OR($U502="",$V502="",$U502<=0),"",$U502-$V502) | X502: =IF(OR($U502="",$V502="",$U502<=0),"",($U502-$V502)/$U502) | AB502: =IF($B502="","",'Workflow (Tracker)'!L525) | AC502: =IF($B502="","",'E08 — Estabilização Hypercare'!K507) | AD502: =IF($B502="","",'E08 — Estabilização Hypercare'!O507) | AE502: =IF($B502="","",'E08 — Estabilização Hypercare'!Q507) | AF502: =IF(OR($B502="",'E08 — Estabilização Hypercare'!R507=""),"",'E08 — Estabilização Hypercare'!R507) | AG502: =IF($B502="","",'E08 — Estabilização Hypercare'!S507) | AH502: =IF($B502="","",'E08 — Estabilização Hypercare'!T507) | AI502: =IF($B502="","",'E08 — Estabilização Hypercare'!N507) | AJ502: =IF(OR($B502="",'E08 — Estabilização Hypercare'!U507=""),"",'E08 — Estabilização Hypercare'!U507) | AK502: =IF(OR($B502="",$AF502="",$C502=""),"",$AF502-$C502) | AL502: =IF($B502="","",IF($AB502="Concluído","Encerrado",IF(AND($S502="Concluído",$AB502<>"Concluído"),"Em Hypercare",$S502)))
B503: =IF($C503="","",Prefixo&"-"&TEXT(ROW()-2,"0000")) | W503: =IF(OR($U503="",$V503="",$U503<=0),"",$U503-$V503) | X503: =IF(OR($U503="",$V503="",$U503<=0),"",($U503-$V503)/$U503)
B504: =IF($C504="","",Prefixo&"-"&TEXT(ROW()-2,"0000")) | W504: =IF(OR($U504="",$V504="",$U504<=0),"",$U504-$V504) | X504: =IF(OR($U504="",$V504="",$U504<=0),"",($U504-$V504)/$U504)
B505: =IF($C505="","",Prefixo&"-"&TEXT(ROW()-2,"0000")) | W505: =IF(OR($U505="",$V505="",$U505<=0),"",$U505-$V505) | X505: =IF(OR($U505="",$V505="",$U505<=0),"",($U505-$V505)/$U505)
B506: =IF($C506="","",Prefixo&"-"&TEXT(ROW()-2,"0000")) | W506: =IF(OR($U506="",$V506="",$U506<=0),"",$U506-$V506) | X506: =IF(OR($U506="",$V506="",$U506<=0),"",($U506-$V506)/$U506)
B507: =IF($C507="","",Prefixo&"-"&TEXT(ROW()-2,"0000")) | W507: =IF(OR($U507="",$V507="",$U507<=0),"",$U507-$V507) | X507: =IF(OR($U507="",$V507="",$U507<=0),"",($U507-$V507)/$U507)
B508: =IF($C508="","",Prefixo&"-"&TEXT(ROW()-2,"0000")) | W508: =IF(OR($U508="",$V508="",$U508<=0),"",$U508-$V508) | X508: =IF(OR($U508="",$V508="",$U508<=0),"",($U508-$V508)/$U508)
B509: =IF($C509="","",Prefixo&"-"&TEXT(ROW()-2,"0000")) | W509: =IF(OR($U509="",$V509="",$U509<=0),"",$U509-$V509) | X509: =IF(OR($U509="",$V509="",$U509<=0),"",($U509-$V509)/$U509)
B510: =IF($C510="","",Prefixo&"-"&TEXT(ROW()-2,"0000")) | W510: =IF(OR($U510="",$V510="",$U510<=0),"",$U510-$V510) | X510: =IF(OR($U510="",$V510="",$U510<=0),"",($U510-$V510)/$U510)
B511: =IF($C511="","",Prefixo&"-"&TEXT(ROW()-2,"0000")) | W511: =IF(OR($U511="",$V511="",$U511<=0),"",$U511-$V511) | X511: =IF(OR($U511="",$V511="",$U511<=0),"",($U511-$V511)/$U511)
B512: =IF($C512="","",Prefixo&"-"&TEXT(ROW()-2,"0000")) | W512: =IF(OR($U512="",$V512="",$U512<=0),"",$U512-$V512) | X512: =IF(OR($U512="",$V512="",$U512<=0),"",($U512-$V512)/$U512)
B513: =IF($C513="","",Prefixo&"-"&TEXT(ROW()-2,"0000")) | W513: =IF(OR($U513="",$V513="",$U513<=0),"",$U513-$V513) | X513: =IF(OR($U513="",$V513="",$U513<=0),"",($U513-$V513)/$U513)
B514: =IF($C514="","",Prefixo&"-"&TEXT(ROW()-2,"0000")) | W514: =IF(OR($U514="",$V514="",$U514<=0),"",$U514-$V514) | X514: =IF(OR($U514="",$V514="",$U514<=0),"",($U514-$V514)/$U514)
... B1001: =IF($C1001="","",Prefixo&"-"&TEXT(ROW()-2,"0000")) | W1001: =IF(OR($U1001="",$V1001="",$U1001<=0),"",$U1001-$V1001) | X1001: =IF(OR($U1001="",$V1001="",$U1001<=0),"",($U1001-$V1001)/$U1001)

Sheet Workflow (Tracker)
B2: WORKFLOW E1–E8 — TRACKER DE ENTREGAS
B3: Governança total: os status E1–E8 são DERIVADOS dos critérios de aceite das 8 abas de etapa · Gates obrigatórios: E3 (escopo) e E5 (validação)
B5: COMO FUNCIONA
B6: • NÃO preencha nada nesta aba: cada etapa fica Concluído quando TODOS os critérios da aba correspondente estiverem ✔ (ou N/A); Bloqueado se houver ⛔; Em andamento se houver progresso parcial.
B7: • GATES: a E4 só inicia com a E3 = Concluído (escopo e critérios de aceite validados); a E6 só inicia com a E5 = Concluído (achados documentados e aprovados).
B8: • Trabalhe SEMPRE nas abas E1 a E8: marque os critérios, anexe a evidência/referência e a observação. O funil e a Etapa Atual atualizam sozinhos.
B10: FUNIL DO WORKFLOW — ONDE CADA ATIVIDADE ESTÁ (automático)
B11: E1 — Solicitação | D11: =COUNTIF($M$26:$M$525,B11) -> 0
B12: E2 — Triagem | D12: =COUNTIF($M$26:$M$525,B12) -> 0
B13: E3 — Levantamento ⚠ | D13: =COUNTIF($M$26:$M$525,B13) -> 0
B14: E4 — Execução | D14: =COUNTIF($M$26:$M$525,B14) -> 0
B15: E5 — Validação ⚠ | D15: =COUNTIF($M$26:$M$525,B15) -> 0
B16: E6 — Ajustes | D16: =COUNTIF($M$26:$M$525,B16) -> 0
B17: E7 — Entrega | D17: =COUNTIF($M$26:$M$525,B17) -> 0
B18: E08 — Estabilização / Hypercare | D18: =COUNTIF($M$26:$M$525,B18) -> 0
B19: ✔ Fluxo concluído | D19: =COUNTIF($M$26:$M$525,B19) -> 0
B20: Bloqueios em alguma etapa | D20: =COUNTIF($E$26:$L$525,"Bloqueado") -> 0
B21: Gate E3 pendente (escopo não fechado) | D21: =COUNTIFS($B$26:$B$525,"?*",$G$26:$G$525,"<>Concluído") -> 0
B22: Gate E5 pendente (validação não aprovada) | D22: =COUNTIFS($B$26:$B$525,"?*",$I$26:$I$525,"<>Concluído") -> 0
B24: TRACKER — UMA LINHA POR ATIVIDADE (100% automático — trabalhe nas abas E1 a E8)
B25: ID (auto) | C25: Atividade (auto) | D25: Pilar (auto) | E25: E1 Solicitação | F25: E2 Triagem | G25: E3 Levantamento ⚠ | H25: E4 Execução | I25: E5 Validação ⚠ | J25: E6 Ajustes | K25: E7 Entrega | L25: E8 Estabilização | M25: Etapa Atual (auto) | N25: % do Fluxo | O25: Observação do Fluxo
B26: =IF(Lançamentos!$B3="","",Lançamentos!$B3) | C26: =IF($B26="","",Lançamentos!$J3) | D26: =IF($B26="","",Lançamentos!$H3) | E26: =IF($B26="","",IF(COUNTIF(Lançamentos!$B$3:$B$1001,$B26)=0,"Bloqueado",IF(COUNTIF('E1 — Solicitação'!$E8:$L8,"⛔ Bloqueado")>0,"Bloqueado",IF(COUNTIF('E1 — Solicitação'!$E8:$L8,"N/A")=8,"Bloqueado",IF(COUNTIF('E1 — Solicitação'!$E8:$L8,"✔ Concluído")+COUNTIF('E1 — Solicitação'!$E8:$L8,"N/A")=8,"Concluído",IF(COUNTIF('E1 — Solicitação'!$E8:$L8,"✔ Concluído")+COUNTIF('E1 — Solicitação'!$E8:$L8,"🔄 Em andamento")>0,"Em andamento","Não iniciado")))))) | F26: =IF($B26="","",IF($E26<>"Concluído","Não iniciado",IF(COUNTIF(Lançamentos!$B$3:$B$1001,$B26)=0,"Bloqueado",IF('E2 — Triagem'!$D8="","Bloqueado",IF(COUNTIF('E2 — Triagem'!$E8:$L8,"N/A")=8,"Bloqueado",IF(COUNTIF('E2 — Triagem'!$E8:$L8,"⛔ Bloqueado")>0,"Bloqueado",IF(COUNTIF('E2 — Triagem'!$E8:$L8,"✔ Concluído")+COUNTIF('E2 — Triagem'!$E8:$L8,"N/A")=8,"Concluído",IF(COUNTIF('E2 — Triagem'!$E8:$L8,"✔ Concluído")+COUNTIF('E2 — Triagem'!$E8:$L8,"🔄 Em andamento")>0,"Em andamento","Não iniciado")))))))) | G26: =IF($B26="","",IF($F26<>"Concluído","Não iniciado",IF(COUNTIF(Lançamentos!$B$3:$B$1001,$B26)=0,"Bloqueado",IF('E3 — Levantamento'!$D8="","Bloqueado",IF(COUNTIF('E3 — Levantamento'!$E8:$I8,"⛔ Bloqueado")>0,"Bloqueado",IF('E3 — Levantamento'!$I8="N/A","Bloqueado",IF(COUNTIF('E3 — Levantamento'!$E8:$I8,"✔ Concluído")=5,"Concluído",IF(COUNTIF('E3 — Levantamento'!$E8:$I8,"✔ Concluído")+COUNTIF('E3 — Levantamento'!$E8:$I8,"🔄 Em andamento")>0,"Em andamento","Não iniciado")))))))) | H26: =IF($B26="","",IF($G26<>"Concluído","Não iniciado",IF(COUNTIF(Lançamentos!$B$3:$B$1001,$B26)=0,"Bloqueado",IF('E4 — Execução'!$D8="","Bloqueado",IF(COUNTIF('E4 — Execução'!$E8:$K8,"⛔ Bloqueado")>0,"Bloqueado",IF(COUNTIF('E4 — Execução'!$E8:$K8,"✔ Concluído")=7,"Concluído",IF(COUNTIF('E4 — Execução'!$E8:$K8,"✔ Concluído")+COUNTIF('E4 — Execução'!$E8:$K8,"🔄 Em andamento")>0,"Em andamento","Não iniciado"))))))) | I26: =IF($B26="","",IF($H26<>"Concluído","Não iniciado",IF(COUNTIF(Lançamentos!$B$3:$B$1001,$B26)=0,"Bloqueado",IF('E5 — Validação'!$D8="","Bloqueado",IF(COUNTIF('E5 — Validação'!$E8:$I8,"⛔ Bloqueado")>0,"Bloqueado",IF('E5 — Validação'!$I8="N/A","Bloqueado",IF(AND('E5 — Validação'!$E8="✔ Concluído",'E5 — Validação'!$F8="✔ Concluído",OR('E5 — Validação'!$G8="✔ Concluído",'E5 — Validação'!$G8="N/A"),'E5 — Validação'!$H8="✔ Concluído",'E5 — Validação'!$I8="✔ Concluído"),"Concluído",IF(COUNTIF('E5 — Validação'!$E8:$I8,"✔ Concluído")+COUNTIF('E5 — Validação'!$E8:$I8,"🔄 Em andamento")>0,"Em andamento","Não iniciado")))))))) | J26: =IF($B26="","",IF($I26<>"Concluído","Não iniciado",IF('E6 — Ajustes'!$N8="Não","N/A",IF(COUNTIF(Lançamentos!$B$3:$B$1001,$B26)=0,"Bloqueado",IF('E6 — Ajustes'!$D8="","Bloqueado",IF(COUNTIF('E6 — Ajustes'!$E8:$J8,"⛔ Bloqueado")>0,"Bloqueado",IF(AND('E6 — Ajustes'!$E8="✔ Concluído",'E6 — Ajustes'!$F8="✔ Concluído",'E6 — Ajustes'!$G8="✔ Concluído",'E6 — Ajustes'!$H8="✔ Concluído",OR('E6 — Ajustes'!$I8="✔ Concluído",'E6 — Ajustes'!$I8="N/A"),'E6 — Ajustes'!$J8="✔ Concluído"),"Concluído",IF(COUNTIF('E6 — Ajustes'!$E8:$J8,"✔ Concluído")+COUNTIF('E6 — Ajustes'!$E8:$J8,"🔄 Em andamento")>0,"Em andamento","Não iniciado")))))))) | K26: =IF($B26="","",IF($I26<>"Concluído","Não iniciado",IF(AND($J26<>"Concluído",$J26<>"N/A"),"Não iniciado",IF(COUNTIF(Lançamentos!$B$3:$B$1001,$B26)=0,"Bloqueado",IF('E7 — Entrega'!$D8="","Bloqueado",IF(COUNTIF('E7 — Entrega'!$E8:$H8,"⛔ Bloqueado")>0,"Bloqueado",IF(COUNTIF('E7 — Entrega'!$E8:$H8,"✔ Concluído")=4,"Concluído",IF(COUNTIF('E7 — Entrega'!$E8:$H8,"✔ Concluído")+COUNTIF('E7 — Entrega'!$E8:$H8,"🔄 Em andamento")>0,"Em andamento","Não iniciado")))))))) | L26: =IF($B26="","",IF($K26<>"Concluído","Não iniciado",IF(OR(COUNTIF('E08 — Estabilização Hypercare'!$E8:$J8,"⛔ Bloqueado")>0,'E08 — Estabilização Hypercare'!$N8="⛔ Incidente Crítico — Encerramento Bloqueado",AND('E08 — Estabilização Hypercare'!$N8="🆕 Evolução Identificada — Nova Demanda Aberta",'E08 — Estabilização Hypercare'!$U8="")),"Bloqueado",IF(AND('E08 — Estabilização Hypercare'!$E8="✔ Concluído",'E08 — Estabilização Hypercare'!$F8="✔ Concluído",'E08 — Estabilização Hypercare'!$G8="✔ Concluído",OR('E08 — Estabilização Hypercare'!$H8="✔ Concluído",'E08 — Estabilização Hypercare'!$H8="N/A"),'E08 — Estabilização Hypercare'!$I8="✔ Concluído",'E08 — Estabilização Hypercare'!$J8="✔ Concluído",OR('E08 — Estabilização Hypercare'!$N8="✅ Estável — Demanda Encerrada",AND('E08 — Estabilização Hypercare'!$N8="🆕 Evolução Identificada — Nova Demanda Aberta",'E08 — Estabilização Hypercare'!$U8<>""))),"Concluído",IF(OR(COUNTIF('E08 — Estabilização Hypercare'!$E8:$J8,"✔ Concluído")>0,COUNTIF('E08 — Estabilização Hypercare'!$E8:$J8,"🔄 Em andamento")>0,'E08 — Estabilização Hypercare'!$N8<>""),"Em andamento","Não iniciado"))))) | M26: {=IF(B26="","",_xlfn.IFS(E26<>"Concluído","E1 — Solicitação",F26<>"Concluído","E2 — Triagem",G26<>"Concluído","E3 — Levantamento ⚠",H26<>"Concluído","E4 — Execução",I26<>"Concluído","E5 — Validação ⚠",AND(J26<>"Concluído",J26<>"N/A"),"E6 — Ajustes",K26<>"Concluído","E7 — Entrega",L26<>"Concluído","E08 — Estabilização / Hypercare",TRUE,"✔ Fluxo concluído"))} | N26: =IF(B26="","",(COUNTIF(E26:L26,"Concluído")+COUNTIF(E26:L26,"N/A"))/8)
B27: =IF(Lançamentos!$B4="","",Lançamentos!$B4) | C27: =IF($B27="","",Lançamentos!$J4) | D27: =IF($B27="","",Lançamentos!$H4) | E27: =IF($B27="","",IF(COUNTIF(Lançamentos!$B$3:$B$1001,$B27)=0,"Bloqueado",IF(COUNTIF('E1 — Solicitação'!$E9:$L9,"⛔ Bloqueado")>0,"Bloqueado",IF(COUNTIF('E1 — Solicitação'!$E9:$L9,"N/A")=8,"Bloqueado",IF(COUNTIF('E1 — Solicitação'!$E9:$L9,"✔ Concluído")+COUNTIF('E1 — Solicitação'!$E9:$L9,"N/A")=8,"Concluído",IF(COUNTIF('E1 — Solicitação'!$E9:$L9,"✔ Concluído")+COUNTIF('E1 — Solicitação'!$E9:$L9,"🔄 Em andamento")>0,"Em andamento","Não iniciado")))))) | F27: =IF($B27="","",IF($E27<>"Concluído","Não iniciado",IF(COUNTIF(Lançamentos!$B$3:$B$1001,$B27)=0,"Bloqueado",IF('E2 — Triagem'!$D9="","Bloqueado",IF(COUNTIF('E2 — Triagem'!$E9:$L9,"N/A")=8,"Bloqueado",IF(COUNTIF('E2 — Triagem'!$E9:$L9,"⛔ Bloqueado")>0,"Bloqueado",IF(COUNTIF('E2 — Triagem'!$E9:$L9,"✔ Concluído")+COUNTIF('E2 — Triagem'!$E9:$L9,"N/A")=8,"Concluído",IF(COUNTIF('E2 — Triagem'!$E9:$L9,"✔ Concluído")+COUNTIF('E2 — Triagem'!$E9:$L9,"🔄 Em andamento")>0,"Em andamento","Não iniciado")))))))) | G27: =IF($B27="","",IF($F27<>"Concluído","Não iniciado",IF(COUNTIF(Lançamentos!$B$3:$B$1001,$B27)=0,"Bloqueado",IF('E3 — Levantamento'!$D9="","Bloqueado",IF(COUNTIF('E3 — Levantamento'!$E9:$I9,"⛔ Bloqueado")>0,"Bloqueado",IF('E3 — Levantamento'!$I9="N/A","Bloqueado",IF(COUNTIF('E3 — Levantamento'!$E9:$I9,"✔ Concluído")=5,"Concluído",IF(COUNTIF('E3 — Levantamento'!$E9:$I9,"✔ Concluído")+COUNTIF('E3 — Levantamento'!$E9:$I9,"🔄 Em andamento")>0,"Em andamento","Não iniciado")))))))) | H27: =IF($B27="","",IF($G27<>"Concluído","Não iniciado",IF(COUNTIF(Lançamentos!$B$3:$B$1001,$B27)=0,"Bloqueado",IF('E4 — Execução'!$D9="","Bloqueado",IF(COUNTIF('E4 — Execução'!$E9:$K9,"⛔ Bloqueado")>0,"Bloqueado",IF(COUNTIF('E4 — Execução'!$E9:$K9,"✔ Concluído")=7,"Concluído",IF(COUNTIF('E4 — Execução'!$E9:$K9,"✔ Concluído")+COUNTIF('E4 — Execução'!$E9:$K9,"🔄 Em andamento")>0,"Em andamento","Não iniciado"))))))) | I27: =IF($B27="","",IF($H27<>"Concluído","Não iniciado",IF(COUNTIF(Lançamentos!$B$3:$B$1001,$B27)=0,"Bloqueado",IF('E5 — Validação'!$D9="","Bloqueado",IF(COUNTIF('E5 — Validação'!$E9:$I9,"⛔ Bloqueado")>0,"Bloqueado",IF('E5 — Validação'!$I9="N/A","Bloqueado",IF(AND('E5 — Validação'!$E9="✔ Concluído",'E5 — Validação'!$F9="✔ Concluído",OR('E5 — Validação'!$G9="✔ Concluído",'E5 — Validação'!$G9="N/A"),'E5 — Validação'!$H9="✔ Concluído",'E5 — Validação'!$I9="✔ Concluído"),"Concluído",IF(COUNTIF('E5 — Validação'!$E9:$I9,"✔ Concluído")+COUNTIF('E5 — Validação'!$E9:$I9,"🔄 Em andamento")>0,"Em andamento","Não iniciado")))))))) | J27: =IF($B27="","",IF($I27<>"Concluído","Não iniciado",IF('E6 — Ajustes'!$N9="Não","N/A",IF(COUNTIF(Lançamentos!$B$3:$B$1001,$B27)=0,"Bloqueado",IF('E6 — Ajustes'!$D9="","Bloqueado",IF(COUNTIF('E6 — Ajustes'!$E9:$J9,"⛔ Bloqueado")>0,"Bloqueado",IF(AND('E6 — Ajustes'!$E9="✔ Concluído",'E6 — Ajustes'!$F9="✔ Concluído",'E6 — Ajustes'!$G9="✔ Concluído",'E6 — Ajustes'!$H9="✔ Concluído",OR('E6 — Ajustes'!$I9="✔ Concluído",'E6 — Ajustes'!$I9="N/A"),'E6 — Ajustes'!$J9="✔ Concluído"),"Concluído",IF(COUNTIF('E6 — Ajustes'!$E9:$J9,"✔ Concluído")+COUNTIF('E6 — Ajustes'!$E9:$J9,"🔄 Em andamento")>0,"Em andamento","Não iniciado")))))))) | K27: =IF($B27="","",IF($I27<>"Concluído","Não iniciado",IF(AND($J27<>"Concluído",$J27<>"N/A"),"Não iniciado",IF(COUNTIF(Lançamentos!$B$3:$B$1001,$B27)=0,"Bloqueado",IF('E7 — Entrega'!$D9="","Bloqueado",IF(COUNTIF('E7 — Entrega'!$E9:$H9,"⛔ Bloqueado")>0,"Bloqueado",IF(COUNTIF('E7 — Entrega'!$E9:$H9,"✔ Concluído")=4,"Concluído",IF(COUNTIF('E7 — Entrega'!$E9:$H9,"✔ Concluído")+COUNTIF('E7 — Entrega'!$E9:$H9,"🔄 Em andamento")>0,"Em andamento","Não iniciado")))))))) | L27: =IF($B27="","",IF($K27<>"Concluído","Não iniciado",IF(OR(COUNTIF('E08 — Estabilização Hypercare'!$E9:$J9,"⛔ Bloqueado")>0,'E08 — Estabilização Hypercare'!$N9="⛔ Incidente Crítico — Encerramento Bloqueado",AND('E08 — Estabilização Hypercare'!$N9="🆕 Evolução Identificada — Nova Demanda Aberta",'E08 — Estabilização Hypercare'!$U9="")),"Bloqueado",IF(AND('E08 — Estabilização Hypercare'!$E9="✔ Concluído",'E08 — Estabilização Hypercare'!$F9="✔ Concluído",'E08 — Estabilização Hypercare'!$G9="✔ Concluído",OR('E08 — Estabilização Hypercare'!$H9="✔ Concluído",'E08 — Estabilização Hypercare'!$H9="N/A"),'E08 — Estabilização Hypercare'!$I9="✔ Concluído",'E08 — Estabilização Hypercare'!$J9="✔ Concluído",OR('E08 — Estabilização Hypercare'!$N9="✅ Estável — Demanda Encerrada",AND('E08 — Estabilização Hypercare'!$N9="🆕 Evolução Identificada — Nova Demanda Aberta",'E08 — Estabilização Hypercare'!$U9<>""))),"Concluído",IF(OR(COUNTIF('E08 — Estabilização Hypercare'!$E9:$J9,"✔ Concluído")>0,COUNTIF('E08 — Estabilização Hypercare'!$E9:$J9,"🔄 Em andamento")>0,'E08 — Estabilização Hypercare'!$N9<>""),"Em andamento","Não iniciado"))))) | M27: {=IF(B27="","",_xlfn.IFS(E27<>"Concluído","E1 — Solicitação",F27<>"Concluído","E2 — Triagem",G27<>"Concluído","E3 — Levantamento ⚠",H27<>"Concluído","E4 — Execução",I27<>"Concluído","E5 — Validação ⚠",AND(J27<>"Concluído",J27<>"N/A"),"E6 — Ajustes",K27<>"Concluído","E7 — Entrega",L27<>"Concluído","E08 — Estabilização / Hypercare",TRUE,"✔ Fluxo concluído"))} | N27: =IF(B27="","",(COUNTIF(E27:L27,"Concluído")+COUNTIF(E27:L27,"N/A"))/8)
