Workbook
Name AvalDesemp: Cadastros!$Q$5:$Q$8
Name AvalPrazo: Cadastros!$R$5:$R$7
Name Beneficios: Cadastros!$H$5:$H$11
Name CategoriasImped: Cadastros!$P$5:$P$11
Name Complexidades: Cadastros!$F$5:$F$7
Name Departamentos: Cadastros!$B$5:$B$7
Name DeptosCSC: Cadastros!$K$5:$K$16
Name Empresas: Cadastros!$D$5:$D$11
Name EntBI: Cadastros!$AQ$5:$AQ$8
Name EntGov: Cadastros!$AN$5:$AN$10
Name EntMC: Cadastros!$AO$5:$AO$9
Name EntOper: Cadastros!$AS$5:$AS$11
Name EntPMO: Cadastros!$AR$5:$AR$8
Name EntTD: Cadastros!$AP$5:$AP$10
Name EquipePI: Cadastros!$M$5:$M$9
Name Impactos: Cadastros!$G$5:$G$7
Name MapaEnt: Cadastros!$X$5:$Y$10
Name MapaPessoas: Cadastros!$AA$5:$AB$16
Name MapaTemas: Cadastros!$U$5:$V$13
Name MotivoStatus: Cadastros!$O$5:$O$14
Name Papeis: Cadastros!$L$5:$L$6
Name Pes01: Cadastros!$AU$5:$AU$15
Name Pes02: Cadastros!$AV$5:$AV$18
Name Pes03: Cadastros!$AW$5:$AW$11
Name Pes04: Cadastros!$AX$5:$AX$25
Name Pes05: Cadastros!$AY$5:$AY$9
Name Pes06: Cadastros!$AZ$5:$AZ$12
Name Pes07: Cadastros!$BA$5:$BA$18
Name Pes08: Cadastros!$BB$5:$BB$15
Name Pes09: Cadastros!$BC$5:$BC$16
Name Pes10: Cadastros!$BD$5:$BD$12
Name Pes11: Cadastros!$BE$5:$BE$8
Name Pes12: Cadastros!$BF$5:$BF$8
Name Pilares: Cadastros!$J$5:$J$10
Name Prioridades: Cadastros!$E$5:$E$7
Name Projetos: Cadastros!$A$5:$A$13
Name RadarCor: Cadastros!$S$5:$S$7
Name SimNao: Cadastros!$I$5:$I$6
Name StatusList: Cadastros!$C$5:$C$10
Name StatusSemana: Cadastros!$N$5:$N$9
Name TemaActio: Cadastros!$AK$5:$AK$10
Name TemaIndMetas: Cadastros!$AL$5:$AL$10
Name TemaInvestidas: Cadastros!$AJ$5:$AJ$10
Name TemaLumen: Cadastros!$AD$5:$AD$18
Name TemaNewsletter: Cadastros!$AG$5:$AG$22
Name TemaRotinaFC: Cadastros!$AH$5:$AH$15
Name TemaRotinaFin: Cadastros!$AI$5:$AI$11
Name TemaSaneamento: Cadastros!$AF$5:$AF$7
Name TemaV360: Cadastros!$AE$5:$AE$7

Sheet Leia-me
A1: BASE GERENCIAL v3.4 — PROCESSOS INTEGRADOS
A2: Torre Financeira CSC · Consolidação de 4 analistas · Supervisora: Juliana Batista
A4: Papel desta pasta de trabalho
A5: BASE GERENCIAL v3.4 — consolidação da supervisora Juliana Batista (Departamento E — Processos Integrados). Fonte oficial da verdade: importa, valida e enriquece — nunca redigita.
A6: Fluxo: 4 planilhas dos analistas (JV, VL, JS, FM) → aba "Base Gerencial" (colunas A a AA, importadas) → colunas de gestão (AB a AJ) → Indicadores e Report (automáticos) → futuro sistema web.
A7: Regra de ID único (chave da consolidação)
A8: • Cada analista tem um PREFIXO exclusivo: JV = José Victor · VL = Viviane Lima · JS = Juliana Santos · FM = Filipe Messias (JB reservado para a supervisora).
A9: • O ID é gerado automaticamente na planilha do analista (ex.: FM-0001, JV-0001). Como os prefixos não se repetem, é impossível haver colisão de IDs entre as 4 planilhas.
A10: • PROTEÇÃO EXTRA: a coluna "ID Origem" fica VERMELHA se algum ID aparecer duplicado após a consolidação (ex.: mesmo arquivo importado duas vezes), e o indicador "IDs duplicados" na aba Indicadores deve ser sempre 0.
A11: • Analistas não devem excluir linhas do meio (renumeraria IDs); atividades descartadas ficam com Status = Cancelado.
A12: Trabalho em parceria (sem contagem dupla)
A13: • Atividades grandes podem ter 2+ participantes: o Responsável registra a entrega completa e lista os parceiros; cada parceiro lança uma linha com Papel = Apoio, suas horas e o ID da Atividade Principal.
... A28: • Nunca altere os Cadastros sem replicar nas 4 planilhas dos analistas.

Sheet Base Gerencial
A1: Analista | B1: ID Origem | C1: Data Início | D1: Data Conclusão | E1: Departamento | F1: Projeto | G1: Tema | H1: Pilar Proc. Integrados | I1: Tipo de Demanda | J1: Atividade (título curto) | K1: Descrição | L1: Depto. Envolvido (CSC) | M1: Pessoa Envolvida | N1: Parceria? | O1: Papel na Atividade | P1: Parceiros (equipe PI) | Q1: ID Atividade Principal | R1: Empresa | S1: Status | T1: Horas Gastas | U1: Tempo Antes (h/mês) | V1: Tempo Depois (h/mês) | W1: Ganho (h/mês) | X1: % Redução | Y1: Resultado Alcançado | Z1: Pendência / Próximo Passo | AA1: Observação Analista | AB1: Validado | AC1: Prioridade | AD1: Complexidade | AE1: Impacto | AF1: Categoria de Benefício | AG1: Pessoas Impactadas | AH1: Economia Estimada (R$) — opcional | AI1: Observação Executiva | AJ1: Destaque Report
A2: Filipe Messias | B2: FM-0001 | C2: 46205 | D2: 46210 | E2: Fiscal/Contábil | F2: Lumen | G2: PIS/COFINS | H2: Transformação Digital | I2: Obrigação Acessória | J2: Auditoria SPED EFD Contribuições | K2: Realiza a auditoria comparativa da EFD Contribuições, identificando alterações entre arquivos originais e retificados, com análise mensal ou anual, comparação de blocos, registros, campos e valores, além da exportação dos resultados em Excel e PDF. | L2: Tributos Federais | M2: Maria Estela | N2: Não | O2: Responsável | R2: Todas | S2: Concluído | T2: 8 | U2: 60 | V2: 1 | W2: =IF($U2>0,$U2-$V2,"") -> 59 | X2: =IF($U2>0,($U2-$V2)/$U2,"") -> 0.98333333 | Y2: Comparativo original x retificado disponível para toda a equipe, com exportação em Excel e PDF; divergências identificadas antes da transmissão. | Z2: Sem pendências | AA2: Utilize arquivos originais e retificados correspondentes ao mesmo período para garantir uma comparação correta dos dados. | AB2: Sim | AC2: Alta | AD2: Alta | AE2: Alto | AF2: Qualidade | AG2: 9 | AI2: Auditoria pré-transmissão reduz risco de retificação | AJ2: Sim
A3: Filipe Messias | B3: FM-0002 | C3: 46204 | D3: 46211 | E3: Financeiro | F3: Saneamento Base Contábil | G3: Adiantamento de Fornecedores | H3: Transformação Digital | I3: Automação | J3: Processamento de documentos de adiantamentos | K3: Leitura automatizada de 1.374 arquivos PDF para extração de informações dos processos de adiantamento de fornecedores, consolidando dados como solicitante, aprovador, motivo, pedido de compra, NFS-e e demais informações para geração de relatório gerencial e planilha em Excel. | L3: Tesouraria | M3: Erica Arcoverde (Supervisora) | N3: Sim | O3: Responsável | P3: José Victor | R3: ELET | S3: Concluído | T3: 12 | U3: 60 | V3: 4 | W3: =IF($U3>0,$U3-$V3,"") -> 56 | X3: =IF($U3>0,($U3-$V3)/$U3,"") -> 0.93333333 | Y3: 1.374 PDFs lidos automaticamente; relatório gerencial e planilha Excel gerados, com campos "Não Identificado" quando não houve evidência no documento. | Z3: Sem pendências | AA3: As informações foram extraídas exclusivamente das evidências contidas nos documentos. Quando um dado não pôde ser comprovado, o sistema preencheu o campo como "Não Identificado", garantindo a confiabilidade da análise. | AB3: Sim | AC3: Alta | AD3: Alta | AE3: Alto | AF3: Tempo | AG3: 12 | AI3: Leitura automatizada de 1.374 PDFs (parceria FM+JV) | AJ3: Sim
A4: Filipe Messias | B4: FM-0003 | C4: 46204 | D4: 46211 | E4: Financeiro | F4: Rotina Financeiro | G4: Pagamento de Tributos (DARF/GPS) | H4: Transformação Digital | I4: Automação | J4: Automação da emissão de DARF (SICALC) | K4: Robô Python/Selenium para cálculo e emissão de DARFs no portal SICALC, com validação humana do captcha. | L4: Tesouraria | M4: Daiane Vicente | N4: Não | O4: Responsável | R4: ELET | S4: Concluído | T4: 12 | U4: 24 | V4: 8 | W4: =IF($U4>0,$U4-$V4,"") -> 16 | X4: =IF($U4>0,($U4-$V4)/$U4,"") -> 0.66666667 | Y4: 95% das DARFs passaram a ser emitidas automaticamente; emissão manual eliminada. | Z4: Sem pendências | AA4: Piloto aprovado pela gestão | AB4: Sim | AC4: Alta | AD4: Alta | AE4: Alto | AF4: Financeiro | AG4: 12 | AH4: 8500 | AI4: 95% das DARFs automatizadas; emissão manual eliminada | AJ4: Sim
A5: Filipe Messias | B5: FM-0004 | C5: 46207 | D5: 46209 | E5: Torre Financeira - CSC | F5: Newsletter | G5: M01 - Normas Gerais da Tributação do Consumo | H5: Governança | I5: Publicação/Conteúdo Técnico | J5: Edição M01 da Newsletter Tributária | K5: Conteúdo sobre fato gerador, base de cálculo, alíquotas e não cumulatividade da CBS/IBS. | L5: Gestão | M5: Angela Ritchie (Coordenadora) | N5: Não | O5: Responsável | R5: Todas | S5: Não iniciado | T5: 8 | W5: =IF($U5>0,$U5-$V5,"") | X5: =IF($U5>0,($U5-$V5)/$U5,"") | Y5: Edição distribuída ao CSC por e-mail; equipes atualizadas sobre a Reforma Tributária (CBS/IBS). | Z5: Elaborar material de estudo | AA5: Distribuída por e-mail ao CSC | AB5: Não | AC5: Média | AD5: Baixa | AE5: Médio | AF5: Pessoas | AI5: Aguardando início do material de estudo | AJ5: Não
A6: Filipe Messias | B6: FM-0005 | C6: 46212 | E6: Fiscal/Contábil | F6: V360 | G6: Dashboard Entrada de NF - TicketLog x V360 | H6: Melhoria Contínua | I6: Gargalo eliminado | J6: Conciliação de notas TicketLog × V360 | K6: Automação que cruza as notas do relatório TicketLog com a base V360 para localizar o ID V360, apoiar a baixa em massa e identificar pendências entre as duas bases. A validação ocorre primeiro pela Chave de Acesso e, quando indisponível, por No da NF + CNPJ do fornecedor + tipo, com conferência de valor. | L6: Recebimento Fiscal | N6: Não | O6: Responsável | R6: Todas | S6: Em validação | W6: =IF($U6>0,$U6-$V6,"") | X6: =IF($U6>0,($U6-$V6)/$U6,"") | Y6: Estrutura automatizada de conciliação em duas direções, com identificação do ID V360, separação entre notas de material e serviço, indicadores de conciliadas e pendentes e lista acionável para tratamento do backlog. | Z6: Feedback da ferramenta | AA6: Capacidade planejada para até 10.000 notas/mês. Abas de origem: base-faturamento e base-v360. Engine principal: consolidado-material-servico. Saídas: analise-material, analise-servico, analise-faturamento, analise-v360 e consolidado-v360-faturamento. | AB6: Não | AC6: Alta | AD6: Alta | AE6: Alto | AF6: Operação | AI6: Conciliação TicketLog×V360 em validação | AJ6: Não
A7: Filipe Messias | B7: FM-0006 | C7: 46190 | D7: 46192 | E7: Fiscal/Contábil | F7: Rotina Fiscal/Contábil | H7: Transformação Digital | I7: OCR/Processamento de Documentos | J7: Conversor PDF para Excel de notas fiscais | K7: Desenvolvimento de aplicação web local para converter PDFs de relatórios de notas fiscais da Prefeitura de Paulo Afonso em planilhas Excel estruturadas. A solução recebe arquivos PDF em lote, processa as páginas por OCR, reconstrói linhas e colunas da tabela por coordenadas, normaliza erros comuns de leitura e gera arquivos .xlsx formatados para conferência e uso pela área fiscal. | L7: Recebimento Fiscal | M7: A confirmar | N7: Não | O7: Responsável | R7: CHESF | S7: Em validação | T7: 16 | U7: 6 | V7: 1.2 | W7: =IF($U7>0,$U7-$V7,"") -> 4.8 | X7: =IF($U7>0,($U7-$V7)/$U7,"") -> 0.8 | Y7: Aplicação funcional em Flask com upload de 1 a 12 PDFs, conversão sequencial, barra de progresso, geração individual de Excel e opção de baixar os resultados em ZIP. Reduz o trabalho manual de digitação e cópia de dados, padroniza a saída em Excel e acelera a preparação de bases fiscais. | Z7: Validar uma amostra final com a área fiscal, confirmar a acurácia do OCR, registrar tempos reais de execução e conferência e ajustar a pessoa responsável na tabela mestra. | AA7: Classificação sugerida: Transformação Digital / OCR. Se necessário, avaliar o enquadramento como Projeto Lumen e Tema Notas Fiscais. A primeira execução pode demorar devido ao carregamento do modelo OCR. | AB7: Não | AC7: Média | AD7: Média | AE7: Médio | AF7: Tempo | AI7: OCR aguardando validação da área fiscal | AJ7: Não
A8: Filipe Messias | B8: FM-0007 | C8: 46174 | E8: Fiscal/Contábil | F8: Rotina Fiscal/Contábil | G8: Apurações | H8: Transformação Digital | I8: Automação | J8: Excel Cleaner ETL para arquivos PIS/COFINS | K8: Desenvolvimento de aplicação web local para reduzir o tamanho de arquivos Excel de apuração de PIS/COFINS, preservando dados, fórmulas, formatação, gráficos e estrutura das tabelas dinâmicas. A ferramenta remove elementos internos redundantes, como ícones decorativos, cache de tabelas dinâmicas e cadeia de cálculo, e recomprime arquivos .xlsx e .xlsb com nível máximo de compressão. | L8: Tributos Federais | M8: A confirmar | N8: Não | O8: Responsável | R8: Todas | S8: Em validação | W8: =IF($U8>0,$U8-$V8,"") | X8: =IF($U8>0,($U8-$V8)/$U8,"") | Y8: Ferramenta funcional com processamento local e preservação da integridade dos arquivos. Nos testes, um arquivo .xlsx foi reduzido de 75,4 MB para 27,9 MB (63%) em aproximadamente 15 segundos, e um arquivo .xlsb foi reduzido de 13,4 MB para cerca de 7 MB (aproximadamente 46%) em aproximadamente 5 segundos. | Z8: Homologar no ambiente corporativo, validar arquivos adicionais de PIS/COFINS, confirmar o responsável, registrar horas de desenvolvimento e medir o ganho mensal real. Após o processamento, atualizar as tabelas dinâmicas no Excel. | AA8: Processamento 100% local, sem envio dos arquivos para serviços externos. A solução preserva valores, fórmulas, formatação e gráficos reais, mas remove ícones decorativos, caches de tabelas dinâmicas e calcChain. Manter sempre o arquivo original intacto; arquivos .xlsm não são suportados na versão atual. | AB8: Não | AC8: Média | AD8: Média | AE8: Médio | AF8: Tecnologia | AI8: Compressão de arquivos em homologação | AJ8: Não
A9: Filipe Messias | B9: FM-0008 | C9: 46205 | D9: 46205 | E9: Financeiro | F9: V360 | G9: Dashboard Entrada de NF - SAP x V360 | H9: Business Intelligence | I9: KPI/Indicador publicado | J9: Memória de cálculo dos índices V360 | K9: Elaboração e validação da memória de cálculo do BI Torre Financeira V360, documentando a base padrão base-v360.xlsx, com 341.867 registros, e as regras dos indicadores de visão geral, Torre Financeira, fluxo de subcontratadas e aguardando pagamento. O trabalho formaliza critérios de normalização textual, cálculo de dias na tarefa, dias de emissão, regra de vencimento acima de 40 dias, notas em aberto, fluxo principal, subcontratadas, Torre Financeira e carteira aguardando pagamento. | L9: Processos Integrados | M9: A confirmar | N9: Não | O9: Responsável | R9: Todas | S9: Concluído | T9: 24 | U9: 16 | V9: 2 | W9: =IF($U9>0,$U9-$V9,"") -> 14 | X9: =IF($U9>0,($U9-$V9)/$U9,"") -> 0.875 | Y9: Memória de cálculo estruturada e auditável para os indicadores V360, com fórmulas, bases de filtro, critérios de classificação, regras de arredondamento e retrato numérico da base atual. A documentação aumenta a rastreabilidade dos KPIs, reduz retrabalho de conferência manual e padroniza a interpretação dos números publicados no BI. | Z9: Confirmar responsável nominal, validar se o escopo da empresa deve permanecer como Todas ou ser restrito a uma empresa específica, e manter a memória atualizada a cada alteração de regra ou atualização relevante da base. | AA9: Valores de tempo são estimativas. Base verificada em 02/07/2026. A regra de vencimento usa dias na tarefa, não data de vencimento. O status Concluídas é calculado por diferença entre fluxo principal e notas em aberto. | AB9: Sim | AC9: Média | AD9: Média | AE9: Alto | AF9: Qualidade | AG9: 8 | AI9: KPIs do V360 rastreáveis e auditáveis | AJ9: Sim
W19: =IF($U19>0,$U19-$V19,"") | X19: =IF($U19>0,($U19-$V19)/$U19,"")
W20: =IF($U20>0,$U20-$V20,"") | X20: =IF($U20>0,($U20-$V20)/$U20,"")
W21: =IF($U21>0,$U21-$V21,"") | X21: =IF($U21>0,($U21-$V21)/$U21,"")
W22: =IF($U22>0,$U22-$V22,"") | X22: =IF($U22>0,($U22-$V22)/$U22,"")
W23: =IF($U23>0,$U23-$V23,"") | X23: =IF($U23>0,($U23-$V23)/$U23,"")
W24: =IF($U24>0,$U24-$V24,"") | X24: =IF($U24>0,($U24-$V24)/$U24,"")
W25: =IF($U25>0,$U25-$V25,"") | X25: =IF($U25>0,($U25-$V25)/$U25,"")
W26: =IF($U26>0,$U26-$V26,"") | X26: =IF($U26>0,($U26-$V26)/$U26,"")
W27: =IF($U27>0,$U27-$V27,"") | X27: =IF($U27>0,($U27-$V27)/$U27,"")
W28: =IF($U28>0,$U28-$V28,"") | X28: =IF($U28>0,($U28-$V28)/$U28,"")
W29: =IF($U29>0,$U29-$V29,"") | X29: =IF($U29>0,($U29-$V29)/$U29,"")
W30: =IF($U30>0,$U30-$V30,"") | X30: =IF($U30>0,($U30-$V30)/$U30,"")
... W2000: =IF($U2000>0,$U2000-$V2000,"") | X2000: =IF($U2000>0,($U2000-$V2000)/$U2000,"")

Sheet Acomp. Equipe
A1: ACOMP. EQUIPE — cole aqui as tabelas da seção 2 dos 4 analistas, ACUMULANDO semana a semana (histórico completo)
A2: Analista | B2: Semana | C2: ID | D2: Projeto | E2: Atividade | F2: Status da Semana | G2: Motivo do Status | H2: O que foi realizado na semana? | I2: Próximo Passo | J2: Necessita Apoio? | K2: Responsável pela Pendência | L2: Previsão de Conclusão | M2: Evolução (%) | N2: Semanas Reportadas (auto)
A3: Filipe Messias | B3: Semana 27 | C3: FM-0006 | D3: Rotina Fiscal/Contábil | E3: Conversor PDF para Excel de notas fiscais | F3: 🟡 Em andamento | G3: Em validação | H3: Conversões de teste com 12 PDFs concluídas | I3: Enviar amostra à área fiscal | J3: Não | L3: 46213 | M3: 0.8 | N3: =IF($C3="","",COUNTIF($C$3:$C$296,$C3)) -> 2
A4: Filipe Messias | B4: Semana 28 | C4: FM-0006 | D4: Rotina Fiscal/Contábil | E4: Conversor PDF para Excel de notas fiscais | F4: ⏸ Aguardando Terceiros | G4: Aguardando outra área | H4: Amostra enviada; sem retorno do Recebimento Fiscal | I4: Cobrar validação da amostra | J4: Sim | K4: Recebimento Fiscal | L4: 46220 | M4: 0.85 | N4: =IF($C4="","",COUNTIF($C$3:$C$296,$C4)) -> 2
A5: Filipe Messias | B5: Semana 28 | C5: FM-0005 | D5: V360 | E5: Conciliação de notas TicketLog × V360 | F5: 🟡 Em andamento | G5: Em validação | H5: Conciliação executada nas bases de junho | I5: Colher feedback da ferramenta | J5: Não | L5: 46220 | M5: 0.9 | N5: =IF($C5="","",COUNTIF($C$3:$C$296,$C5)) -> 1
A6: Filipe Messias | B6: Semana 28 | C6: FM-0007 | D6: Rotina Fiscal/Contábil | E6: Excel Cleaner ETL para arquivos PIS/COFINS | F6: ⏸ Aguardando Terceiros | G6: Em homologação | H6: Testes de compressão em arquivos reais concluídos | I6: Homologar no ambiente corporativo | J6: Sim | K6: TI | L6: 46227 | M6: 0.7 | N6: =IF($C6="","",COUNTIF($C$3:$C$296,$C6)) -> 1
N7: =IF($C7="","",COUNTIF($C$3:$C$296,$C7))
N8: =IF($C8="","",COUNTIF($C$3:$C$296,$C8))
N9: =IF($C9="","",COUNTIF($C$3:$C$296,$C9))
N10: =IF($C10="","",COUNTIF($C$3:$C$296,$C10))
N11: =IF($C11="","",COUNTIF($C$3:$C$296,$C11))
N12: =IF($C12="","",COUNTIF($C$3:$C$296,$C12))
N13: =IF($C13="","",COUNTIF($C$3:$C$296,$C13))
N14: =IF($C14="","",COUNTIF($C$3:$C$296,$C14))
N15: =IF($C15="","",COUNTIF($C$3:$C$296,$C15))
N16: =IF($C16="","",COUNTIF($C$3:$C$296,$C16))
N17: =IF($C17="","",COUNTIF($C$3:$C$296,$C17))
N18: =IF($C18="","",COUNTIF($C$3:$C$296,$C18))
... N296: =IF($C296="","",COUNTIF($C$3:$C$296,$C296))

Sheet Acompanhamento Semanal
A1: ACOMPANHAMENTO SEMANAL — VISÃO DA GESTORA
A2: Consolidação automática · Concluídas não aparecem aqui · Gargalos = atividades reportadas em 2+ semanas
A4: IDENTIFICAÇÃO
A5: Semana (nº / descrição): | B5: Semana 28
A6: Período — de: | B6: 46209 | C6: até: | D6: 46213
A8: 1. RESUMO EXECUTIVO DA SEMANA (automático)
A9: Linhas reportadas (histórico acumulado) | E9: =COUNTIF('Acomp. Equipe'!$C$3:$C$296,"<>") -> 4
A10: Atividades distintas reportadas | E10: =SUMPRODUCT(('Acomp. Equipe'!$C$3:$C$296<>"")/COUNTIF('Acomp. Equipe'!$C$3:$C$296,'Acomp. Equipe'!$C$3:$C$296&"")) -> 3
A11: 🟢 Concluídas (reportadas) | E11: =COUNTIF('Acomp. Equipe'!$F$3:$F$296,"🟢 Concluído") -> 0
A12: 🟡 Em andamento | E12: =COUNTIF('Acomp. Equipe'!$F$3:$F$296,"🟡 Em andamento") -> 2
A13: 🔴 Bloqueadas | E13: =COUNTIF('Acomp. Equipe'!$F$3:$F$296,"🔴 Bloqueado") -> 0
A14: ⏸ Aguardando terceiros | E14: =COUNTIF('Acomp. Equipe'!$F$3:$F$296,"⏸ Aguardando Terceiros") -> 2
A15: ⚠ Necessitam apoio do gestor | E15: =COUNTIFS('Acomp. Equipe'!$J$3:$J$296,"Sim",'Acomp. Equipe'!$F$3:$F$296,"<>🟢 Concluído") -> 2
A16: Analistas reportando | E16: =SUMPRODUCT(('Acomp. Equipe'!$A$3:$A$296<>"")/COUNTIF('Acomp. Equipe'!$A$3:$A$296,'Acomp. Equipe'!$A$3:$A$296&"")) -> 1
A17: Entregas concluídas na semana (Base Gerencial) | E17: =COUNTIFS('Base Gerencial'!$S$2:$S$2000,"Concluído",'Base Gerencial'!$D$2:$D$2000,">="&$B$6,'Base Gerencial'!$D$2:$D$2000,"<="&$D$6,'Base Gerencial'!$O$2:$O$2000,"<>Apoio") -> 3
A18: Horas das entregas da semana | E18: =SUMIFS('Base Gerencial'!$T$2:$T$2000,'Base Gerencial'!$S$2:$S$2000,"Concluído",'Base Gerencial'!$D$2:$D$2000,">="&$B$6,'Base Gerencial'!$D$2:$D$2000,"<="&$D$6) -> 32
A19: Ganho de produtividade gerado na semana (h/mês) | E19: =SUMIFS('Base Gerencial'!$W$2:$W$2000,'Base Gerencial'!$S$2:$S$2000,"Concluído",'Base Gerencial'!$D$2:$D$2000,">="&$B$6,'Base Gerencial'!$D$2:$D$2000,"<="&$D$6,'Base Gerencial'!$O$2:$O$2000,"<>Apoio") -> 131
A21: 2. 🔴 ATIVIDADES BLOQUEADAS
A22: Analista | B22: Semana | C22: ID | D22: Projeto | E22: Atividade | F22: Motivo | G22: Previsão | H22: Semanas
A23: =IF($L23="","",INDEX('Acomp. Equipe'!$A:$A,$L23)) | B23: =IF($L23="","",INDEX('Acomp. Equipe'!$B:$B,$L23)) | C23: =IF($L23="","",INDEX('Acomp. Equipe'!$C:$C,$L23)) | D23: =IF($L23="","",INDEX('Acomp. Equipe'!$D:$D,$L23)) | E23: =IF($L23="","",INDEX('Acomp. Equipe'!$E:$E,$L23)) | F23: =IF($L23="","",INDEX('Acomp. Equipe'!$G:$G,$L23)) | G23: =IF($L23="","",INDEX('Acomp. Equipe'!$L:$L,$L23)) | H23: =IF($L23="","",INDEX('Acomp. Equipe'!$N:$N,$L23)) | L23: =IFERROR(_xlfn.AGGREGATE(15,6,ROW('Acomp. Equipe'!$C$3:$C$296)/(('Acomp. Equipe'!$F$3:$F$296="🔴 Bloqueado")),1),"")
A24: =IF($L24="","",INDEX('Acomp. Equipe'!$A:$A,$L24)) | B24: =IF($L24="","",INDEX('Acomp. Equipe'!$B:$B,$L24)) | C24: =IF($L24="","",INDEX('Acomp. Equipe'!$C:$C,$L24)) | D24: =IF($L24="","",INDEX('Acomp. Equipe'!$D:$D,$L24)) | E24: =IF($L24="","",INDEX('Acomp. Equipe'!$E:$E,$L24)) | F24: =IF($L24="","",INDEX('Acomp. Equipe'!$G:$G,$L24)) | G24: =IF($L24="","",INDEX('Acomp. Equipe'!$L:$L,$L24)) | H24: =IF($L24="","",INDEX('Acomp. Equipe'!$N:$N,$L24)) | L24: =IFERROR(_xlfn.AGGREGATE(15,6,ROW('Acomp. Equipe'!$C$3:$C$296)/(('Acomp. Equipe'!$F$3:$F$296="🔴 Bloqueado")),2),"")
A25: =IF($L25="","",INDEX('Acomp. Equipe'!$A:$A,$L25)) | B25: =IF($L25="","",INDEX('Acomp. Equipe'!$B:$B,$L25)) | C25: =IF($L25="","",INDEX('Acomp. Equipe'!$C:$C,$L25)) | D25: =IF($L25="","",INDEX('Acomp. Equipe'!$D:$D,$L25)) | E25: =IF($L25="","",INDEX('Acomp. Equipe'!$E:$E,$L25)) | F25: =IF($L25="","",INDEX('Acomp. Equipe'!$G:$G,$L25)) | G25: =IF($L25="","",INDEX('Acomp. Equipe'!$L:$L,$L25)) | H25: =IF($L25="","",INDEX('Acomp. Equipe'!$N:$N,$L25)) | L25: =IFERROR(_xlfn.AGGREGATE(15,6,ROW('Acomp. Equipe'!$C$3:$C$296)/(('Acomp. Equipe'!$F$3:$F$296="🔴 Bloqueado")),3),"")
A26: =IF($L26="","",INDEX('Acomp. Equipe'!$A:$A,$L26)) | B26: =IF($L26="","",INDEX('Acomp. Equipe'!$B:$B,$L26)) | C26: =IF($L26="","",INDEX('Acomp. Equipe'!$C:$C,$L26)) | D26: =IF($L26="","",INDEX('Acomp. Equipe'!$D:$D,$L26)) | E26: =IF($L26="","",INDEX('Acomp. Equipe'!$E:$E,$L26)) | F26: =IF($L26="","",INDEX('Acomp. Equipe'!$G:$G,$L26)) | G26: =IF($L26="","",INDEX('Acomp. Equipe'!$L:$L,$L26)) | H26: =IF($L26="","",INDEX('Acomp. Equipe'!$N:$N,$L26)) | L26: =IFERROR(_xlfn.AGGREGATE(15,6,ROW('Acomp. Equipe'!$C$3:$C$296)/(('Acomp. Equipe'!$F$3:$F$296="🔴 Bloqueado")),4),"")
A27: =IF($L27="","",INDEX('Acomp. Equipe'!$A:$A,$L27)) | B27: =IF($L27="","",INDEX('Acomp. Equipe'!$B:$B,$L27)) | C27: =IF($L27="","",INDEX('Acomp. Equipe'!$C:$C,$L27)) | D27: =IF($L27="","",INDEX('Acomp. Equipe'!$D:$D,$L27)) | E27: =IF($L27="","",INDEX('Acomp. Equipe'!$E:$E,$L27)) | F27: =IF($L27="","",INDEX('Acomp. Equipe'!$G:$G,$L27)) | G27: =IF($L27="","",INDEX('Acomp. Equipe'!$L:$L,$L27)) | H27: =IF($L27="","",INDEX('Acomp. Equipe'!$N:$N,$L27)) | L27: =IFERROR(_xlfn.AGGREGATE(15,6,ROW('Acomp. Equipe'!$C$3:$C$296)/(('Acomp. Equipe'!$F$3:$F$296="🔴 Bloqueado")),5),"")
A28: =IF($L28="","",INDEX('Acomp. Equipe'!$A:$A,$L28)) | B28: =IF($L28="","",INDEX('Acomp. Equipe'!$B:$B,$L28)) | C28: =IF($L28="","",INDEX('Acomp. Equipe'!$C:$C,$L28)) | D28: =IF($L28="","",INDEX('Acomp. Equipe'!$D:$D,$L28)) | E28: =IF($L28="","",INDEX('Acomp. Equipe'!$E:$E,$L28)) | F28: =IF($L28="","",INDEX('Acomp. Equipe'!$G:$G,$L28)) | G28: =IF($L28="","",INDEX('Acomp. Equipe'!$L:$L,$L28)) | H28: =IF($L28="","",INDEX('Acomp. Equipe'!$N:$N,$L28)) | L28: =IFERROR(_xlfn.AGGREGATE(15,6,ROW('Acomp. Equipe'!$C$3:$C$296)/(('Acomp. Equipe'!$F$3:$F$296="🔴 Bloqueado")),6),"")
A29: =IF($L29="","",INDEX('Acomp. Equipe'!$A:$A,$L29)) | B29: =IF($L29="","",INDEX('Acomp. Equipe'!$B:$B,$L29)) | C29: =IF($L29="","",INDEX('Acomp. Equipe'!$C:$C,$L29)) | D29: =IF($L29="","",INDEX('Acomp. Equipe'!$D:$D,$L29)) | E29: =IF($L29="","",INDEX('Acomp. Equipe'!$E:$E,$L29)) | F29: =IF($L29="","",INDEX('Acomp. Equipe'!$G:$G,$L29)) | G29: =IF($L29="","",INDEX('Acomp. Equipe'!$L:$L,$L29)) | H29: =IF($L29="","",INDEX('Acomp. Equipe'!$N:$N,$L29)) | L29: =IFERROR(_xlfn.AGGREGATE(15,6,ROW('Acomp. Equipe'!$C$3:$C$296)/(('Acomp. Equipe'!$F$3:$F$296="🔴 Bloqueado")),7),"")
A30: =IF($L30="","",INDEX('Acomp. Equipe'!$A:$A,$L30)) | B30: =IF($L30="","",INDEX('Acomp. Equipe'!$B:$B,$L30)) | C30: =IF($L30="","",INDEX('Acomp. Equipe'!$C:$C,$L30)) | D30: =IF($L30="","",INDEX('Acomp. Equipe'!$D:$D,$L30)) | E30: =IF($L30="","",INDEX('Acomp. Equipe'!$E:$E,$L30)) | F30: =IF($L30="","",INDEX('Acomp. Equipe'!$G:$G,$L30)) | G30: =IF($L30="","",INDEX('Acomp. Equipe'!$L:$L,$L30)) | H30: =IF($L30="","",INDEX('Acomp. Equipe'!$N:$N,$L30)) | L30: =IFERROR(_xlfn.AGGREGATE(15,6,ROW('Acomp. Equipe'!$C$3:$C$296)/(('Acomp. Equipe'!$F$3:$F$296="🔴 Bloqueado")),8),"")
A32: 3. ⚠ EXIGEM AÇÃO DO GESTOR (Necessita Apoio = Sim)
A33: Analista | B33: ID | C33: Projeto | D33: Atividade | E33: Motivo | F33: Resp. Pendência | G33: Semanas | H33: Ação do Gestor
A34: =IF($L34="","",INDEX('Acomp. Equipe'!$A:$A,$L34)) -> Filipe Messias | B34: =IF($L34="","",INDEX('Acomp. Equipe'!$C:$C,$L34)) -> FM-0006 | C34: =IF($L34="","",INDEX('Acomp. Equipe'!$D:$D,$L34)) -> Rotina Fiscal/Contábil | D34: =IF($L34="","",INDEX('Acomp. Equipe'!$E:$E,$L34)) -> Conversor PDF para Excel de notas fiscais | E34: =IF($L34="","",INDEX('Acomp. Equipe'!$G:$G,$L34)) -> Aguardando outra área | F34: =IF($L34="","",INDEX('Acomp. Equipe'!$K:$K,$L34)) -> Recebimento Fiscal | G34: =IF($L34="","",INDEX('Acomp. Equipe'!$N:$N,$L34)) -> 2 | L34: =IFERROR(_xlfn.AGGREGATE(15,6,ROW('Acomp. Equipe'!$C$3:$C$296)/(('Acomp. Equipe'!$J$3:$J$296="Sim")*('Acomp. Equipe'!$F$3:$F$296<>"🟢 Concluído")),1),"") -> 4
A35: =IF($L35="","",INDEX('Acomp. Equipe'!$A:$A,$L35)) -> Filipe Messias | B35: =IF($L35="","",INDEX('Acomp. Equipe'!$C:$C,$L35)) -> FM-0007 | C35: =IF($L35="","",INDEX('Acomp. Equipe'!$D:$D,$L35)) -> Rotina Fiscal/Contábil | D35: =IF($L35="","",INDEX('Acomp. Equipe'!$E:$E,$L35)) -> Excel Cleaner ETL para arquivos PIS/COFINS | E35: =IF($L35="","",INDEX('Acomp. Equipe'!$G:$G,$L35)) -> Em homologação | F35: =IF($L35="","",INDEX('Acomp. Equipe'!$K:$K,$L35)) -> TI | G35: =IF($L35="","",INDEX('Acomp. Equipe'!$N:$N,$L35)) -> 1 | L35: =IFERROR(_xlfn.AGGREGATE(15,6,ROW('Acomp. Equipe'!$C$3:$C$296)/(('Acomp. Equipe'!$J$3:$J$296="Sim")*('Acomp. Equipe'!$F$3:$F$296<>"🟢 Concluído")),2),"") -> 6
A36: =IF($L36="","",INDEX('Acomp. Equipe'!$A:$A,$L36)) | B36: =IF($L36="","",INDEX('Acomp. Equipe'!$C:$C,$L36)) | C36: =IF($L36="","",INDEX('Acomp. Equipe'!$D:$D,$L36)) | D36: =IF($L36="","",INDEX('Acomp. Equipe'!$E:$E,$L36)) | E36: =IF($L36="","",INDEX('Acomp. Equipe'!$G:$G,$L36)) | F36: =IF($L36="","",INDEX('Acomp. Equipe'!$K:$K,$L36)) | G36: =IF($L36="","",INDEX('Acomp. Equipe'!$N:$N,$L36)) | L36: =IFERROR(_xlfn.AGGREGATE(15,6,ROW('Acomp. Equipe'!$C$3:$C$296)/(('Acomp. Equipe'!$J$3:$J$296="Sim")*('Acomp. Equipe'!$F$3:$F$296<>"🟢 Concluído")),3),"")
A37: =IF($L37="","",INDEX('Acomp. Equipe'!$A:$A,$L37)) | B37: =IF($L37="","",INDEX('Acomp. Equipe'!$C:$C,$L37)) | C37: =IF($L37="","",INDEX('Acomp. Equipe'!$D:$D,$L37)) | D37: =IF($L37="","",INDEX('Acomp. Equipe'!$E:$E,$L37)) | E37: =IF($L37="","",INDEX('Acomp. Equipe'!$G:$G,$L37)) | F37: =IF($L37="","",INDEX('Acomp. Equipe'!$K:$K,$L37)) | G37: =IF($L37="","",INDEX('Acomp. Equipe'!$N:$N,$L37)) | L37: =IFERROR(_xlfn.AGGREGATE(15,6,ROW('Acomp. Equipe'!$C$3:$C$296)/(('Acomp. Equipe'!$J$3:$J$296="Sim")*('Acomp. Equipe'!$F$3:$F$296<>"🟢 Concluído")),4),"")
A38: =IF($L38="","",INDEX('Acomp. Equipe'!$A:$A,$L38)) | B38: =IF($L38="","",INDEX('Acomp. Equipe'!$C:$C,$L38)) | C38: =IF($L38="","",INDEX('Acomp. Equipe'!$D:$D,$L38)) | D38: =IF($L38="","",INDEX('Acomp. Equipe'!$E:$E,$L38)) | E38: =IF($L38="","",INDEX('Acomp. Equipe'!$G:$G,$L38)) | F38: =IF($L38="","",INDEX('Acomp. Equipe'!$K:$K,$L38)) | G38: =IF($L38="","",INDEX('Acomp. Equipe'!$N:$N,$L38)) | L38: =IFERROR(_xlfn.AGGREGATE(15,6,ROW('Acomp. Equipe'!$C$3:$C$296)/(('Acomp. Equipe'!$J$3:$J$296="Sim")*('Acomp. Equipe'!$F$3:$F$296<>"🟢 Concluído")),5),"")
A39: =IF($L39="","",INDEX('Acomp. Equipe'!$A:$A,$L39)) | B39: =IF($L39="","",INDEX('Acomp. Equipe'!$C:$C,$L39)) | C39: =IF($L39="","",INDEX('Acomp. Equipe'!$D:$D,$L39)) | D39: =IF($L39="","",INDEX('Acomp. Equipe'!$E:$E,$L39)) | E39: =IF($L39="","",INDEX('Acomp. Equipe'!$G:$G,$L39)) | F39: =IF($L39="","",INDEX('Acomp. Equipe'!$K:$K,$L39)) | G39: =IF($L39="","",INDEX('Acomp. Equipe'!$N:$N,$L39)) | L39: =IFERROR(_xlfn.AGGREGATE(15,6,ROW('Acomp. Equipe'!$C$3:$C$296)/(('Acomp. Equipe'!$J$3:$J$296="Sim")*('Acomp. Equipe'!$F$3:$F$296<>"🟢 Concluído")),6),"")
A40: =IF($L40="","",INDEX('Acomp. Equipe'!$A:$A,$L40)) | B40: =IF($L40="","",INDEX('Acomp. Equipe'!$C:$C,$L40)) | C40: =IF($L40="","",INDEX('Acomp. Equipe'!$D:$D,$L40)) | D40: =IF($L40="","",INDEX('Acomp. Equipe'!$E:$E,$L40)) | E40: =IF($L40="","",INDEX('Acomp. Equipe'!$G:$G,$L40)) | F40: =IF($L40="","",INDEX('Acomp. Equipe'!$K:$K,$L40)) | G40: =IF($L40="","",INDEX('Acomp. Equipe'!$N:$N,$L40)) | L40: =IFERROR(_xlfn.AGGREGATE(15,6,ROW('Acomp. Equipe'!$C$3:$C$296)/(('Acomp. Equipe'!$J$3:$J$296="Sim")*('Acomp. Equipe'!$F$3:$F$296<>"🟢 Concluído")),7),"")
A41: =IF($L41="","",INDEX('Acomp. Equipe'!$A:$A,$L41)) | B41: =IF($L41="","",INDEX('Acomp. Equipe'!$C:$C,$L41)) | C41: =IF($L41="","",INDEX('Acomp. Equipe'!$D:$D,$L41)) | D41: =IF($L41="","",INDEX('Acomp. Equipe'!$E:$E,$L41)) | E41: =IF($L41="","",INDEX('Acomp. Equipe'!$G:$G,$L41)) | F41: =IF($L41="","",INDEX('Acomp. Equipe'!$K:$K,$L41)) | G41: =IF($L41="","",INDEX('Acomp. Equipe'!$N:$N,$L41)) | L41: =IFERROR(_xlfn.AGGREGATE(15,6,ROW('Acomp. Equipe'!$C$3:$C$296)/(('Acomp. Equipe'!$J$3:$J$296="Sim")*('Acomp. Equipe'!$F$3:$F$296<>"🟢 Concluído")),8),"")
A43: 4. 🟡 EM ANDAMENTO / AGUARDANDO (com próximas entregas e previsão)
A44: Analista | B44: ID | C44: Projeto | D44: Atividade | E44: Próximo Passo | F44: Previsão | G44: Evolução | H44: Semanas
A45: =IF($L45="","",INDEX('Acomp. Equipe'!$A:$A,$L45)) -> Filipe Messias | B45: =IF($L45="","",INDEX('Acomp. Equipe'!$C:$C,$L45)) -> FM-0006 | C45: =IF($L45="","",INDEX('Acomp. Equipe'!$D:$D,$L45)) -> Rotina Fiscal/Contábil | D45: =IF($L45="","",INDEX('Acomp. Equipe'!$E:$E,$L45)) -> Conversor PDF para Excel de notas fiscais | E45: =IF($L45="","",INDEX('Acomp. Equipe'!$I:$I,$L45)) -> Enviar amostra à área fiscal | F45: =IF($L45="","",INDEX('Acomp. Equipe'!$L:$L,$L45)) -> 46213 | G45: =IF($L45="","",INDEX('Acomp. Equipe'!$M:$M,$L45)) -> 0.8 | H45: =IF($L45="","",INDEX('Acomp. Equipe'!$N:$N,$L45)) -> 2 | L45: =IFERROR(_xlfn.AGGREGATE(15,6,ROW('Acomp. Equipe'!$C$3:$C$296)/((('Acomp. Equipe'!$F$3:$F$296="🟡 Em andamento")+('Acomp. Equipe'!$F$3:$F$296="⏸ Aguardando Terceiros")+('Acomp. Equipe'!$F$3:$F$296="⚪ Não iniciado"))),1),"") -> 3
...

Sheet Indicadores
A1: INDICADORES EXECUTIVOS v3.4
A2: Calculados automaticamente a partir da Base Gerencial
A4: 1. TORRE FINANCEIRA — CSC (visão consolidada)
A5: Total de atividades (entregas, sem apoios) | B5: =COUNTIFS('Base Gerencial'!$J$2:$J$2000,"<>",'Base Gerencial'!$O$2:$O$2000,"<>Apoio") -> 8
A6: Concluídas | B6: =COUNTIFS('Base Gerencial'!$S$2:$S$2000,"Concluído",'Base Gerencial'!$O$2:$O$2000,"<>Apoio") -> 4
A7: Em andamento | B7: =COUNTIFS('Base Gerencial'!$S$2:$S$2000,"Em andamento",'Base Gerencial'!$O$2:$O$2000,"<>Apoio") -> 0
A8: Atividades em parceria (2+ pessoas) | B8: =COUNTIFS('Base Gerencial'!$N$2:$N$2000,"Sim",'Base Gerencial'!$O$2:$O$2000,"<>Apoio") -> 1
A9: Linhas de apoio (colaboração) | B9: =COUNTIF('Base Gerencial'!$O$2:$O$2000,"Apoio") -> 0
A10: Horas gastas pela equipe (inclui apoios) | B10: =SUM('Base Gerencial'!$T$2:$T$2000) -> 80
A11: Ganho de produtividade (h/mês) | B11: =SUM('Base Gerencial'!$W$2:$W$2000) -> 149.8
A12: Ganho anualizado (h/ano) | B12: =SUM('Base Gerencial'!$W$2:$W$2000)*12 -> 1797.6
A13: Economia estimada (R$) — quando aplicável | B13: =SUM('Base Gerencial'!$AH$2:$AH$2000) -> 8500
A14: Pessoas impactadas | B14: =SUM('Base Gerencial'!$AG$2:$AG$2000) -> 41
A15: Destaques do mês (Destaque = Sim) | B15: =COUNTIF('Base Gerencial'!$AJ$2:$AJ$2000,"Sim") -> 4
A16: IDs duplicados (controle de consolidação — deve ser 0) | B16: =SUMPRODUCT(--(COUNTIF('Base Gerencial'!$B$2:$B$2000,'Base Gerencial'!$B$2:$B$2000)>1),--('Base Gerencial'!$B$2:$B$2000<>"")) -> 0
A18: 2. GANHOS DE PRODUTIVIDADE (antes x depois dos processos melhorados)
A19: Tempo dos processos ANTES (h/mês) | B19: =SUM('Base Gerencial'!$U$2:$U$2000) -> 166
A20: Tempo dos processos DEPOIS (h/mês) | B20: =SUM('Base Gerencial'!$V$2:$V$2000) -> 16.2
A21: Ganho mensal (h/mês) | B21: =SUM('Base Gerencial'!$U$2:$U$2000)-SUM('Base Gerencial'!$V$2:$V$2000) -> 149.8
A22: Ganho anualizado (h/ano) | B22: =(SUM('Base Gerencial'!$U$2:$U$2000)-SUM('Base Gerencial'!$V$2:$V$2000))*12 -> 1797.6
A23: % de redução média (ponderada) | B23: =IF(SUM('Base Gerencial'!$U$2:$U$2000)>0,(SUM('Base Gerencial'!$U$2:$U$2000)-SUM('Base Gerencial'!$V$2:$V$2000))/SUM('Base Gerencial'!$U$2:$U$2000),0) -> 0.90240964
A24: Processos com ganho medido | B24: =COUNTIFS('Base Gerencial'!$U$2:$U$2000,">0",'Base Gerencial'!$O$2:$O$2000,"<>Apoio") -> 5
A26: 3. PRODUÇÃO POR ANALISTA (consolidação das 4 planilhas)
A27: Analista | B27: Entregas | C27: Concluídas | D27: Horas | E27: Ganho (h/mês) | F27: Apoios
A28: José Victor (JV) | B28: =COUNTIFS('Base Gerencial'!$A$2:$A$2000,"José Victor",'Base Gerencial'!$O$2:$O$2000,"<>Apoio") -> 0 | C28: =COUNTIFS('Base Gerencial'!$A$2:$A$2000,"José Victor",'Base Gerencial'!$S$2:$S$2000,"Concluído",'Base Gerencial'!$O$2:$O$2000,"<>Apoio") -> 0 | D28: =SUMIFS('Base Gerencial'!$T$2:$T$2000,'Base Gerencial'!$A$2:$A$2000,"José Victor") -> 0 | E28: =SUMIFS('Base Gerencial'!$W$2:$W$2000,'Base Gerencial'!$A$2:$A$2000,"José Victor") -> 0 | F28: =COUNTIFS('Base Gerencial'!$A$2:$A$2000,"José Victor",'Base Gerencial'!$O$2:$O$2000,"Apoio") -> 0
A29: Viviane Lima (VL) | B29: =COUNTIFS('Base Gerencial'!$A$2:$A$2000,"Viviane Lima",'Base Gerencial'!$O$2:$O$2000,"<>Apoio") -> 0 | C29: =COUNTIFS('Base Gerencial'!$A$2:$A$2000,"Viviane Lima",'Base Gerencial'!$S$2:$S$2000,"Concluído",'Base Gerencial'!$O$2:$O$2000,"<>Apoio") -> 0 | D29: =SUMIFS('Base Gerencial'!$T$2:$T$2000,'Base Gerencial'!$A$2:$A$2000,"Viviane Lima") -> 0 | E29: =SUMIFS('Base Gerencial'!$W$2:$W$2000,'Base Gerencial'!$A$2:$A$2000,"Viviane Lima") -> 0 | F29: =COUNTIFS('Base Gerencial'!$A$2:$A$2000,"Viviane Lima",'Base Gerencial'!$O$2:$O$2000,"Apoio") -> 0
A30: Juliana Santos (JS) | B30: =COUNTIFS('Base Gerencial'!$A$2:$A$2000,"Juliana Santos",'Base Gerencial'!$O$2:$O$2000,"<>Apoio") -> 0 | C30: =COUNTIFS('Base Gerencial'!$A$2:$A$2000,"Juliana Santos",'Base Gerencial'!$S$2:$S$2000,"Concluído",'Base Gerencial'!$O$2:$O$2000,"<>Apoio") -> 0 | D30: =SUMIFS('Base Gerencial'!$T$2:$T$2000,'Base Gerencial'!$A$2:$A$2000,"Juliana Santos") -> 0 | E30: =SUMIFS('Base Gerencial'!$W$2:$W$2000,'Base Gerencial'!$A$2:$A$2000,"Juliana Santos") -> 0 | F30: =COUNTIFS('Base Gerencial'!$A$2:$A$2000,"Juliana Santos",'Base Gerencial'!$O$2:$O$2000,"Apoio") -> 0
A31: Filipe Messias (FM) | B31: =COUNTIFS('Base Gerencial'!$A$2:$A$2000,"Filipe Messias",'Base Gerencial'!$O$2:$O$2000,"<>Apoio") -> 8 | C31: =COUNTIFS('Base Gerencial'!$A$2:$A$2000,"Filipe Messias",'Base Gerencial'!$S$2:$S$2000,"Concluído",'Base Gerencial'!$O$2:$O$2000,"<>Apoio") -> 4 | D31: =SUMIFS('Base Gerencial'!$T$2:$T$2000,'Base Gerencial'!$A$2:$A$2000,"Filipe Messias") -> 80 | E31: =SUMIFS('Base Gerencial'!$W$2:$W$2000,'Base Gerencial'!$A$2:$A$2000,"Filipe Messias") -> 149.8 | F31: =COUNTIFS('Base Gerencial'!$A$2:$A$2000,"Filipe Messias",'Base Gerencial'!$O$2:$O$2000,"Apoio") -> 0
A33: 4. PROCESSOS INTEGRADOS — POR PILAR
A34: Item | B34: Total | C34: Concluídas | D34: Horas | E34: Ganho (h/mês)
A35: Governança | B35: =COUNTIFS('Base Gerencial'!$H$2:$H$2000,$A35,'Base Gerencial'!$O$2:$O$2000,"<>Apoio") -> 1 | C35: =COUNTIFS('Base Gerencial'!$H$2:$H$2000,$A35,'Base Gerencial'!$S$2:$S$2000,"Concluído",'Base Gerencial'!$O$2:$O$2000,"<>Apoio") -> 0 | D35: =SUMIFS('Base Gerencial'!$T$2:$T$2000,'Base Gerencial'!$H$2:$H$2000,$A35) -> 8 | E35: =SUMIFS('Base Gerencial'!$W$2:$W$2000,'Base Gerencial'!$H$2:$H$2000,$A35) -> 0
A36: Melhoria Contínua | B36: =COUNTIFS('Base Gerencial'!$H$2:$H$2000,$A36,'Base Gerencial'!$O$2:$O$2000,"<>Apoio") -> 1 | C36: =COUNTIFS('Base Gerencial'!$H$2:$H$2000,$A36,'Base Gerencial'!$S$2:$S$2000,"Concluído",'Base Gerencial'!$O$2:$O$2000,"<>Apoio") -> 0 | D36: =SUMIFS('Base Gerencial'!$T$2:$T$2000,'Base Gerencial'!$H$2:$H$2000,$A36) -> 0 | E36: =SUMIFS('Base Gerencial'!$W$2:$W$2000,'Base Gerencial'!$H$2:$H$2000,$A36) -> 0
A37: Transformação Digital | B37: =COUNTIFS('Base Gerencial'!$H$2:$H$2000,$A37,'Base Gerencial'!$O$2:$O$2000,"<>Apoio") -> 5 | C37: =COUNTIFS('Base Gerencial'!$H$2:$H$2000,$A37,'Base Gerencial'!$S$2:$S$2000,"Concluído",'Base Gerencial'!$O$2:$O$2000,"<>Apoio") -> 3 | D37: =SUMIFS('Base Gerencial'!$T$2:$T$2000,'Base Gerencial'!$H$2:$H$2000,$A37) -> 48 | E37: =SUMIFS('Base Gerencial'!$W$2:$W$2000,'Base Gerencial'!$H$2:$H$2000,$A37) -> 135.8
A38: Business Intelligence | B38: =COUNTIFS('Base Gerencial'!$H$2:$H$2000,$A38,'Base Gerencial'!$O$2:$O$2000,"<>Apoio") -> 1 | C38: =COUNTIFS('Base Gerencial'!$H$2:$H$2000,$A38,'Base Gerencial'!$S$2:$S$2000,"Concluído",'Base Gerencial'!$O$2:$O$2000,"<>Apoio") -> 1 | D38: =SUMIFS('Base Gerencial'!$T$2:$T$2000,'Base Gerencial'!$H$2:$H$2000,$A38) -> 24 | E38: =SUMIFS('Base Gerencial'!$W$2:$W$2000,'Base Gerencial'!$H$2:$H$2000,$A38) -> 14
A39: PMO / Projetos | B39: =COUNTIFS('Base Gerencial'!$H$2:$H$2000,$A39,'Base Gerencial'!$O$2:$O$2000,"<>Apoio") -> 0 | C39: =COUNTIFS('Base Gerencial'!$H$2:$H$2000,$A39,'Base Gerencial'!$S$2:$S$2000,"Concluído",'Base Gerencial'!$O$2:$O$2000,"<>Apoio") -> 0 | D39: =SUMIFS('Base Gerencial'!$T$2:$T$2000,'Base Gerencial'!$H$2:$H$2000,$A39) -> 0 | E39: =SUMIFS('Base Gerencial'!$W$2:$W$2000,'Base Gerencial'!$H$2:$H$2000,$A39) -> 0
A40: Operação (Rotina) | B40: =COUNTIFS('Base Gerencial'!$H$2:$H$2000,$A40,'Base Gerencial'!$O$2:$O$2000,"<>Apoio") -> 0 | C40: =COUNTIFS('Base Gerencial'!$H$2:$H$2000,$A40,'Base Gerencial'!$S$2:$S$2000,"Concluído",'Base Gerencial'!$O$2:$O$2000,"<>Apoio") -> 0 | D40: =SUMIFS('Base Gerencial'!$T$2:$T$2000,'Base Gerencial'!$H$2:$H$2000,$A40) -> 0 | E40: =SUMIFS('Base Gerencial'!$W$2:$W$2000,'Base Gerencial'!$H$2:$H$2000,$A40) -> 0
A42: 5. ENTREGAS DO MÊS (por tipo de demanda)
A43: Pilar | B43: Tipo de Demanda | C43: Total | D43: Concluídas
A44: Governança | B44: POP elaborado/atualizado | C44: =COUNTIFS('Base Gerencial'!$I$2:$I$2000,$B44,'Base Gerencial'!$O$2:$O$2000,"<>Apoio") -> 0 | D44: =COUNTIFS('Base Gerencial'!$I$2:$I$2000,$B44,'Base Gerencial'!$S$2:$S$2000,"Concluído",'Base Gerencial'!$O$2:$O$2000,"<>Apoio") -> 0
A45: Governança | B45: Fluxograma (AS-IS/TO-BE) | C45: =COUNTIFS('Base Gerencial'!$I$2:$I$2000,$B45,'Base Gerencial'!$O$2:$O$2000,"<>Apoio") -> 0 | D45: =COUNTIFS('Base Gerencial'!$I$2:$I$2000,$B45,'Base Gerencial'!$S$2:$S$2000,"Concluído",'Base Gerencial'!$O$2:$O$2000,"<>Apoio") -> 0
...

Sheet Report
A1: RELATÓRIO EXECUTIVO MENSAL
A3: Planejamento de Entregas e Inovação Operacional — Processos Integrados (Depto. E) · Torre Financeira CSC
A5: Mês de Referência:
A6: Responsável:
A7: Supervisora: | B7: Juliana Batista
A8: Versão:
A9: Data de Emissão:
A11: 1. MENSAGEM EXECUTIVA
A12: (Resumo do mês: principais entregas e resultados alcançados, ganhos de produtividade, riscos, projetos em destaque. Use a coluna "Resultado Alcançado" das linhas com Destaque = Sim.)
A19: 2. DASHBOARD EXECUTIVO
A20: Total de atividades | B20: =Indicadores!B5 -> 8
A21: Concluídas | B21: =Indicadores!B6 -> 4
A22: Horas gastas pela equipe | B22: =Indicadores!B10 -> 80
A23: Ganho de produtividade (h/mês) | B23: =Indicadores!B11 -> 149.8
A24: Ganho anualizado (h/ano) | B24: =Indicadores!B12 -> 1797.6
A25: Economia estimada (R$) | B25: =Indicadores!B13 -> 8500
A26: Pessoas impactadas | B26: =Indicadores!B14 -> 41
A27: Atividades em parceria | B27: =Indicadores!B8 -> 1
A28: Destaques do mês | B28: =Indicadores!B15 -> 4
A30: 3. GANHOS DE PRODUTIVIDADE — ANTES x DEPOIS
A31: Tempo dos processos ANTES (h/mês) | B31: =Indicadores!B19 -> 166
A32: Tempo dos processos DEPOIS (h/mês) | B32: =Indicadores!B20 -> 16.2
A33: Ganho mensal (h/mês) | B33: =Indicadores!B21 -> 149.8
A34: Ganho anualizado (h/ano) | B34: =Indicadores!B22 -> 1797.6
A35: % de redução média | B35: =Indicadores!B23 -> 0.90240964
A36: Processos com ganho medido | B36: =Indicadores!B24 -> 5
A38: 4. PRODUÇÃO POR ANALISTA
A39: Analista | B39: Entregas | C39: Concluídas | D39: Horas | E39: Ganho (h/mês) | F39: Apoios
A40: =Indicadores!A28 -> José Victor (JV) | B40: =Indicadores!B28 -> 0 | C40: =Indicadores!C28 -> 0 | D40: =Indicadores!D28 -> 0 | E40: =Indicadores!E28 -> 0 | F40: =Indicadores!F28 -> 0
A41: =Indicadores!A29 -> Viviane Lima (VL) | B41: =Indicadores!B29 -> 0 | C41: =Indicadores!C29 -> 0 | D41: =Indicadores!D29 -> 0 | E41: =Indicadores!E29 -> 0 | F41: =Indicadores!F29 -> 0
A42: =Indicadores!A30 -> Juliana Santos (JS) | B42: =Indicadores!B30 -> 0 | C42: =Indicadores!C30 -> 0 | D42: =Indicadores!D30 -> 0 | E42: =Indicadores!E30 -> 0 | F42: =Indicadores!F30 -> 0
A43: =Indicadores!A31 -> Filipe Messias (FM) | B43: =Indicadores!B31 -> 8 | C43: =Indicadores!C31 -> 4 | D43: =Indicadores!D31 -> 80 | E43: =Indicadores!E31 -> 149.8 | F43: =Indicadores!F31 -> 0
A45: 5. PROCESSOS INTEGRADOS — POR PILAR
A46: Pilar | B46: Total | C46: Concluídas | D46: Horas | E46: Ganho (h/mês)
A47: =Indicadores!A35 -> Governança | B47: =Indicadores!B35 -> 1 | C47: =Indicadores!C35 -> 0 | D47: =Indicadores!D35 -> 8 | E47: =Indicadores!E35 -> 0
A48: =Indicadores!A36 -> Melhoria Contínua | B48: =Indicadores!B36 -> 1 | C48: =Indicadores!C36 -> 0 | D48: =Indicadores!D36 -> 0 | E48: =Indicadores!E36 -> 0
A49: =Indicadores!A37 -> Transformação Digital | B49: =Indicadores!B37 -> 5 | C49: =Indicadores!C37 -> 3 | D49: =Indicadores!D37 -> 48 | E49: =Indicadores!E37 -> 135.8
A50: =Indicadores!A38 -> Business Intelligence | B50: =Indicadores!B38 -> 1 | C50: =Indicadores!C38 -> 1 | D50: =Indicadores!D38 -> 24 | E50: =Indicadores!E38 -> 14
A51: =Indicadores!A39 -> PMO / Projetos | B51: =Indicadores!B39 -> 0 | C51: =Indicadores!C39 -> 0 | D51: =Indicadores!D39 -> 0 | E51: =Indicadores!E39 -> 0
A52: =Indicadores!A40 -> Operação (Rotina) | B52: =Indicadores!B40 -> 0 | C52: =Indicadores!C40 -> 0 | D52: =Indicadores!D40 -> 0 | E52: =Indicadores!E40 -> 0
...

Sheet Cadastros
A1: CADASTROS MESTRES v3.4
A2: Fonte única das listas suspensas — alterar somente aqui e replicar nas planilhas dos analistas
A4: Projetos | B4: Departamentos | C4: Status | D4: Empresa | E4: Prioridade | F4: Complexidade | G4: Impacto | H4: Categoria de Benefício | I4: Sim/Não | J4: Pilar Proc. Integrados | K4: Departamentos CSC | L4: Papel na Atividade | M4: Equipe Proc. Integrados | N4: Status da Semana | O4: Motivo do Status | P4: Categoria de Impedimento | Q4: Avaliação (Desempenho) | R4: Avaliação (Prazo) | S4: Radar | U4: Projeto (mapa) | V4: Range Temas | X4: Pilar (mapa) | Y4: Range Tipos | AA4: Depto CSC (mapa) | AB4: Range Pessoas | AD4: Lumen | AE4: V360 | AF4: Saneamento Base Contábil | AG4: Newsletter | AH4: Rotina Fiscal/Contábil | AI4: Rotina Financeiro | AJ4: Investidas | AK4: Actio | AL4: Indicadores e Metas | AN4: Governança | AO4: Melhoria Contínua | AP4: Transformação Digital | AQ4: Business Intelligence | AR4: PMO / Projetos | AS4: Operação (Rotina) | AU4: Contas a Receber | AV4: Tesouraria | AW4: Auditoria Financeira CSC | AX4: Recebimento Fiscal | AY4: Processos Integrados | AZ4: Cartão Corporativo | BA4: Tributos Federais | BB4: Tributos Estaduais | BC4: Contabilidade | BD4: Faturamento | BE4: CSC Corporativo | BF4: Gestão
A5: Lumen | B5: Torre Financeira - CSC | C5: Não iniciado | D5: ELET | E5: Alta | F5: Alta | G5: Alto | H5: Tempo | I5: Sim | J5: Governança | K5: Contas a Receber | L5: Responsável | M5: José Victor | N5: 🟢 Concluído | O5: Em desenvolvimento | P5: Dependência de outra área | Q5: Excelente | R5: No prazo | S5: 🟢 Verde | U5: Lumen | V5: TemaLumen | X5: Governança | Y5: EntGov | AA5: Contas a Receber | AB5: Pes01 | AD5: PIS/COFINS | AE5: Dashboard de Produtividade | AF5: Adiantamento de Fornecedores | AG5: M01 - Normas Gerais da Tributação do Consumo | AH5: EFD ICMS/IPI | AI5: Pagamentos a Fornecedores | AJ5: Geral | AK5: Geral | AL5: Geral | AN5: POP elaborado/atualizado | AO5: Gargalo eliminado | AP5: Automação | AQ5: Dashboard | AR5: Projeto/Sprint gerenciado | AS5: Obrigação Acessória | AU5: Viviane Monteiro (Supervisora) | AV5: Erica Arcoverde (Supervisora) | AW5: Gabriela Cavalcanti (Supervisora) | AX5: Adriana Albuquerque (Supervisora) | AY5: Juliana Batista (Supervisora) | AZ5: Lucia Helena (Supervisora) | BA5: Emerson Pontes (Supervisor) | BB5: Yuri Medeiros (Técnico) | BC5: Magnum Brandão (Técnico) | BD5: Emerson Pontes (Técnico) | BE5: Jan Carlos | BF5: Rone Ferreira (Gerente)
A6: V360 | B6: Fiscal/Contábil | C6: Em andamento | D6: CHESF | E6: Média | F6: Média | G6: Médio | H6: Financeiro | I6: Não | J6: Melhoria Contínua | K6: Tesouraria | L6: Apoio | M6: Viviane Lima | N6: 🟡 Em andamento | O6: Aguardando usuário | P6: TI / Sistema | Q6: Boa | R6: Em risco | S6: 🟡 Atenção | U6: V360 | V6: TemaV360 | X6: Melhoria Contínua | Y6: EntMC | AA6: Tesouraria | AB6: Pes02 | AD6: ISS | AE6: Dashboard Entrada de NF - SAP x V360 | AF6: Adiantamento de Clientes | AG6: M02 - Comércio Internacional | AH6: EFD Contribuições | AI6: Pagamento de Tributos (DARF/GPS) | AJ6: Obrigações Acessórias | AK6: Cadastro de Indicadores | AL6: KPI/Indicador | AN6: Fluxograma (AS-IS/TO-BE) | AO6: Processo revisado/simplificado | AP6: Agente de IA | AQ6: KPI/Indicador publicado | AR6: Cronograma/Roadmap | AS6: Pagamento/Tesouraria | AU6: Adriana Martins | AV6: Aline Neves | AW6: Ana Lucia Ferreira | AX6: Altanira Carla | AY6: José Victor | AZ6: Izabella Paz | BA6: Danilo Oliveira | BB6: Lucas de Albuquerque | BC6: Deyvison de Lima | BD6: Ridley Renan | BE6: Manoel Cariele | BF6: Angela Ritchie (Coordenadora)
A7: Saneamento Base Contábil | B7: Financeiro | C7: Em validação | D7: ENOR | E7: Baixa | F7: Baixa | G7: Baixo | H7: Qualidade | J7: Transformação Digital | K7: Auditoria Financeira CSC | M7: Juliana Santos | N7: 🔴 Bloqueado | O7: Aguardando gestor | P7: Fornecedor | Q7: Regular | R7: Atrasado | S7: 🔴 Crítico | U7: Saneamento Base Contábil | V7: TemaSaneamento | X7: Transformação Digital | Y7: EntTD | AA7: Auditoria Financeira CSC | AB7: Pes03 | AD7: Diretos | AE7: Dashboard Entrada de NF - TicketLog x V360 | AF7: PIS e COFINS a Recuperar | AG7: M03 - FCBF - ICMS | AH7: ECD | AI7: Contas de Concessionárias | AJ7: Apurações | AK7: Planos de Ação | AL7: Meta | AN7: Política/Norma | AO7: Redução de etapas | AP7: Portal/Sistema Web | AQ7: Relatório Analítico | AR7: Workshop/Treinamento | AS7: Conciliação | AU7: Amanda Ferraz | AV7: Carlos Samuel | AW7: Rafaela Seabra | AX7: Ana Palheta | AY7: Viviane Lima | AZ7: Adriana Marinho | BA7: Emerson dos Santos | BB7: Amélia Gabriel | BC7: Rafael Lucio | BD7: Larisa Leal | BE7: Laura Santana | BF7: Phillippe de Sá (Coordenador)
A8: Newsletter | C8: Concluído | D8: ESUL | H8: Operação | J8: Business Intelligence | K8: Recebimento Fiscal | M8: Filipe Messias | N8: ⏸ Aguardando Terceiros | O8: Aguardando TI | P8: Licença / Acesso | Q8: Ruim | U8: Newsletter | V8: TemaNewsletter | X8: Business Intelligence | Y8: EntBI | AA8: Recebimento Fiscal | AB8: Pes04 | AD8: Retidos | AG8: M04 - Cadastro | AH8: ECF | AI8: Conciliações Financeiras | AJ8: Suporte Contábil/Fiscal | AK8: Acompanhamento de Metas | AL8: Dashboard | AN8: Indicador definido | AO8: Padronização implantada | AP8: Integração (SAP/API) | AQ8: Base de Dados estruturada | AR8: Gestão de Mudança | AS8: Análise/Parecer | AU8: Ana Carla | AV8: Denise Maria | AW8: Guilardo Souza | AX8: Alynna Pereira | AY8: Juliana Santos | AZ8: Cintia Bernardino | BA8: Maria Estela | BB8: Flavius de Oliveira | BC8: José Paulo Farias | BD8: Jonnathan dos Santos | BE8: Ademilson Jerônimo | BF8: Diogo Calado (Especialista Tributário)
A9: Rotina Fiscal/Contábil | C9: Aguardando terceiros | D9: Todas | H9: Compliance | J9: PMO / Projetos | K9: Processos Integrados | M9: Juliana Batista (Supervisora) | N9: ⚪ Não iniciado | O9: Aguardando fornecedor | P9: Aprovação | U9: Rotina Fiscal/Contábil | V9: TemaRotinaFC | X9: PMO / Projetos | Y9: EntPMO | AA9: Processos Integrados | AB9: Pes05 | AD9: ICMS | AG9: M05 - Obrigações Acessórias | AH9: DCTFWeb | AI9: Melhorias e Automações | AJ9: Análises | AK9: Relatórios | AL9: Relatório Gerencial | AN9: Documentação/Manual | AO9: Kaizen/Lean | AP9: OCR/Processamento de Documentos | AS9: Apuração de Tributos | AU9: Ana Manuela | AV9: Diego Maciel | AW9: Ana Cartaxo | AX9: Cassyo Cleyson | AY9: Filipe Messias | AZ9: Lea Carolina | BA9: Roberto Cavalcante | BB9: Diogo Santos | BC9: Roberta Neves | BD9: Thiago da Silva
A10: Rotina Financeiro | C10: Cancelado | D10: Outra | H10: Tecnologia | J10: Operação (Rotina) | K10: Cartão Corporativo | O10: Aguardando outra área | P10: Cliente / Usuário | U10: Rotina Financeiro | V10: TemaRotinaFin | X10: Operação (Rotina) | Y10: EntOper | AA10: Cartão Corporativo | AB10: Pes06 | AD10: Obrig. Estaduais - DAMEF-MG / DAPI-MG / DECLAN-RJ | AG10: M06 - Apuração Assistida | AH10: DIRBI | AI10: Relatórios e KPIs | AJ10: Outros | AK10: Outros | AL10: Outros | AN10: Publicação/Conteúdo Técnico | AP10: Script/Macro | AS10: Suporte/Atendimento | AU10: Dâmaris de Santana | AV10: Elaine Santana | AW10: Maria Aparecida | AX10: Emanuelle Monteiro | AZ10: Beatriz Rosseti | BA10: Roseli Marinho | BB10: Amanda C. da Silva | BC10: Vinicius Pinheiro | BD10: Bruno Santos
A11: Investidas | D11: N/A | H11: Pessoas | K11: Tributos Federais | O11: Em homologação | P11: Outro | U11: Investidas | V11: TemaInvestidas | AA11: Tributos Federais | AB11: Pes07 | AD11: Obrig. Estaduais - DCIP-SC / DIME-SC / DIF-TO / DOT-ES | AG11: M07 - Compensação, Ressarcimento e Restituição | AH11: EFD-Reinf | AI11: Outros | AS11: Correção/Retificação | AU11: Eneias Matias | AV11: John Williams | AW11: Ranata Calumbi | AX11: Erick Melo | AZ11: Augusto Ildefonso | BA11: Luisa Arruda | BB11: Rodrigo de Albuquerque | BC11: Sergio Melo Filho | BD11: Arthur Tavares
A12: Actio | K12: Tributos Estaduais | O12: Em validação | U12: Actio | V12: TemaActio | AA12: Tributos Estaduais | AB12: Pes08 | AD12: Obrig. Estaduais - GIA-ST / DIFAL / ICMS Simples Nacional | AG12: M08 - Simples Nacional e MEI | AH12: eSocial | AU12: Ludimille Amaral | AV12: Elma de Andrade | AX12: Fernanda Ximenes | AZ12: Sintia Oliveira | BA12: Giselly Alves | BB12: Kellner Leal | BC12: Angela Maria Silva | BD12: João Fortunato
A13: Indicadores e Metas | K13: Contabilidade | O13: Ajustes identificados | U13: Indicadores e Metas | V13: TemaIndMetas | AA13: Contabilidade | AB13: Pes09 | AD13: GNRE / CIAP | AG13: M09 - Economia Digital | AH13: Apurações | AU13: Juliana Albuquerque | AV13: Willams Martins | AX13: Geovanni Paiva | BA13: João Brito | BB13: Isaac Kesseler | BC13: Romullo Nascimento
K14: Faturamento | O14: Concluído | AA14: Faturamento | AB14: Pes10 | AD14: Notas Fiscais (Entradas/Saídas, Correções, Inconformidades) | AG14: M10 - Regimes Diferenciados e Específicos | AH14: Conciliações Contábeis | AU14: Priscilla Negrão | AV14: Paloma Mendes | AX14: Pholyana Katy | BA14: Janice de Lima | BB14: Aline Tavares | BC14: Mylena Silva
K15: CSC Corporativo | AA15: CSC Corporativo | AB15: Pes11 | AD15: CDC / CFC / MCX | AG15: M11 - Planos de Saúde e Prognósticos | AH15: Outros | AU15: Lana Barros | AV15: Natália Rocha | AX15: Terezinha Santos | BA15: Janaina Nascimento | BB15: Rafael Cunha | BC15: Luiz Claudio da Silva
K16: Gestão | AA16: Gestão | AB16: Pes12 | AD16: Calendário e Dashboards Fiscais / PGTC | AG16: M12 - Serviços Financeiros | AV16: Nadja Buarque | AX16: Mylene Lira | BA16: Gleicy Gomes | BC16: Lucas Bernardo
AD17: ECD - SPED Contábil / Balancete, Razão e Diário | AG17: M13 - Bens Imóveis | AV17: Silvia Helena | AX17: Fernando Calado | BA17: Daiane Vicente
AD18: Sintegra / 3P2M | AG18: M14 - Agronegócio e Cooperativismo | AV18: Fernando Bruno | AX18: Maria Helena | BA18: Luana de Oliveira
AG19: M15 - ZFM e ALC | AX19: Roger Melo
AG20: M16 - Combustíveis e Energia Elétrica | AX20: Thaynara Ávila
AG21: M17 - Imposto Seletivo | AX21: Josuellington Costa
AG22: M18 - Temas Complementares e Casos Práticos | AX22: Ítalo Henrique
AX23: Tiago Pereira
AX24: Wialy Marlan
AX25: Maria Eduarda
A40: REGRA DE ID ÚNICO — PREFIXOS POR ANALISTA
A41: Analista | B41: Prefixo
A42: José Victor | B42: JV
A43: Viviane Lima | B43: VL
A44: Juliana Santos | B44: JS
A45: Filipe Messias | B45: FM
A46: Juliana Batista (Supervisora) | B46: JB
A47: Cada analista usa exclusivamente o seu prefixo. O ID é gerado automaticamente (PREFIXO-0001, PREFIXO-0002...), portanto nunca haverá repetição entre as planilhas da equipe.
