Workbook
Name AvalDesemp: Cadastros!$Q$5:$Q$8
Name AvalPrazo: Cadastros!$R$5:$R$7
Name Beneficios: Cadastros!$H$5:$H$11
Name CategoriasImped: Cadastros!$P$5:$P$11
Name Complexidades: Cadastros!$F$5:$F$7
Name Departamentos: Cadastros!$B$5:$B$7
Name DeptosCSC: Cadastros!$K$5:$K$16
Name Empresas: Cadastros!$D$5:$D$11
Name EntBI: Cadastros!$AQ$5:$AQ$8
Name EntGov: Cadastros!$AN$5:$AN$10
Name EntMC: Cadastros!$AO$5:$AO$9
Name EntOper: Cadastros!$AS$5:$AS$11
Name EntPMO: Cadastros!$AR$5:$AR$8
Name EntTD: Cadastros!$AP$5:$AP$10
Name EquipePI: Cadastros!$M$5:$M$9
Name Impactos: Cadastros!$G$5:$G$7
Name MapaEnt: Cadastros!$X$5:$Y$10
Name MapaPessoas: Cadastros!$AA$5:$AB$16
Name MapaTemas: Cadastros!$U$5:$V$13
Name MotivoStatus: Cadastros!$O$5:$O$14
Name Papeis: Cadastros!$L$5:$L$6
Name Pes01: Cadastros!$AU$5:$AU$15
Name Pes02: Cadastros!$AV$5:$AV$18
Name Pes03: Cadastros!$AW$5:$AW$11
Name Pes04: Cadastros!$AX$5:$AX$25
Name Pes05: Cadastros!$AY$5:$AY$9
Name Pes06: Cadastros!$AZ$5:$AZ$12
Name Pes07: Cadastros!$BA$5:$BA$18
Name Pes08: Cadastros!$BB$5:$BB$15
Name Pes09: Cadastros!$BC$5:$BC$16
Name Pes10: Cadastros!$BD$5:$BD$12
Name Pes11: Cadastros!$BE$5:$BE$8
Name Pes12: Cadastros!$BF$5:$BF$8
Name Pilares: Cadastros!$J$5:$J$10
Name Prefixo: 'Leia-me'!$B$22
Name Prioridades: Cadastros!$E$5:$E$7
Name Projetos: Cadastros!$A$5:$A$13
Name RadarCor: Cadastros!$S$5:$S$7
Name SimNao: Cadastros!$I$5:$I$6
Name StatusList: Cadastros!$C$5:$C$10
Name StatusSemana: Cadastros!$N$5:$N$9
Name TemaActio: Cadastros!$AK$5:$AK$10
Name TemaIndMetas: Cadastros!$AL$5:$AL$10
Name TemaInvestidas: Cadastros!$AJ$5:$AJ$10
Name TemaLumen: Cadastros!$AD$5:$AD$18
Name TemaNewsletter: Cadastros!$AG$5:$AG$22
Name TemaRotinaFC: Cadastros!$AH$5:$AH$15
Name TemaRotinaFin: Cadastros!$AI$5:$AI$11
Name TemaSaneamento: Cadastros!$AF$5:$AF$7
Name TemaV360: Cadastros!$AE$5:$AE$7

Sheet Leia-me
A1: PLANILHA DO ANALISTA v3.4 — JULIANA SANTOS
A2: Torre Financeira CSC · Departamento E — Processos Integrados · Supervisora: Juliana Batista
A4: Como usar esta planilha
A5: 1. Este arquivo pertence a Juliana Santos (Departamento E — Processos Integrados). Salve como: Analista_JS_Juliana.xlsx.
A6: 2. Uma linha = uma atividade/entrega, na aba "Lançamentos". Preencha da esquerda para a direita.
A7: 3. ID ÚNICO: seu prefixo exclusivo é "JS". O ID é gerado sozinho (JS-0001, JS-0002...). NUNCA altere o prefixo nem digite IDs manualmente — é ele que garante que nenhum ID se repita entre os 4 analistas na consolidação da Juliana.
A8: 4. NÃO EXCLUA linhas já lançadas (isso renumeraria os IDs). Se uma atividade for descartada, use Status = Cancelado.
A9: 5. Listas dependentes: escolha o Projeto antes do Tema, o Pilar antes do Tipo de Demanda, e o Depto. Envolvido antes da Pessoa Envolvida.
A10: 6. RESULTADO ALCANÇADO: descreva em 1-2 frases o que a entrega gerou de concreto. Esse texto alimenta o report mensal.
A11: 7. GANHO DE PRODUTIVIDADE: se a entrega reduziu um processo recorrente, informe Tempo Antes e Tempo Depois em HORAS POR MÊS. Ganho e % Redução calculam sozinhos.
A12: 8. TRABALHO EM PARCERIA (2+ pessoas na mesma atividade): apenas UM participante é o Responsável — ele registra a atividade completa (antes/depois, resultado) e lista os colegas em "Parceiros". Os demais lançam uma linha com Papel = Apoio, SUAS horas, e o ID da Atividade Principal do responsável (ex.: FM-0002). Linhas de Apoio não repetem Tempo Antes/Depois — assim nada conta em dobro no report.
A13: 9. Ao final da semana, envie/salve o arquivo na pasta compartilhada para a consolidação da supervisora.
... A20: Identificação
A21: Nome do Analista: | B21: Juliana Santos
A22: Prefixo de ID: | B22: JS | C22: (exclusivo — não alterar)
A23: Departamento: | B23: Processos Integrados
A24: Supervisora: | B24: Juliana Batista

Sheet Lançamentos
A1: ID Único | B1: Data Início | C1: Data Conclusão | D1: Departamento | E1: Projeto | F1: Tema | G1: Pilar Proc. Integrados | H1: Tipo de Demanda | I1: Atividade (título curto) | J1: Descrição | K1: Depto. Envolvido (CSC) | L1: Pessoa Envolvida | M1: Parceria? | N1: Papel na Atividade | O1: Parceiros (equipe PI) | P1: ID Atividade Principal | Q1: Empresa | R1: Status | S1: Horas Gastas | T1: Tempo Antes (h/mês) | U1: Tempo Depois (h/mês) | V1: Ganho (h/mês) | W1: % Redução | X1: Resultado Alcançado | Y1: Pendência / Próximo Passo | Z1: Observação
A2: =IF($B2="","",Prefixo&"-"&TEXT(ROW()-1,"0000"))
A3: =IF($B3="","",Prefixo&"-"&TEXT(ROW()-1,"0000"))
A4: =IF($B4="","",Prefixo&"-"&TEXT(ROW()-1,"0000"))
A5: =IF($B5="","",Prefixo&"-"&TEXT(ROW()-1,"0000")) | V5: =IF($T5>0,$T5-$U5,"") | W5: =IF($T5>0,($T5-$U5)/$T5,"")
A6: =IF($B6="","",Prefixo&"-"&TEXT(ROW()-1,"0000")) | V6: =IF($T6>0,$T6-$U6,"") | W6: =IF($T6>0,($T6-$U6)/$T6,"")
A7: =IF($B7="","",Prefixo&"-"&TEXT(ROW()-1,"0000")) | V7: =IF($T7>0,$T7-$U7,"") | W7: =IF($T7>0,($T7-$U7)/$T7,"")
A8: =IF($B8="","",Prefixo&"-"&TEXT(ROW()-1,"0000")) | V8: =IF($T8>0,$T8-$U8,"") | W8: =IF($T8>0,($T8-$U8)/$T8,"")
A9: =IF($B9="","",Prefixo&"-"&TEXT(ROW()-1,"0000")) | V9: =IF($T9>0,$T9-$U9,"") | W9: =IF($T9>0,($T9-$U9)/$T9,"")
A10: =IF($B10="","",Prefixo&"-"&TEXT(ROW()-1,"0000")) | V10: =IF($T10>0,$T10-$U10,"") | W10: =IF($T10>0,($T10-$U10)/$T10,"")
A11: =IF($B11="","",Prefixo&"-"&TEXT(ROW()-1,"0000")) | V11: =IF($T11>0,$T11-$U11,"") | W11: =IF($T11>0,($T11-$U11)/$T11,"")
A12: =IF($B12="","",Prefixo&"-"&TEXT(ROW()-1,"0000")) | V12: =IF($T12>0,$T12-$U12,"") | W12: =IF($T12>0,($T12-$U12)/$T12,"")
A13: =IF($B13="","",Prefixo&"-"&TEXT(ROW()-1,"0000")) | V13: =IF($T13>0,$T13-$U13,"") | W13: =IF($T13>0,($T13-$U13)/$T13,"")
A14: =IF($B14="","",Prefixo&"-"&TEXT(ROW()-1,"0000")) | V14: =IF($T14>0,$T14-$U14,"") | W14: =IF($T14>0,($T14-$U14)/$T14,"")
A15: =IF($B15="","",Prefixo&"-"&TEXT(ROW()-1,"0000")) | V15: =IF($T15>0,$T15-$U15,"") | W15: =IF($T15>0,($T15-$U15)/$T15,"")
A16: =IF($B16="","",Prefixo&"-"&TEXT(ROW()-1,"0000")) | V16: =IF($T16>0,$T16-$U16,"") | W16: =IF($T16>0,($T16-$U16)/$T16,"")
... A1000: =IF($B1000="","",Prefixo&"-"&TEXT(ROW()-1,"0000")) | V1000: =IF($T1000>0,$T1000-$U1000,"") | W1000: =IF($T1000>0,($T1000-$U1000)/$T1000,"")

Sheet Acompanhamento Semanal
A1: ACOMPANHAMENTO SEMANAL
A2: Check-in de gestão (15-30 min) · Complementa a aba Lançamentos, nunca a substitui
A4: IDENTIFICAÇÃO
A5: Semana (nº / descrição):
A6: Período — de: | C6: até:
A7: Analista: | B7: Juliana Santos
A8: Gestora: | B8: Juliana Batista
A9: Departamento: | B9: Processos Integrados
A10: Data do Report:
A12: 1. RESUMO EXECUTIVO DA SEMANA (analista)
A13: Resumo das principais entregas
A14: Principais desafios
A15: Maior resultado alcançado
A16: Maior dificuldade encontrada
A17: Risco identificado
A18: Necessidade de apoio do gestor
A20: 2. CARTEIRA EM ABERTO (automático — tudo que ainda não foi concluído nos Lançamentos)
A21: ID | B21: Projeto | C21: Tema | D21: Atividade | E21: Status (Lançamento) | F21: Status da Semana (sugerido) | G21: Dias em Aberto | H21: Pendência / Próximo Passo
A22: =IF($O22="","",INDEX(Lançamentos!$A:$A,$O22)) | B22: =IF($O22="","",INDEX(Lançamentos!$E:$E,$O22)) | C22: =IF($O22="","",INDEX(Lançamentos!$F:$F,$O22)) | D22: =IF($O22="","",INDEX(Lançamentos!$I:$I,$O22)) | E22: =IF($O22="","",INDEX(Lançamentos!$R:$R,$O22)) | F22: =IF($O22="","",IF($E22="Em andamento","🟡 Em andamento",IF($E22="Aguardando terceiros","⏸ Aguardando Terceiros",IF($E22="Não iniciado","⚪ Não iniciado","🟡 Em andamento")))) | G22: =IF($O22="","",TODAY()-INDEX(Lançamentos!$B:$B,$O22)) | H22: =IF($O22="","",INDEX(Lançamentos!$Y:$Y,$O22)) | O22: =IFERROR(_xlfn.AGGREGATE(15,6,ROW(Lançamentos!$I$2:$I$1000)/((Lançamentos!$R$2:$R$1000<>"Concluído")*(Lançamentos!$R$2:$R$1000<>"Cancelado")*(Lançamentos!$I$2:$I$1000<>"")),1),"")
A23: =IF($O23="","",INDEX(Lançamentos!$A:$A,$O23)) | B23: =IF($O23="","",INDEX(Lançamentos!$E:$E,$O23)) | C23: =IF($O23="","",INDEX(Lançamentos!$F:$F,$O23)) | D23: =IF($O23="","",INDEX(Lançamentos!$I:$I,$O23)) | E23: =IF($O23="","",INDEX(Lançamentos!$R:$R,$O23)) | F23: =IF($O23="","",IF($E23="Em andamento","🟡 Em andamento",IF($E23="Aguardando terceiros","⏸ Aguardando Terceiros",IF($E23="Não iniciado","⚪ Não iniciado","🟡 Em andamento")))) | G23: =IF($O23="","",TODAY()-INDEX(Lançamentos!$B:$B,$O23)) | H23: =IF($O23="","",INDEX(Lançamentos!$Y:$Y,$O23)) | O23: =IFERROR(_xlfn.AGGREGATE(15,6,ROW(Lançamentos!$I$2:$I$1000)/((Lançamentos!$R$2:$R$1000<>"Concluído")*(Lançamentos!$R$2:$R$1000<>"Cancelado")*(Lançamentos!$I$2:$I$1000<>"")),2),"")
A24: =IF($O24="","",INDEX(Lançamentos!$A:$A,$O24)) | B24: =IF($O24="","",INDEX(Lançamentos!$E:$E,$O24)) | C24: =IF($O24="","",INDEX(Lançamentos!$F:$F,$O24)) | D24: =IF($O24="","",INDEX(Lançamentos!$I:$I,$O24)) | E24: =IF($O24="","",INDEX(Lançamentos!$R:$R,$O24)) | F24: =IF($O24="","",IF($E24="Em andamento","🟡 Em andamento",IF($E24="Aguardando terceiros","⏸ Aguardando Terceiros",IF($E24="Não iniciado","⚪ Não iniciado","🟡 Em andamento")))) | G24: =IF($O24="","",TODAY()-INDEX(Lançamentos!$B:$B,$O24)) | H24: =IF($O24="","",INDEX(Lançamentos!$Y:$Y,$O24)) | O24: =IFERROR(_xlfn.AGGREGATE(15,6,ROW(Lançamentos!$I$2:$I$1000)/((Lançamentos!$R$2:$R$1000<>"Concluído")*(Lançamentos!$R$2:$R$1000<>"Cancelado")*(Lançamentos!$I$2:$I$1000<>"")),3),"")
A25: =IF($O25="","",INDEX(Lançamentos!$A:$A,$O25)) | B25: =IF($O25="","",INDEX(Lançamentos!$E:$E,$O25)) | C25: =IF($O25="","",INDEX(Lançamentos!$F:$F,$O25)) | D25: =IF($O25="","",INDEX(Lançamentos!$I:$I,$O25)) | E25: =IF($O25="","",INDEX(Lançamentos!$R:$R,$O25)) | F25: =IF($O25="","",IF($E25="Em andamento","🟡 Em andamento",IF($E25="Aguardando terceiros","⏸ Aguardando Terceiros",IF($E25="Não iniciado","⚪ Não iniciado","🟡 Em andamento")))) | G25: =IF($O25="","",TODAY()-INDEX(Lançamentos!$B:$B,$O25)) | H25: =IF($O25="","",INDEX(Lançamentos!$Y:$Y,$O25)) | O25: =IFERROR(_xlfn.AGGREGATE(15,6,ROW(Lançamentos!$I$2:$I$1000)/((Lançamentos!$R$2:$R$1000<>"Concluído")*(Lançamentos!$R$2:$R$1000<>"Cancelado")*(Lançamentos!$I$2:$I$1000<>"")),4),"")
A26: =IF($O26="","",INDEX(Lançamentos!$A:$A,$O26)) | B26: =IF($O26="","",INDEX(Lançamentos!$E:$E,$O26)) | C26: =IF($O26="","",INDEX(Lançamentos!$F:$F,$O26)) | D26: =IF($O26="","",INDEX(Lançamentos!$I:$I,$O26)) | E26: =IF($O26="","",INDEX(Lançamentos!$R:$R,$O26)) | F26: =IF($O26="","",IF($E26="Em andamento","🟡 Em andamento",IF($E26="Aguardando terceiros","⏸ Aguardando Terceiros",IF($E26="Não iniciado","⚪ Não iniciado","🟡 Em andamento")))) | G26: =IF($O26="","",TODAY()-INDEX(Lançamentos!$B:$B,$O26)) | H26: =IF($O26="","",INDEX(Lançamentos!$Y:$Y,$O26)) | O26: =IFERROR(_xlfn.AGGREGATE(15,6,ROW(Lançamentos!$I$2:$I$1000)/((Lançamentos!$R$2:$R$1000<>"Concluído")*(Lançamentos!$R$2:$R$1000<>"Cancelado")*(Lançamentos!$I$2:$I$1000<>"")),5),"")
A27: =IF($O27="","",INDEX(Lançamentos!$A:$A,$O27)) | B27: =IF($O27="","",INDEX(Lançamentos!$E:$E,$O27)) | C27: =IF($O27="","",INDEX(Lançamentos!$F:$F,$O27)) | D27: =IF($O27="","",INDEX(Lançamentos!$I:$I,$O27)) | E27: =IF($O27="","",INDEX(Lançamentos!$R:$R,$O27)) | F27: =IF($O27="","",IF($E27="Em andamento","🟡 Em andamento",IF($E27="Aguardando terceiros","⏸ Aguardando Terceiros",IF($E27="Não iniciado","⚪ Não iniciado","🟡 Em andamento")))) | G27: =IF($O27="","",TODAY()-INDEX(Lançamentos!$B:$B,$O27)) | H27: =IF($O27="","",INDEX(Lançamentos!$Y:$Y,$O27)) | O27: =IFERROR(_xlfn.AGGREGATE(15,6,ROW(Lançamentos!$I$2:$I$1000)/((Lançamentos!$R$2:$R$1000<>"Concluído")*(Lançamentos!$R$2:$R$1000<>"Cancelado")*(Lançamentos!$I$2:$I$1000<>"")),6),"")
A28: =IF($O28="","",INDEX(Lançamentos!$A:$A,$O28)) | B28: =IF($O28="","",INDEX(Lançamentos!$E:$E,$O28)) | C28: =IF($O28="","",INDEX(Lançamentos!$F:$F,$O28)) | D28: =IF($O28="","",INDEX(Lançamentos!$I:$I,$O28)) | E28: =IF($O28="","",INDEX(Lançamentos!$R:$R,$O28)) | F28: =IF($O28="","",IF($E28="Em andamento","🟡 Em andamento",IF($E28="Aguardando terceiros","⏸ Aguardando Terceiros",IF($E28="Não iniciado","⚪ Não iniciado","🟡 Em andamento")))) | G28: =IF($O28="","",TODAY()-INDEX(Lançamentos!$B:$B,$O28)) | H28: =IF($O28="","",INDEX(Lançamentos!$Y:$Y,$O28)) | O28: =IFERROR(_xlfn.AGGREGATE(15,6,ROW(Lançamentos!$I$2:$I$1000)/((Lançamentos!$R$2:$R$1000<>"Concluído")*(Lançamentos!$R$2:$R$1000<>"Cancelado")*(Lançamentos!$I$2:$I$1000<>"")),7),"")
A29: =IF($O29="","",INDEX(Lançamentos!$A:$A,$O29)) | B29: =IF($O29="","",INDEX(Lançamentos!$E:$E,$O29)) | C29: =IF($O29="","",INDEX(Lançamentos!$F:$F,$O29)) | D29: =IF($O29="","",INDEX(Lançamentos!$I:$I,$O29)) | E29: =IF($O29="","",INDEX(Lançamentos!$R:$R,$O29)) | F29: =IF($O29="","",IF($E29="Em andamento","🟡 Em andamento",IF($E29="Aguardando terceiros","⏸ Aguardando Terceiros",IF($E29="Não iniciado","⚪ Não iniciado","🟡 Em andamento")))) | G29: =IF($O29="","",TODAY()-INDEX(Lançamentos!$B:$B,$O29)) | H29: =IF($O29="","",INDEX(Lançamentos!$Y:$Y,$O29)) | O29: =IFERROR(_xlfn.AGGREGATE(15,6,ROW(Lançamentos!$I$2:$I$1000)/((Lançamentos!$R$2:$R$1000<>"Concluído")*(Lançamentos!$R$2:$R$1000<>"Cancelado")*(Lançamentos!$I$2:$I$1000<>"")),8),"")
A30: =IF($O30="","",INDEX(Lançamentos!$A:$A,$O30)) | B30: =IF($O30="","",INDEX(Lançamentos!$E:$E,$O30)) | C30: =IF($O30="","",INDEX(Lançamentos!$F:$F,$O30)) | D30: =IF($O30="","",INDEX(Lançamentos!$I:$I,$O30)) | E30: =IF($O30="","",INDEX(Lançamentos!$R:$R,$O30)) | F30: =IF($O30="","",IF($E30="Em andamento","🟡 Em andamento",IF($E30="Aguardando terceiros","⏸ Aguardando Terceiros",IF($E30="Não iniciado","⚪ Não iniciado","🟡 Em andamento")))) | G30: =IF($O30="","",TODAY()-INDEX(Lançamentos!$B:$B,$O30)) | H30: =IF($O30="","",INDEX(Lançamentos!$Y:$Y,$O30)) | O30: =IFERROR(_xlfn.AGGREGATE(15,6,ROW(Lançamentos!$I$2:$I$1000)/((Lançamentos!$R$2:$R$1000<>"Concluído")*(Lançamentos!$R$2:$R$1000<>"Cancelado")*(Lançamentos!$I$2:$I$1000<>"")),9),"")
A31: =IF($O31="","",INDEX(Lançamentos!$A:$A,$O31)) | B31: =IF($O31="","",INDEX(Lançamentos!$E:$E,$O31)) | C31: =IF($O31="","",INDEX(Lançamentos!$F:$F,$O31)) | D31: =IF($O31="","",INDEX(Lançamentos!$I:$I,$O31)) | E31: =IF($O31="","",INDEX(Lançamentos!$R:$R,$O31)) | F31: =IF($O31="","",IF($E31="Em andamento","🟡 Em andamento",IF($E31="Aguardando terceiros","⏸ Aguardando Terceiros",IF($E31="Não iniciado","⚪ Não iniciado","🟡 Em andamento")))) | G31: =IF($O31="","",TODAY()-INDEX(Lançamentos!$B:$B,$O31)) | H31: =IF($O31="","",INDEX(Lançamentos!$Y:$Y,$O31)) | O31: =IFERROR(_xlfn.AGGREGATE(15,6,ROW(Lançamentos!$I$2:$I$1000)/((Lançamentos!$R$2:$R$1000<>"Concluído")*(Lançamentos!$R$2:$R$1000<>"Cancelado")*(Lançamentos!$I$2:$I$1000<>"")),10),"")
A32: =IF($O32="","",INDEX(Lançamentos!$A:$A,$O32)) | B32: =IF($O32="","",INDEX(Lançamentos!$E:$E,$O32)) | C32: =IF($O32="","",INDEX(Lançamentos!$F:$F,$O32)) | D32: =IF($O32="","",INDEX(Lançamentos!$I:$I,$O32)) | E32: =IF($O32="","",INDEX(Lançamentos!$R:$R,$O32)) | F32: =IF($O32="","",IF($E32="Em andamento","🟡 Em andamento",IF($E32="Aguardando terceiros","⏸ Aguardando Terceiros",IF($E32="Não iniciado","⚪ Não iniciado","🟡 Em andamento")))) | G32: =IF($O32="","",TODAY()-INDEX(Lançamentos!$B:$B,$O32)) | H32: =IF($O32="","",INDEX(Lançamentos!$Y:$Y,$O32)) | O32: =IFERROR(_xlfn.AGGREGATE(15,6,ROW(Lançamentos!$I$2:$I$1000)/((Lançamentos!$R$2:$R$1000<>"Concluído")*(Lançamentos!$R$2:$R$1000<>"Cancelado")*(Lançamentos!$I$2:$I$1000<>"")),11),"")
A33: =IF($O33="","",INDEX(Lançamentos!$A:$A,$O33)) | B33: =IF($O33="","",INDEX(Lançamentos!$E:$E,$O33)) | C33: =IF($O33="","",INDEX(Lançamentos!$F:$F,$O33)) | D33: =IF($O33="","",INDEX(Lançamentos!$I:$I,$O33)) | E33: =IF($O33="","",INDEX(Lançamentos!$R:$R,$O33)) | F33: =IF($O33="","",IF($E33="Em andamento","🟡 Em andamento",IF($E33="Aguardando terceiros","⏸ Aguardando Terceiros",IF($E33="Não iniciado","⚪ Não iniciado","🟡 Em andamento")))) | G33: =IF($O33="","",TODAY()-INDEX(Lançamentos!$B:$B,$O33)) | H33: =IF($O33="","",INDEX(Lançamentos!$Y:$Y,$O33)) | O33: =IFERROR(_xlfn.AGGREGATE(15,6,ROW(Lançamentos!$I$2:$I$1000)/((Lançamentos!$R$2:$R$1000<>"Concluído")*(Lançamentos!$R$2:$R$1000<>"Cancelado")*(Lançamentos!$I$2:$I$1000<>"")),12),"")
A34: =IF($O34="","",INDEX(Lançamentos!$A:$A,$O34)) | B34: =IF($O34="","",INDEX(Lançamentos!$E:$E,$O34)) | C34: =IF($O34="","",INDEX(Lançamentos!$F:$F,$O34)) | D34: =IF($O34="","",INDEX(Lançamentos!$I:$I,$O34)) | E34: =IF($O34="","",INDEX(Lançamentos!$R:$R,$O34)) | F34: =IF($O34="","",IF($E34="Em andamento","🟡 Em andamento",IF($E34="Aguardando terceiros","⏸ Aguardando Terceiros",IF($E34="Não iniciado","⚪ Não iniciado","🟡 Em andamento")))) | G34: =IF($O34="","",TODAY()-INDEX(Lançamentos!$B:$B,$O34)) | H34: =IF($O34="","",INDEX(Lançamentos!$Y:$Y,$O34)) | O34: =IFERROR(_xlfn.AGGREGATE(15,6,ROW(Lançamentos!$I$2:$I$1000)/((Lançamentos!$R$2:$R$1000<>"Concluído")*(Lançamentos!$R$2:$R$1000<>"Cancelado")*(Lançamentos!$I$2:$I$1000<>"")),13),"")
A35: =IF($O35="","",INDEX(Lançamentos!$A:$A,$O35)) | B35: =IF($O35="","",INDEX(Lançamentos!$E:$E,$O35)) | C35: =IF($O35="","",INDEX(Lançamentos!$F:$F,$O35)) | D35: =IF($O35="","",INDEX(Lançamentos!$I:$I,$O35)) | E35: =IF($O35="","",INDEX(Lançamentos!$R:$R,$O35)) | F35: =IF($O35="","",IF($E35="Em andamento","🟡 Em andamento",IF($E35="Aguardando terceiros","⏸ Aguardando Terceiros",IF($E35="Não iniciado","⚪ Não iniciado","🟡 Em andamento")))) | G35: =IF($O35="","",TODAY()-INDEX(Lançamentos!$B:$B,$O35)) | H35: =IF($O35="","",INDEX(Lançamentos!$Y:$Y,$O35)) | O35: =IFERROR(_xlfn.AGGREGATE(15,6,ROW(Lançamentos!$I$2:$I$1000)/((Lançamentos!$R$2:$R$1000<>"Concluído")*(Lançamentos!$R$2:$R$1000<>"Cancelado")*(Lançamentos!$I$2:$I$1000<>"")),14),"")
A36: =IF($O36="","",INDEX(Lançamentos!$A:$A,$O36)) | B36: =IF($O36="","",INDEX(Lançamentos!$E:$E,$O36)) | C36: =IF($O36="","",INDEX(Lançamentos!$F:$F,$O36)) | D36: =IF($O36="","",INDEX(Lançamentos!$I:$I,$O36)) | E36: =IF($O36="","",INDEX(Lançamentos!$R:$R,$O36)) | F36: =IF($O36="","",IF($E36="Em andamento","🟡 Em andamento",IF($E36="Aguardando terceiros","⏸ Aguardando Terceiros",IF($E36="Não iniciado","⚪ Não iniciado","🟡 Em andamento")))) | G36: =IF($O36="","",TODAY()-INDEX(Lançamentos!$B:$B,$O36)) | H36: =IF($O36="","",INDEX(Lançamentos!$Y:$Y,$O36)) | O36: =IFERROR(_xlfn.AGGREGATE(15,6,ROW(Lançamentos!$I$2:$I$1000)/((Lançamentos!$R$2:$R$1000<>"Concluído")*(Lançamentos!$R$2:$R$1000<>"Cancelado")*(Lançamentos!$I$2:$I$1000<>"")),15),"")
A37: =IF($O37="","",INDEX(Lançamentos!$A:$A,$O37)) | B37: =IF($O37="","",INDEX(Lançamentos!$E:$E,$O37)) | C37: =IF($O37="","",INDEX(Lançamentos!$F:$F,$O37)) | D37: =IF($O37="","",INDEX(Lançamentos!$I:$I,$O37)) | E37: =IF($O37="","",INDEX(Lançamentos!$R:$R,$O37)) | F37: =IF($O37="","",IF($E37="Em andamento","🟡 Em andamento",IF($E37="Aguardando terceiros","⏸ Aguardando Terceiros",IF($E37="Não iniciado","⚪ Não iniciado","🟡 Em andamento")))) | G37: =IF($O37="","",TODAY()-INDEX(Lançamentos!$B:$B,$O37)) | H37: =IF($O37="","",INDEX(Lançamentos!$Y:$Y,$O37)) | O37: =IFERROR(_xlfn.AGGREGATE(15,6,ROW(Lançamentos!$I$2:$I$1000)/((Lançamentos!$R$2:$R$1000<>"Concluído")*(Lançamentos!$R$2:$R$1000<>"Cancelado")*(Lançamentos!$I$2:$I$1000<>"")),16),"")
A38: =IF($O38="","",INDEX(Lançamentos!$A:$A,$O38)) | B38: =IF($O38="","",INDEX(Lançamentos!$E:$E,$O38)) | C38: =IF($O38="","",INDEX(Lançamentos!$F:$F,$O38)) | D38: =IF($O38="","",INDEX(Lançamentos!$I:$I,$O38)) | E38: =IF($O38="","",INDEX(Lançamentos!$R:$R,$O38)) | F38: =IF($O38="","",IF($E38="Em andamento","🟡 Em andamento",IF($E38="Aguardando terceiros","⏸ Aguardando Terceiros",IF($E38="Não iniciado","⚪ Não iniciado","🟡 Em andamento")))) | G38: =IF($O38="","",TODAY()-INDEX(Lançamentos!$B:$B,$O38)) | H38: =IF($O38="","",INDEX(Lançamentos!$Y:$Y,$O38)) | O38: =IFERROR(_xlfn.AGGREGATE(15,6,ROW(Lançamentos!$I$2:$I$1000)/((Lançamentos!$R$2:$R$1000<>"Concluído")*(Lançamentos!$R$2:$R$1000<>"Cancelado")*(Lançamentos!$I$2:$I$1000<>"")),17),"")
A39: =IF($O39="","",INDEX(Lançamentos!$A:$A,$O39)) | B39: =IF($O39="","",INDEX(Lançamentos!$E:$E,$O39)) | C39: =IF($O39="","",INDEX(Lançamentos!$F:$F,$O39)) | D39: =IF($O39="","",INDEX(Lançamentos!$I:$I,$O39)) | E39: =IF($O39="","",INDEX(Lançamentos!$R:$R,$O39)) | F39: =IF($O39="","",IF($E39="Em andamento","🟡 Em andamento",IF($E39="Aguardando terceiros","⏸ Aguardando Terceiros",IF($E39="Não iniciado","⚪ Não iniciado","🟡 Em andamento")))) | G39: =IF($O39="","",TODAY()-INDEX(Lançamentos!$B:$B,$O39)) | H39: =IF($O39="","",INDEX(Lançamentos!$Y:$Y,$O39)) | O39: =IFERROR(_xlfn.AGGREGATE(15,6,ROW(Lançamentos!$I$2:$I$1000)/((Lançamentos!$R$2:$R$1000<>"Concluído")*(Lançamentos!$R$2:$R$1000<>"Cancelado")*(Lançamentos!$I$2:$I$1000<>"")),18),"")
A40: =IF($O40="","",INDEX(Lançamentos!$A:$A,$O40)) | B40: =IF($O40="","",INDEX(Lançamentos!$E:$E,$O40)) | C40: =IF($O40="","",INDEX(Lançamentos!$F:$F,$O40)) | D40: =IF($O40="","",INDEX(Lançamentos!$I:$I,$O40)) | E40: =IF($O40="","",INDEX(Lançamentos!$R:$R,$O40)) | F40: =IF($O40="","",IF($E40="Em andamento","🟡 Em andamento",IF($E40="Aguardando terceiros","⏸ Aguardando Terceiros",IF($E40="Não iniciado","⚪ Não iniciado","🟡 Em andamento")))) | G40: =IF($O40="","",TODAY()-INDEX(Lançamentos!$B:$B,$O40)) | H40: =IF($O40="","",INDEX(Lançamentos!$Y:$Y,$O40)) | O40: =IFERROR(_xlfn.AGGREGATE(15,6,ROW(Lançamentos!$I$2:$I$1000)/((Lançamentos!$R$2:$R$1000<>"Concluído")*(Lançamentos!$R$2:$R$1000<>"Cancelado")*(Lançamentos!$I$2:$I$1000<>"")),19),"")
A41: =IF($O41="","",INDEX(Lançamentos!$A:$A,$O41)) | B41: =IF($O41="","",INDEX(Lançamentos!$E:$E,$O41)) | C41: =IF($O41="","",INDEX(Lançamentos!$F:$F,$O41)) | D41: =IF($O41="","",INDEX(Lançamentos!$I:$I,$O41)) | E41: =IF($O41="","",INDEX(Lançamentos!$R:$R,$O41)) | F41: =IF($O41="","",IF($E41="Em andamento","🟡 Em andamento",IF($E41="Aguardando terceiros","⏸ Aguardando Terceiros",IF($E41="Não iniciado","⚪ Não iniciado","🟡 Em andamento")))) | G41: =IF($O41="","",TODAY()-INDEX(Lançamentos!$B:$B,$O41)) | H41: =IF($O41="","",INDEX(Lançamentos!$Y:$Y,$O41)) | O41: =IFERROR(_xlfn.AGGREGATE(15,6,ROW(Lançamentos!$I$2:$I$1000)/((Lançamentos!$R$2:$R$1000<>"Concluído")*(Lançamentos!$R$2:$R$1000<>"Cancelado")*(Lançamentos!$I$2:$I$1000<>"")),20),"")
A43: 3. COMPLEMENTO SEMANAL — repita a atividade TODA semana até concluir (o histórico fica aqui)
A44: Semana | B44: ID | C44: Projeto (auto) | D44: Atividade (auto) | E44: Status da Semana (sugerido — pode alterar) | F44: Motivo do Status | G44: O que foi realizado na semana? | H44: Próximo Passo | I44: Necessita Apoio? | J44: Responsável pela Pendência | K44: Previsão de Conclusão | L44: Evolução (%) | M44: Semanas Reportadas (auto)
...

Sheet Resumo
A1: RESUMO — JULIANA SANTOS (JS)
A2: Calculado automaticamente a partir da aba Lançamentos
A4: VISÃO GERAL
A5: Total de lançamentos | B5: =COUNTIF(Lançamentos!$I$2:$I$1000,"<>") -> 0
A6: Entregas como Responsável | B6: =COUNTIFS(Lançamentos!$I$2:$I$1000,"<>",Lançamentos!$N$2:$N$1000,"<>Apoio") -> 0
A7: Linhas de Apoio (parcerias) | B7: =COUNTIF(Lançamentos!$N$2:$N$1000,"Apoio") -> 0
A8: Concluídos | B8: =COUNTIF(Lançamentos!$R$2:$R$1000,"Concluído") -> 0
A9: Em andamento | B9: =COUNTIF(Lançamentos!$R$2:$R$1000,"Em andamento") -> 0
A10: Horas gastas (total) | B10: =SUM(Lançamentos!$S$2:$S$1000) -> 0
A11: Ganho de produtividade gerado (h/mês) | B11: =SUM(Lançamentos!$V$2:$V$1000) -> 0
A13: POR PROJETO
A14: Item | B14: Total | C14: Concluídas | D14: Horas | E14: Ganho h/mês
A15: Lumen | B15: =COUNTIF(Lançamentos!$E$2:$E$1000,$A15) -> 0 | C15: =COUNTIFS(Lançamentos!$E$2:$E$1000,$A15,Lançamentos!$R$2:$R$1000,"Concluído") -> 0 | D15: =SUMIFS(Lançamentos!$S$2:$S$1000,Lançamentos!$E$2:$E$1000,$A15) -> 0 | E15: =SUMIFS(Lançamentos!$V$2:$V$1000,Lançamentos!$E$2:$E$1000,$A15) -> 0
A16: V360 | B16: =COUNTIF(Lançamentos!$E$2:$E$1000,$A16) -> 0 | C16: =COUNTIFS(Lançamentos!$E$2:$E$1000,$A16,Lançamentos!$R$2:$R$1000,"Concluído") -> 0 | D16: =SUMIFS(Lançamentos!$S$2:$S$1000,Lançamentos!$E$2:$E$1000,$A16) -> 0 | E16: =SUMIFS(Lançamentos!$V$2:$V$1000,Lançamentos!$E$2:$E$1000,$A16) -> 0
A17: Saneamento Base Contábil | B17: =COUNTIF(Lançamentos!$E$2:$E$1000,$A17) -> 0 | C17: =COUNTIFS(Lançamentos!$E$2:$E$1000,$A17,Lançamentos!$R$2:$R$1000,"Concluído") -> 0 | D17: =SUMIFS(Lançamentos!$S$2:$S$1000,Lançamentos!$E$2:$E$1000,$A17) -> 0 | E17: =SUMIFS(Lançamentos!$V$2:$V$1000,Lançamentos!$E$2:$E$1000,$A17) -> 0
A18: Newsletter | B18: =COUNTIF(Lançamentos!$E$2:$E$1000,$A18) -> 0 | C18: =COUNTIFS(Lançamentos!$E$2:$E$1000,$A18,Lançamentos!$R$2:$R$1000,"Concluído") -> 0 | D18: =SUMIFS(Lançamentos!$S$2:$S$1000,Lançamentos!$E$2:$E$1000,$A18) -> 0 | E18: =SUMIFS(Lançamentos!$V$2:$V$1000,Lançamentos!$E$2:$E$1000,$A18) -> 0
A19: Rotina Fiscal/Contábil | B19: =COUNTIF(Lançamentos!$E$2:$E$1000,$A19) -> 0 | C19: =COUNTIFS(Lançamentos!$E$2:$E$1000,$A19,Lançamentos!$R$2:$R$1000,"Concluído") -> 0 | D19: =SUMIFS(Lançamentos!$S$2:$S$1000,Lançamentos!$E$2:$E$1000,$A19) -> 0 | E19: =SUMIFS(Lançamentos!$V$2:$V$1000,Lançamentos!$E$2:$E$1000,$A19) -> 0
A20: Rotina Financeiro | B20: =COUNTIF(Lançamentos!$E$2:$E$1000,$A20) -> 0 | C20: =COUNTIFS(Lançamentos!$E$2:$E$1000,$A20,Lançamentos!$R$2:$R$1000,"Concluído") -> 0 | D20: =SUMIFS(Lançamentos!$S$2:$S$1000,Lançamentos!$E$2:$E$1000,$A20) -> 0 | E20: =SUMIFS(Lançamentos!$V$2:$V$1000,Lançamentos!$E$2:$E$1000,$A20) -> 0
A21: Investidas | B21: =COUNTIF(Lançamentos!$E$2:$E$1000,$A21) -> 0 | C21: =COUNTIFS(Lançamentos!$E$2:$E$1000,$A21,Lançamentos!$R$2:$R$1000,"Concluído") -> 0 | D21: =SUMIFS(Lançamentos!$S$2:$S$1000,Lançamentos!$E$2:$E$1000,$A21) -> 0 | E21: =SUMIFS(Lançamentos!$V$2:$V$1000,Lançamentos!$E$2:$E$1000,$A21) -> 0
A22: Actio | B22: =COUNTIF(Lançamentos!$E$2:$E$1000,$A22) -> 0 | C22: =COUNTIFS(Lançamentos!$E$2:$E$1000,$A22,Lançamentos!$R$2:$R$1000,"Concluído") -> 0 | D22: =SUMIFS(Lançamentos!$S$2:$S$1000,Lançamentos!$E$2:$E$1000,$A22) -> 0 | E22: =SUMIFS(Lançamentos!$V$2:$V$1000,Lançamentos!$E$2:$E$1000,$A22) -> 0
A23: Indicadores e Metas | B23: =COUNTIF(Lançamentos!$E$2:$E$1000,$A23) -> 0 | C23: =COUNTIFS(Lançamentos!$E$2:$E$1000,$A23,Lançamentos!$R$2:$R$1000,"Concluído") -> 0 | D23: =SUMIFS(Lançamentos!$S$2:$S$1000,Lançamentos!$E$2:$E$1000,$A23) -> 0 | E23: =SUMIFS(Lançamentos!$V$2:$V$1000,Lançamentos!$E$2:$E$1000,$A23) -> 0
A25: POR PILAR DE PROCESSOS INTEGRADOS
A26: Item | B26: Total | C26: Concluídas | D26: Horas | E26: Ganho h/mês
A27: Governança | B27: =COUNTIF(Lançamentos!$G$2:$G$1000,$A27) -> 0 | C27: =COUNTIFS(Lançamentos!$G$2:$G$1000,$A27,Lançamentos!$R$2:$R$1000,"Concluído") -> 0 | D27: =SUMIFS(Lançamentos!$S$2:$S$1000,Lançamentos!$G$2:$G$1000,$A27) -> 0 | E27: =SUMIFS(Lançamentos!$V$2:$V$1000,Lançamentos!$G$2:$G$1000,$A27) -> 0
A28: Melhoria Contínua | B28: =COUNTIF(Lançamentos!$G$2:$G$1000,$A28) -> 0 | C28: =COUNTIFS(Lançamentos!$G$2:$G$1000,$A28,Lançamentos!$R$2:$R$1000,"Concluído") -> 0 | D28: =SUMIFS(Lançamentos!$S$2:$S$1000,Lançamentos!$G$2:$G$1000,$A28) -> 0 | E28: =SUMIFS(Lançamentos!$V$2:$V$1000,Lançamentos!$G$2:$G$1000,$A28) -> 0
A29: Transformação Digital | B29: =COUNTIF(Lançamentos!$G$2:$G$1000,$A29) -> 0 | C29: =COUNTIFS(Lançamentos!$G$2:$G$1000,$A29,Lançamentos!$R$2:$R$1000,"Concluído") -> 0 | D29: =SUMIFS(Lançamentos!$S$2:$S$1000,Lançamentos!$G$2:$G$1000,$A29) -> 0 | E29: =SUMIFS(Lançamentos!$V$2:$V$1000,Lançamentos!$G$2:$G$1000,$A29) -> 0
A30: Business Intelligence | B30: =COUNTIF(Lançamentos!$G$2:$G$1000,$A30) -> 0 | C30: =COUNTIFS(Lançamentos!$G$2:$G$1000,$A30,Lançamentos!$R$2:$R$1000,"Concluído") -> 0 | D30: =SUMIFS(Lançamentos!$S$2:$S$1000,Lançamentos!$G$2:$G$1000,$A30) -> 0 | E30: =SUMIFS(Lançamentos!$V$2:$V$1000,Lançamentos!$G$2:$G$1000,$A30) -> 0
A31: PMO / Projetos | B31: =COUNTIF(Lançamentos!$G$2:$G$1000,$A31) -> 0 | C31: =COUNTIFS(Lançamentos!$G$2:$G$1000,$A31,Lançamentos!$R$2:$R$1000,"Concluído") -> 0 | D31: =SUMIFS(Lançamentos!$S$2:$S$1000,Lançamentos!$G$2:$G$1000,$A31) -> 0 | E31: =SUMIFS(Lançamentos!$V$2:$V$1000,Lançamentos!$G$2:$G$1000,$A31) -> 0
A32: Operação (Rotina) | B32: =COUNTIF(Lançamentos!$G$2:$G$1000,$A32) -> 0 | C32: =COUNTIFS(Lançamentos!$G$2:$G$1000,$A32,Lançamentos!$R$2:$R$1000,"Concluído") -> 0 | D32: =SUMIFS(Lançamentos!$S$2:$S$1000,Lançamentos!$G$2:$G$1000,$A32) -> 0 | E32: =SUMIFS(Lançamentos!$V$2:$V$1000,Lançamentos!$G$2:$G$1000,$A32) -> 0
A34: POR DEPARTAMENTO ENVOLVIDO (CSC)
A35: Item | B35: Total | C35: Concluídas | D35: Horas | E35: Ganho h/mês
A36: Contas a Receber | B36: =COUNTIF(Lançamentos!$K$2:$K$1000,$A36) -> 0 | C36: =COUNTIFS(Lançamentos!$K$2:$K$1000,$A36,Lançamentos!$R$2:$R$1000,"Concluído") -> 0 | D36: =SUMIFS(Lançamentos!$S$2:$S$1000,Lançamentos!$K$2:$K$1000,$A36) -> 0 | E36: =SUMIFS(Lançamentos!$V$2:$V$1000,Lançamentos!$K$2:$K$1000,$A36) -> 0
A37: Tesouraria | B37: =COUNTIF(Lançamentos!$K$2:$K$1000,$A37) -> 0 | C37: =COUNTIFS(Lançamentos!$K$2:$K$1000,$A37,Lançamentos!$R$2:$R$1000,"Concluído") -> 0 | D37: =SUMIFS(Lançamentos!$S$2:$S$1000,Lançamentos!$K$2:$K$1000,$A37) -> 0 | E37: =SUMIFS(Lançamentos!$V$2:$V$1000,Lançamentos!$K$2:$K$1000,$A37) -> 0
A38: Auditoria Financeira CSC | B38: =COUNTIF(Lançamentos!$K$2:$K$1000,$A38) -> 0 | C38: =COUNTIFS(Lançamentos!$K$2:$K$1000,$A38,Lançamentos!$R$2:$R$1000,"Concluído") -> 0 | D38: =SUMIFS(Lançamentos!$S$2:$S$1000,Lançamentos!$K$2:$K$1000,$A38) -> 0 | E38: =SUMIFS(Lançamentos!$V$2:$V$1000,Lançamentos!$K$2:$K$1000,$A38) -> 0
A39: Recebimento Fiscal | B39: =COUNTIF(Lançamentos!$K$2:$K$1000,$A39) -> 0 | C39: =COUNTIFS(Lançamentos!$K$2:$K$1000,$A39,Lançamentos!$R$2:$R$1000,"Concluído") -> 0 | D39: =SUMIFS(Lançamentos!$S$2:$S$1000,Lançamentos!$K$2:$K$1000,$A39) -> 0 | E39: =SUMIFS(Lançamentos!$V$2:$V$1000,Lançamentos!$K$2:$K$1000,$A39) -> 0
A40: Processos Integrados | B40: =COUNTIF(Lançamentos!$K$2:$K$1000,$A40) -> 0 | C40: =COUNTIFS(Lançamentos!$K$2:$K$1000,$A40,Lançamentos!$R$2:$R$1000,"Concluído") -> 0 | D40: =SUMIFS(Lançamentos!$S$2:$S$1000,Lançamentos!$K$2:$K$1000,$A40) -> 0 | E40: =SUMIFS(Lançamentos!$V$2:$V$1000,Lançamentos!$K$2:$K$1000,$A40) -> 0
A41: Cartão Corporativo | B41: =COUNTIF(Lançamentos!$K$2:$K$1000,$A41) -> 0 | C41: =COUNTIFS(Lançamentos!$K$2:$K$1000,$A41,Lançamentos!$R$2:$R$1000,"Concluído") -> 0 | D41: =SUMIFS(Lançamentos!$S$2:$S$1000,Lançamentos!$K$2:$K$1000,$A41) -> 0 | E41: =SUMIFS(Lançamentos!$V$2:$V$1000,Lançamentos!$K$2:$K$1000,$A41) -> 0
A42: Tributos Federais | B42: =COUNTIF(Lançamentos!$K$2:$K$1000,$A42) -> 0 | C42: =COUNTIFS(Lançamentos!$K$2:$K$1000,$A42,Lançamentos!$R$2:$R$1000,"Concluído") -> 0 | D42: =SUMIFS(Lançamentos!$S$2:$S$1000,Lançamentos!$K$2:$K$1000,$A42) -> 0 | E42: =SUMIFS(Lançamentos!$V$2:$V$1000,Lançamentos!$K$2:$K$1000,$A42) -> 0
A43: Tributos Estaduais | B43: =COUNTIF(Lançamentos!$K$2:$K$1000,$A43) -> 0 | C43: =COUNTIFS(Lançamentos!$K$2:$K$1000,$A43,Lançamentos!$R$2:$R$1000,"Concluído") -> 0 | D43: =SUMIFS(Lançamentos!$S$2:$S$1000,Lançamentos!$K$2:$K$1000,$A43) -> 0 | E43: =SUMIFS(Lançamentos!$V$2:$V$1000,Lançamentos!$K$2:$K$1000,$A43) -> 0
A44: Contabilidade | B44: =COUNTIF(Lançamentos!$K$2:$K$1000,$A44) -> 0 | C44: =COUNTIFS(Lançamentos!$K$2:$K$1000,$A44,Lançamentos!$R$2:$R$1000,"Concluído") -> 0 | D44: =SUMIFS(Lançamentos!$S$2:$S$1000,Lançamentos!$K$2:$K$1000,$A44) -> 0 | E44: =SUMIFS(Lançamentos!$V$2:$V$1000,Lançamentos!$K$2:$K$1000,$A44) -> 0
...

Sheet Cadastros
A1: CADASTROS MESTRES v3.4
A2: Fonte única das listas suspensas — alterar somente aqui e replicar nas planilhas dos analistas
A4: Projetos | B4: Departamentos | C4: Status | D4: Empresa | E4: Prioridade | F4: Complexidade | G4: Impacto | H4: Categoria de Benefício | I4: Sim/Não | J4: Pilar Proc. Integrados | K4: Departamentos CSC | L4: Papel na Atividade | M4: Equipe Proc. Integrados | N4: Status da Semana | O4: Motivo do Status | P4: Categoria de Impedimento | Q4: Avaliação (Desempenho) | R4: Avaliação (Prazo) | S4: Radar | U4: Projeto (mapa) | V4: Range Temas | X4: Pilar (mapa) | Y4: Range Tipos | AA4: Depto CSC (mapa) | AB4: Range Pessoas | AD4: Lumen | AE4: V360 | AF4: Saneamento Base Contábil | AG4: Newsletter | AH4: Rotina Fiscal/Contábil | AI4: Rotina Financeiro | AJ4: Investidas | AK4: Actio | AL4: Indicadores e Metas | AN4: Governança | AO4: Melhoria Contínua | AP4: Transformação Digital | AQ4: Business Intelligence | AR4: PMO / Projetos | AS4: Operação (Rotina) | AU4: Contas a Receber | AV4: Tesouraria | AW4: Auditoria Financeira CSC | AX4: Recebimento Fiscal | AY4: Processos Integrados | AZ4: Cartão Corporativo | BA4: Tributos Federais | BB4: Tributos Estaduais | BC4: Contabilidade | BD4: Faturamento | BE4: CSC Corporativo | BF4: Gestão
A5: Lumen | B5: Torre Financeira - CSC | C5: Não iniciado | D5: ELET | E5: Alta | F5: Alta | G5: Alto | H5: Tempo | I5: Sim | J5: Governança | K5: Contas a Receber | L5: Responsável | M5: José Victor | N5: 🟢 Concluído | O5: Em desenvolvimento | P5: Dependência de outra área | Q5: Excelente | R5: No prazo | S5: 🟢 Verde | U5: Lumen | V5: TemaLumen | X5: Governança | Y5: EntGov | AA5: Contas a Receber | AB5: Pes01 | AD5: PIS/COFINS | AE5: Dashboard de Produtividade | AF5: Adiantamento de Fornecedores | AG5: M01 - Normas Gerais da Tributação do Consumo | AH5: EFD ICMS/IPI | AI5: Pagamentos a Fornecedores | AJ5: Geral | AK5: Geral | AL5: Geral | AN5: POP elaborado/atualizado | AO5: Gargalo eliminado | AP5: Automação | AQ5: Dashboard | AR5: Projeto/Sprint gerenciado | AS5: Obrigação Acessória | AU5: Viviane Monteiro (Supervisora) | AV5: Erica Arcoverde (Supervisora) | AW5: Gabriela Cavalcanti (Supervisora) | AX5: Adriana Albuquerque (Supervisora) | AY5: Juliana Batista (Supervisora) | AZ5: Lucia Helena (Supervisora) | BA5: Emerson Pontes (Supervisor) | BB5: Yuri Medeiros (Técnico) | BC5: Magnum Brandão (Técnico) | BD5: Emerson Pontes (Técnico) | BE5: Jan Carlos | BF5: Rone Ferreira (Gerente)
A6: V360 | B6: Fiscal/Contábil | C6: Em andamento | D6: CHESF | E6: Média | F6: Média | G6: Médio | H6: Financeiro | I6: Não | J6: Melhoria Contínua | K6: Tesouraria | L6: Apoio | M6: Viviane Lima | N6: 🟡 Em andamento | O6: Aguardando usuário | P6: TI / Sistema | Q6: Boa | R6: Em risco | S6: 🟡 Atenção | U6: V360 | V6: TemaV360 | X6: Melhoria Contínua | Y6: EntMC | AA6: Tesouraria | AB6: Pes02 | AD6: ISS | AE6: Dashboard Entrada de NF - SAP x V360 | AF6: Adiantamento de Clientes | AG6: M02 - Comércio Internacional | AH6: EFD Contribuições | AI6: Pagamento de Tributos (DARF/GPS) | AJ6: Obrigações Acessórias | AK6: Cadastro de Indicadores | AL6: KPI/Indicador | AN6: Fluxograma (AS-IS/TO-BE) | AO6: Processo revisado/simplificado | AP6: Agente de IA | AQ6: KPI/Indicador publicado | AR6: Cronograma/Roadmap | AS6: Pagamento/Tesouraria | AU6: Adriana Martins | AV6: Aline Neves | AW6: Ana Lucia Ferreira | AX6: Altanira Carla | AY6: José Victor | AZ6: Izabella Paz | BA6: Danilo Oliveira | BB6: Lucas de Albuquerque | BC6: Deyvison de Lima | BD6: Ridley Renan | BE6: Manoel Cariele | BF6: Angela Ritchie (Coordenadora)
A7: Saneamento Base Contábil | B7: Financeiro | C7: Em validação | D7: ENOR | E7: Baixa | F7: Baixa | G7: Baixo | H7: Qualidade | J7: Transformação Digital | K7: Auditoria Financeira CSC | M7: Juliana Santos | N7: 🔴 Bloqueado | O7: Aguardando gestor | P7: Fornecedor | Q7: Regular | R7: Atrasado | S7: 🔴 Crítico | U7: Saneamento Base Contábil | V7: TemaSaneamento | X7: Transformação Digital | Y7: EntTD | AA7: Auditoria Financeira CSC | AB7: Pes03 | AD7: Diretos | AE7: Dashboard Entrada de NF - TicketLog x V360 | AF7: PIS e COFINS a Recuperar | AG7: M03 - FCBF - ICMS | AH7: ECD | AI7: Contas de Concessionárias | AJ7: Apurações | AK7: Planos de Ação | AL7: Meta | AN7: Política/Norma | AO7: Redução de etapas | AP7: Portal/Sistema Web | AQ7: Relatório Analítico | AR7: Workshop/Treinamento | AS7: Conciliação | AU7: Amanda Ferraz | AV7: Carlos Samuel | AW7: Rafaela Seabra | AX7: Ana Palheta | AY7: Viviane Lima | AZ7: Adriana Marinho | BA7: Emerson dos Santos | BB7: Amélia Gabriel | BC7: Rafael Lucio | BD7: Larisa Leal | BE7: Laura Santana | BF7: Phillippe de Sá (Coordenador)
A8: Newsletter | C8: Concluído | D8: ESUL | H8: Operação | J8: Business Intelligence | K8: Recebimento Fiscal | M8: Filipe Messias | N8: ⏸ Aguardando Terceiros | O8: Aguardando TI | P8: Licença / Acesso | Q8: Ruim | U8: Newsletter | V8: TemaNewsletter | X8: Business Intelligence | Y8: EntBI | AA8: Recebimento Fiscal | AB8: Pes04 | AD8: Retidos | AG8: M04 - Cadastro | AH8: ECF | AI8: Conciliações Financeiras | AJ8: Suporte Contábil/Fiscal | AK8: Acompanhamento de Metas | AL8: Dashboard | AN8: Indicador definido | AO8: Padronização implantada | AP8: Integração (SAP/API) | AQ8: Base de Dados estruturada | AR8: Gestão de Mudança | AS8: Análise/Parecer | AU8: Ana Carla | AV8: Denise Maria | AW8: Guilardo Souza | AX8: Alynna Pereira | AY8: Juliana Santos | AZ8: Cintia Bernardino | BA8: Maria Estela | BB8: Flavius de Oliveira | BC8: José Paulo Farias | BD8: Jonnathan dos Santos | BE8: Ademilson Jerônimo | BF8: Diogo Calado (Especialista Tributário)
A9: Rotina Fiscal/Contábil | C9: Aguardando terceiros | D9: Todas | H9: Compliance | J9: PMO / Projetos | K9: Processos Integrados | M9: Juliana Batista (Supervisora) | N9: ⚪ Não iniciado | O9: Aguardando fornecedor | P9: Aprovação | U9: Rotina Fiscal/Contábil | V9: TemaRotinaFC | X9: PMO / Projetos | Y9: EntPMO | AA9: Processos Integrados | AB9: Pes05 | AD9: ICMS | AG9: M05 - Obrigações Acessórias | AH9: DCTFWeb | AI9: Melhorias e Automações | AJ9: Análises | AK9: Relatórios | AL9: Relatório Gerencial | AN9: Documentação/Manual | AO9: Kaizen/Lean | AP9: OCR/Processamento de Documentos | AS9: Apuração de Tributos | AU9: Ana Manuela | AV9: Diego Maciel | AW9: Ana Cartaxo | AX9: Cassyo Cleyson | AY9: Filipe Messias | AZ9: Lea Carolina | BA9: Roberto Cavalcante | BB9: Diogo Santos | BC9: Roberta Neves | BD9: Thiago da Silva
A10: Rotina Financeiro | C10: Cancelado | D10: Outra | H10: Tecnologia | J10: Operação (Rotina) | K10: Cartão Corporativo | O10: Aguardando outra área | P10: Cliente / Usuário | U10: Rotina Financeiro | V10: TemaRotinaFin | X10: Operação (Rotina) | Y10: EntOper | AA10: Cartão Corporativo | AB10: Pes06 | AD10: Obrig. Estaduais - DAMEF-MG / DAPI-MG / DECLAN-RJ | AG10: M06 - Apuração Assistida | AH10: DIRBI | AI10: Relatórios e KPIs | AJ10: Outros | AK10: Outros | AL10: Outros | AN10: Publicação/Conteúdo Técnico | AP10: Script/Macro | AS10: Suporte/Atendimento | AU10: Dâmaris de Santana | AV10: Elaine Santana | AW10: Maria Aparecida | AX10: Emanuelle Monteiro | AZ10: Beatriz Rosseti | BA10: Roseli Marinho | BB10: Amanda C. da Silva | BC10: Vinicius Pinheiro | BD10: Bruno Santos
A11: Investidas | D11: N/A | H11: Pessoas | K11: Tributos Federais | O11: Em homologação | P11: Outro | U11: Investidas | V11: TemaInvestidas | AA11: Tributos Federais | AB11: Pes07 | AD11: Obrig. Estaduais - DCIP-SC / DIME-SC / DIF-TO / DOT-ES | AG11: M07 - Compensação, Ressarcimento e Restituição | AH11: EFD-Reinf | AI11: Outros | AS11: Correção/Retificação | AU11: Eneias Matias | AV11: John Williams | AW11: Ranata Calumbi | AX11: Erick Melo | AZ11: Augusto Ildefonso | BA11: Luisa Arruda | BB11: Rodrigo de Albuquerque | BC11: Sergio Melo Filho | BD11: Arthur Tavares
A12: Actio | K12: Tributos Estaduais | O12: Em validação | U12: Actio | V12: TemaActio | AA12: Tributos Estaduais | AB12: Pes08 | AD12: Obrig. Estaduais - GIA-ST / DIFAL / ICMS Simples Nacional | AG12: M08 - Simples Nacional e MEI | AH12: eSocial | AU12: Ludimille Amaral | AV12: Elma de Andrade | AX12: Fernanda Ximenes | AZ12: Sintia Oliveira | BA12: Giselly Alves | BB12: Kellner Leal | BC12: Angela Maria Silva | BD12: João Fortunato
A13: Indicadores e Metas | K13: Contabilidade | O13: Ajustes identificados | U13: Indicadores e Metas | V13: TemaIndMetas | AA13: Contabilidade | AB13: Pes09 | AD13: GNRE / CIAP | AG13: M09 - Economia Digital | AH13: Apurações | AU13: Juliana Albuquerque | AV13: Willams Martins | AX13: Geovanni Paiva | BA13: João Brito | BB13: Isaac Kesseler | BC13: Romullo Nascimento
K14: Faturamento | O14: Concluído | AA14: Faturamento | AB14: Pes10 | AD14: Notas Fiscais (Entradas/Saídas, Correções, Inconformidades) | AG14: M10 - Regimes Diferenciados e Específicos | AH14: Conciliações Contábeis | AU14: Priscilla Negrão | AV14: Paloma Mendes | AX14: Pholyana Katy | BA14: Janice de Lima | BB14: Aline Tavares | BC14: Mylena Silva
K15: CSC Corporativo | AA15: CSC Corporativo | AB15: Pes11 | AD15: CDC / CFC / MCX | AG15: M11 - Planos de Saúde e Prognósticos | AH15: Outros | AU15: Lana Barros | AV15: Natália Rocha | AX15: Terezinha Santos | BA15: Janaina Nascimento | BB15: Rafael Cunha | BC15: Luiz Claudio da Silva
K16: Gestão | AA16: Gestão | AB16: Pes12 | AD16: Calendário e Dashboards Fiscais / PGTC | AG16: M12 - Serviços Financeiros | AV16: Nadja Buarque | AX16: Mylene Lira | BA16: Gleicy Gomes | BC16: Lucas Bernardo
AD17: ECD - SPED Contábil / Balancete, Razão e Diário | AG17: M13 - Bens Imóveis | AV17: Silvia Helena | AX17: Fernando Calado | BA17: Daiane Vicente
AD18: Sintegra / 3P2M | AG18: M14 - Agronegócio e Cooperativismo | AV18: Fernando Bruno | AX18: Maria Helena | BA18: Luana de Oliveira
AG19: M15 - ZFM e ALC | AX19: Roger Melo
AG20: M16 - Combustíveis e Energia Elétrica | AX20: Thaynara Ávila
AG21: M17 - Imposto Seletivo | AX21: Josuellington Costa
AG22: M18 - Temas Complementares e Casos Práticos | AX22: Ítalo Henrique
AX23: Tiago Pereira
AX24: Wialy Marlan
AX25: Maria Eduarda
A40: REGRA DE ID ÚNICO — PREFIXOS POR ANALISTA
A41: Analista | B41: Prefixo
A42: José Victor | B42: JV
A43: Viviane Lima | B43: VL
A44: Juliana Santos | B44: JS
A45: Filipe Messias | B45: FM
A46: Juliana Batista (Supervisora) | B46: JB
A47: Cada analista usa exclusivamente o seu prefixo. O ID é gerado automaticamente (PREFIXO-0001, PREFIXO-0002...), portanto nunca haverá repetição entre as planilhas da equipe.
